Workbook

Sheet Summary
A2: NEXT WP008 sourcing scenarios
A4: Scenario: | B4: =Assumptions!C5 -> Balanced | D4: Price period: | E4: =Assumptions!C6 -> H1 2026 | G4: Data basis: | H4: =Assumptions!C7 -> Reported
A6: Illustrative shifts from China using FY2025 trade-mass weights. Candidate origin, capability and sourcing clearance remain pending. No allocation is released.
A8: Product | B8: China baseline | C8: Requested shift | D8: Feasible limit | E8: Applied shift | F8: Cost index | G8: Cost change | H8: HHI change (pts) | I8: Release
A9: Cotton T-shirts | B9: =Cost_Model!D8 -> 0.032221227 | C9: =Assumptions!C12 -> 0.1 | D9: =Cost_Model!D51 -> 0.032221227 | E9: =Cost_Model!E51 -> 0.032221227 | F9: =100*Cost_Model!F51/Cost_Model!B51 -> 99.915376 | G9: =F9/100-1 -> -0.00084624275 | H9: =(Cost_Model!J51-Cost_Model!G51)*10000 -> 39.567478 | I9: =Cost_Model!O51 -> Hold
A10: MMF knitwear | B10: =Cost_Model!D18 -> 0.36613275 | C10: =Assumptions!C12 -> 0.1 | D10: =Cost_Model!D52 -> 0.014153298 | E10: =Cost_Model!E52 -> 0.014153298 | F10: =100*Cost_Model!F52/Cost_Model!B52 -> 99.5373 | G10: =F10/100-1 -> -0.0046270035 | H10: =(Cost_Model!J52-Cost_Model!G52)*10000 -> -88.19323 | I10: =Cost_Model!O52 -> Hold
A11: Synthetic dresses | B11: =Cost_Model!D28 -> 0.47952185 | C11: =Assumptions!C12 -> 0.1 | D11: =Cost_Model!D53 -> 0.2 | E11: =Cost_Model!E53 -> 0.1 | F11: =100*Cost_Model!F53/Cost_Model!B53 -> 99.509124 | G11: =F11/100-1 -> -0.0049087561 | H11: =(Cost_Model!J53-Cost_Model!G53)*10000 -> -635.80165 | I11: =Cost_Model!O53 -> Hold
A12: Cotton shirts | B12: =Cost_Model!D38 -> 0.069159901 | C12: =Assumptions!C12 -> 0.1 | D12: =Cost_Model!D54 -> 0.069159901 | E12: =Cost_Model!E54 -> 0.069159901 | F12: =100*Cost_Model!F54/Cost_Model!B54 -> 101.34489 | G12: =F12/100-1 -> 0.013448904 | H12: =(Cost_Model!J54-Cost_Model!G54)*10000 -> 117.77114 | I12: =Cost_Model!O54 -> Hold
A14: Index 100 = unchanged country mix under the same prices and tariff treatment. Negative HHI change means lower concentration within the product’s ten-country benchmark.
A15: =IF(AND(H10<0,H11<0,H9>0,H12>0),"The synthetic pair de-concentrates; both cotton codes concentrate further. Bangladesh remains dominant in the cotton baseline. These results support a category-specific investigation, not a blanket reduction in China.","Concentration effects differ by category and receiver mix. Read each HHI change separately; reducing China alone does not guarantee diversification.") -> The synthetic pair de-concentrates; both cotton codes concentrate further. Bangladesh remains dominant in the cotton baseline. These results support a category-specific investigation, not a blanket reduction in China.
A16: Scenario | B16: Requested shift | C16: Eligible index | D16: MFN index | E16: Active index | F16: Cost change | G16: Smallest shift | H16: Largest shift | I16: Release
A17: Cautious | B17: =Assumptions!B17 -> 0.05 | C17: =100*(1+SUMPRODUCT(Assumptions!$C$38:$C$41,Cost_Model!F60:F63)) -> 100.04489 | D17: =100*(1+SUMPRODUCT(Assumptions!$C$38:$C$41,Cost_Model!G60:G63)) -> 100.54108 | E17: =IF(Assumptions!C9="Eligible preference",C17,D17) -> 100.04489 | F17: =E17/100-1 -> 0.00044885644 | G17: =MIN(Cost_Model!E60:E63) -> 0.014153298 | H17: =MAX(Cost_Model!E60:E63) -> 0.05 | I17: =IF(COUNTIF(Cost_Model!N60:N63,"Hold")=0,"Evidence recorded","Hold") -> Hold
A18: Balanced | B18: =Assumptions!B18 -> 0.1 | C18: =100*(1+SUMPRODUCT(Assumptions!$C$38:$C$41,Cost_Model!F64:F67)) -> 100.07667 | D18: =100*(1+SUMPRODUCT(Assumptions!$C$38:$C$41,Cost_Model!G64:G67)) -> 100.78714 | E18: =IF(Assumptions!C9="Eligible preference",C18,D18) -> 100.07667 | F18: =E18/100-1 -> 0.0007667253 | G18: =MIN(Cost_Model!E64:E67) -> 0.014153298 | H18: =MAX(Cost_Model!E64:E67) -> 0.1 | I18: =IF(COUNTIF(Cost_Model!N64:N67,"Hold")=0,"Evidence recorded","Hold") -> Hold
A19: Accelerated | B19: =Assumptions!B19 -> 0.15 | C19: =100*(1+SUMPRODUCT(Assumptions!$C$38:$C$41,Cost_Model!F68:F71)) -> 100.01531 | D19: =100*(1+SUMPRODUCT(Assumptions!$C$38:$C$41,Cost_Model!G68:G71)) -> 100.87774 | E19: =IF(Assumptions!C9="Eligible preference",C19,D19) -> 100.01531 | F19: =E19/100-1 -> 0.00015313079 | G19: =MIN(Cost_Model!E68:E71) -> 0.014153298 | H19: =MAX(Cost_Model!E68:E71) -> 0.15 | I19: =IF(COUNTIF(Cost_Model!N68:N71,"Hold")=0,"Evidence recorded","Hold") -> Hold
A21: Basket comparison uses equal category spend weights. Preferences and fallback each have their own unchanged-mix baseline of 100. Compare cost changes, not absolute duty costs, across these indices.
A40: The three scenarios test scale, not three different strategies. India receives 50% of each shift; Turkey and Vietnam receive 25% each. Change the receiver weights in Assumptions to test another mix.
A41: Myanmar receives no additional share. Its observed benchmark share is retained; this makes no claim about NEXT’s existing sourcing. All candidate evidence checks remain open.
A42: Reported observations are the baseline. Common-month sensitivity removes a product-month for every partner if any partner/World observation is REVIEW or unusable. It holds FY2025 allocation weights fixed.
A43: The model excludes unobserved lead-time, working-capital and transition costs. WP009 should test whether premiums and tariff fallback overturn the benchmark result before a recommendation is made.
A44: WP004: 85.61% of China’s four-code value is in the synthetic pair. China’s tariff rate is 12% on all four codes. H5 remains partly tested because comparable capability and achievable supplier economics are unverified.
A46: Product | B46: India baseline | C46: India after | D46: India multiple | E46: Vietnam baseline | F46: Vietnam after | G46: Vietnam multiple | H46: Turkey multiple | I46: Max receiver multiple
A47: =A9 -> Cotton T-shirts | B47: =Cost_Model!D9 -> 0.10252755 | C47: =Cost_Model!R9 -> 0.11863816 | D47: =Cost_Model!AE9 -> 1.1571345 | E47: =Cost_Model!D15 -> 0.015508884 | F47: =Cost_Model!R15 -> 0.023564191 | G47: =Cost_Model!AE15 -> 1.5193995 | H47: =Cost_Model!AE14 -> 1.123337 | I47: =MAX(Cost_Model!AF6:AF15) -> 1.5193995
A48: =A10 -> MMF knitwear | B48: =Cost_Model!D19 -> 0.0035383246 | C48: =Cost_Model!R19 -> 0.010614974 | D48: =Cost_Model!AE19 -> 3 | E48: =Cost_Model!D25 -> 0.0088231666 | F48: =Cost_Model!R25 -> 0.012361491 | G48: =Cost_Model!AE25 -> 1.4010266 | H48: =Cost_Model!AE24 -> 1.0216474 | I48: =MAX(Cost_Model!AF16:AF25) -> 3
A49: =A11 -> Synthetic dresses | B49: =Cost_Model!D29 -> 0.15126886 | C49: =Cost_Model!R29 -> 0.20126886 | D49: =Cost_Model!AE29 -> 1.3305373 | E49: =Cost_Model!D35 -> 0.034917395 | F49: =Cost_Model!R35 -> 0.059917395 | G49: =Cost_Model!AE35 -> 1.7159755 | H49: =Cost_Model!AE34 -> 1.7346679 | I49: =MAX(Cost_Model!AF26:AF35) -> 1.7346679
A50: =A12 -> Cotton shirts | B50: =Cost_Model!D39 -> 0.16719111 | C50: =Cost_Model!R39 -> 0.20177106 | D50: =Cost_Model!AE39 -> 1.2068289 | E50: =Cost_Model!D45 -> 0.05205513 | F50: =Cost_Model!R45 -> 0.069345105 | G50: =Cost_Model!AE45 -> 1.3321474 | H50: =Cost_Model!AE44 -> 1.425978 | I50: =MAX(Cost_Model!AF36:AF45) -> 1.425978
A52: Multiples show scenario share divided by FY2025 baseline share. With fixed product volume they also describe the implied volume multiple. They do not measure a supplier’s production capacity.
A53: =IF(Assumptions!F14="Yes","The baseline-share multiple cap is enabled. MMF knitwear can hit this limit before the requested shift is reached. Compare the share-only case and code-specific receiver mixes in WP009.","The baseline-share multiple cap is disabled. Large implied receiver expansions remain visible above and require separate feasibility testing.") -> The baseline-share multiple cap is enabled. MMF knitwear can hit this limit before the requested shift is reached. Compare the share-only case and code-specific receiver mixes in WP009.

Sheet Assumptions
A2: WP008 model assumptions
B5: Scenario | C5: Balanced
B6: Price period | C6: H1 2026
B7: Data basis | C7: Reported
B8: Tariff window | C8: From 15 Jul 2026
B9: Tariff treatment | C9: Eligible preference
B10: Recipient country share ceiling | C10: 0.35
B11: Maximum addition per recipient | C11: 0.1
B12: Active requested shift | C12: =IF(COUNTIFS(A17:A19,C5,B17:B19,"<>")=1,SUMIF(A17:A19,C5,B17:B19),"n.a.") -> 0.1
B13: Input status | C13: =IF(AND(OR(F14="Yes",F14="No"),IF(F14="Yes",AND(ISNUMBER(C14),C14>=1),TRUE),COUNT(C10:C11)=2,C10>0,C10<=1,C11>=0,C11<=1,ISNUMBER(C12),C12>=0,C12<=1,COUNT(B24:B33)=10,MIN(B24:B33)>=0,ABS(SUM(B24:B33)-1)<0.000000001,B26=0,B29=0,COUNT(C24:C33)=10,MIN(C24:C33)>=0,COUNT(C38:C41)=4,MIN(C38:C41)>=0,ABS(SUM(C38:C41)-1)<0.000000001),"Valid","Invalid inputs") -> Valid
B14: Maximum baseline-share multiple | C14: 3 | E14: Apply multiple cap | F14: Yes
A16: Scenario | B16: Requested shift
A17: Cautious | B17: 0.05
A18: Balanced | B18: 0.1
A19: Accelerated | B19: 0.15
A23: Country | B23: Receiver weight | C23: Incremental premium | D23: Basis
A24: Bangladesh | B24: 0 | C24: 0 | D24: Scenario assumption
A25: Cambodia | B25: 0 | C25: 0 | D25: Scenario assumption
A26: China | B26: 0 | C26: 0 | D26: Scenario assumption
A27: India | B27: 0.5 | C27: 0 | D27: Scenario assumption
A28: Morocco | B28: 0 | C28: 0 | D28: Scenario assumption
A29: Myanmar | B29: 0 | C29: 0 | D29: Scenario assumption
A30: Pakistan | B30: 0 | C30: 0 | D30: Scenario assumption
A31: Sri Lanka | B31: 0 | C31: 0 | D31: Scenario assumption
A32: Turkey | B32: 0.25 | C32: 0 | D32: Scenario assumption
A33: Vietnam | B33: 0.25 | C33: 0 | D33: Scenario assumption
A37: CN8 | B37: Product | C37: Basket spend weight | E37: FY2025 UK import value (£) | F37: Value weight
A38: 61091000 | B38: Cotton T-shirts | C38: 0.25 | E38: 1223299784 | F38: =E38/SUM($E$38:$E$41) -> 0.47878752
A39: 61103099 | B39: MMF knitwear | C39: 0.25 | E39: 719371758 | F39: =E39/SUM($E$38:$E$41) -> 0.28155504
A40: 62044300 | B40: Synthetic dresses | C40: 0.25 | E40: 349077816 | F40: =E40/SUM($E$38:$E$41) -> 0.13662563
A41: 62052000 | B41: Cotton shirts | C41: 0.25 | E41: 263245768 | F41: =E41/SUM($E$38:$E$41) -> 0.10303181
A43: Amber cells are editable assumptions. Receiver weights allocate each feasible shift: India 50%, Turkey 25%, Vietnam 25%. This is a test portfolio, not an optimised allocation or a capacity assessment.
A44: China is the donor. FY2025 ten-country import-mass shares remain the fixed baseline. Myanmar retains its baseline benchmark share and receives no increment. Country ceilings constrain additions only.
A45: Receiver headroom is the minimum of the 35% share ceiling, 10pp addition limit and, when enabled, (maximum multiple − 1) × baseline share. The default 3× cap is a modelling safeguard, not verified capacity. Zero-baseline receivers cannot grow while it is enabled.
A46: Equal 25% category spend weights create a synthetic cost index. They do not represent NEXT spend. Incremental premiums apply only to transferred volume; zero means the scenario excludes a premium.
A47: The tariff window is independent of the trade period: changing it holds observed prices constant for a policy comparison. It does not estimate duty actually paid during that trade period.
A48: Illustrative requested shifts are 5/10/15pp (Q5.2). Receiver mix, ceilings, zero premiums and equal category weights are explicit model assumptions. See docs/Research_Question_and_Scope.md.
A49: Set Apply multiple cap to No to reproduce the original share-only constraints. The receiver mix remains common across codes; WP009 will test code-specific mixes and alternative growth limits.
A50: Value-weight reference: WP004 Commodity_Shortlist!G2:G5 and WP006 world_trade_period_reported, FULL_YEAR 2025. These weights are queued for WP009; active basket weights remain in C38:C41. They describe the UK four-code market, not NEXT spend.

Sheet Cost_Model
A2: Cost and allocation model
A4: Scenario: | B4: =Assumptions!C5 -> Balanced | D4: Price period: | E4: =Assumptions!C6 -> H1 2026 | H4: =Assumptions!C7 -> Reported | K4: =Assumptions!C9 -> Eligible preference
A5: CN8 | B5: Country | C5: FY25 mass (kg) | D5: Baseline share | E5: Price value (£) | F5: Price mass (kg) | G5: UV (£/kg) | H5: Eligible tariff | I5: MFN tariff | J5: Eligible £/kg | K5: MFN £/kg | L5: Active £/kg | M5: Receiver weight | N5: Premium | O5: Shift direction | P5: Shift limit | Q5: Active change | R5: Scenario share | S5: Baseline cost | T5: Scenario cost | U5: Unit-shift cost | V5: Baseline HHI | W5: HHI linear term | X5: HHI square term | Y5: Evidence-ready increment | Z5: Eligible baseline | AA5: Eligible direction | AB5: MFN baseline | AC5: MFN direction | AD5: Input coverage | AE5: Share multiple | AF5: Receiver multiple | AG5: Multiple-cap excess
A6: 61091000 | B6: Bangladesh | C6: =SUMIFS(Trade_Periods!$F$6:$F$125,Trade_Periods!$B$6:$B$125,"FY2025",Trade_Periods!$C$6:$C$125,B6,Trade_Periods!$D$6:$D$125,A6) -> 44227971 | D6: =C6/SUM(C6:C15) -> 0.58622087 | E6: =IF(Assumptions!$C$7="Reported",SUMIFS(Trade_Periods!$E$6:$E$125,Trade_Periods!$B$6:$B$125,Assumptions!$C$6,Trade_Periods!$C$6:$C$125,B6,Trade_Periods!$D$6:$D$125,A6),SUMIFS(Trade_Periods!$L$6:$L$125,Trade_Periods!$B$6:$B$125,Assumptions!$C$6,Trade_Periods!$C$6:$C$125,B6,Trade_Periods!$D$6:$D$125,A6)) -> 254631302 | F6: =IF(Assumptions!$C$7="Reported",SUMIFS(Trade_Periods!$F$6:$F$125,Trade_Periods!$B$6:$B$125,Assumptions!$C$6,Trade_Periods!$C$6:$C$125,B6,Trade_Periods!$D$6:$D$125,A6),SUMIFS(Trade_Periods!$M$6:$M$125,Trade_Periods!$B$6:$B$125,Assumptions!$C$6,Trade_Periods!$C$6:$C$125,B6,Trade_Periods!$D$6:$D$125,A6)) -> 24484056 | G6: =IF(F6>0,E6/F6,"n.a.") -> 10.399882 | H6: =IF(Assumptions!$C$8="2025",SUMIFS(Tariffs!$D$6:$D$45,Tariffs!$B$6:$B$45,B6,Tariffs!$C$6:$C$45,A6),IF(Assumptions!$C$8="1 Jan to 14 Jul 2026",SUMIFS(Tariffs!$E$6:$E$45,Tariffs!$B$6:$B$45,B6,Tariffs!$C$6:$C$45,A6),SUMIFS(Tariffs!$F$6:$F$45,Tariffs!$B$6:$B$45,B6,Tariffs!$C$6:$C$45,A6))) -> 0 | I6: =SUMIFS(Tariffs!$G$6:$G$45,Tariffs!$B$6:$B$45,B6,Tariffs!$C$6:$C$45,A6) -> 0.12 | J6: =G6*(1+H6) -> 10.399882 | K6: =G6*(1+I6) -> 11.647868 | L6: =IF(Assumptions!$C$9="Eligible preference",J6,K6) -> 10.399882 | M6: =Assumptions!B24 -> 0 | N6: =Assumptions!C24 -> 0 | O6: =IF(B6="China",-1,M6) -> 0 | P6: =IF(B6="China",D6,IF(M6>0,MAX(0,MIN(Assumptions!$C$10-D6,Assumptions!$C$11,IF(Assumptions!$F$14="Yes",(Assumptions!$C$14-1)*D6,1))/M6),1)) -> 1 | Q6: =$E51*O6 -> 0 | R6: =D6+Q6 -> 0.58622087 | S6: =D6*L6 -> 6.0966281 | T6: =R6*L6+MAX(0,Q6)*L6*N6 -> 6.0966281 | U6: =O6*L6+M6*L6*N6 -> 0 | V6: =D6^2 -> 0.34365491 | W6: =2*D6*O6 -> 0 | X6: =O6^2 -> 0 | Y6: =IF(Candidate_Gates!N6="Pass",MAX(0,Q6),0) -> 0 | Z6: =D6*J6 -> 6.0966281 | AA6: =O6*J6+M6*J6*N6 -> 0 | AB6: =D6*K6 -> 6.8282234 | AC6: =O6*K6+M6*K6*N6 -> 0 | AD6: =IF(AND(C6>=0,F6>0,E6>0,ISNUMBER(G6),COUNTIFS(Trade_Periods!$B$6:$B$125,Assumptions!$C$6,Trade_Periods!$C$6:$C$125,B6,Trade_Periods!$D$6:$D$125,A6)=1,COUNTIFS(Tariffs!$B$6:$B$45,B6,Tariffs!$C$6:$C$45,A6)=1),"Ready","Missing data") -> Ready | AE6: =IF(D6>0,R6/D6,"n.a.") -> 1 | AF6: =IF(M6>0,IF(D6>0,R6/D6,IF(R6=0,0,"n.a.")),0) -> 0 | AG6: =IF(AND(Assumptions!$F$14="Yes",M6>0),MAX(0,R6-Assumptions!$C$14*D6),0) -> 0
A7: 61091000 | B7: Cambodia | C7: =SUMIFS(Trade_Periods!$F$6:$F$125,Trade_Periods!$B$6:$B$125,"FY2025",Trade_Periods!$C$6:$C$125,B7,Trade_Periods!$D$6:$D$125,A7) -> 547756 | D7: =C7/SUM(C6:C15) -> 0.0072602471 | E7: =IF(Assumptions!$C$7="Reported",SUMIFS(Trade_Periods!$E$6:$E$125,Trade_Periods!$B$6:$B$125,Assumptions!$C$6,Trade_Periods!$C$6:$C$125,B7,Trade_Periods!$D$6:$D$125,A7),SUMIFS(Trade_Periods!$L$6:$L$125,Trade_Periods!$B$6:$B$125,Assumptions!$C$6,Trade_Periods!$C$6:$C$125,B7,Trade_Periods!$D$6:$D$125,A7)) -> 5968533 | F7: =IF(Assumptions!$C$7="Reported",SUMIFS(Trade_Periods!$F$6:$F$125,Trade_Periods!$B$6:$B$125,Assumptions!$C$6,Trade_Periods!$C$6:$C$125,B7,Trade_Periods!$D$6:$D$125,A7),SUMIFS(Trade_Periods!$M$6:$M$125,Trade_Periods!$B$6:$B$125,Assumptions!$C$6,Trade_Periods!$C$6:$C$125,B7,Trade_Periods!$D$6:$D$125,A7)) -> 334694 | G7: =IF(F7>0,E7/F7,"n.a.") -> 17.832805 | H7: =IF(Assumptions!$C$8="2025",SUMIFS(Tariffs!$D$6:$D$45,Tariffs!$B$6:$B$45,B7,Tariffs!$C$6:$C$45,A7),IF(Assumptions!$C$8="1 Jan to 14 Jul 2026",SUMIFS(Tariffs!$E$6:$E$45,Tariffs!$B$6:$B$45,B7,Tariffs!$C$6:$C$45,A7),SUMIFS(Tariffs!$F$6:$F$45,Tariffs!$B$6:$B$45,B7,Tariffs!$C$6:$C$45,A7))) -> 0 | I7: =SUMIFS(Tariffs!$G$6:$G$45,Tariffs!$B$6:$B$45,B7,Tariffs!$C$6:$C$45,A7) -> 0.12 | J7: =G7*(1+H7) -> 17.832805 | K7: =G7*(1+I7) -> 19.972742 | L7: =IF(Assumptions!$C$9="Eligible preference",J7,K7) -> 17.832805 | M7: =Assumptions!B25 -> 0 | N7: =Assumptions!C25 -> 0 | O7: =IF(B7="China",-1,M7) -> 0 | P7: =IF(B7="China",D7,IF(M7>0,MAX(0,MIN(Assumptions!$C$10-D7,Assumptions!$C$11,IF(Assumptions!$F$14="Yes",(Assumptions!$C$14-1)*D7,1))/M7),1)) -> 1 | Q7: =$E51*O7 -> 0 | R7: =D7+Q7 -> 0.0072602471 | S7: =D7*L7 -> 0.12947057 | T7: =R7*L7+MAX(0,Q7)*L7*N7 -> 0.12947057 | U7: =O7*L7+M7*L7*N7 -> 0 | V7: =D7^2 -> 5.2711188e-05 | W7: =2*D7*O7 -> 0 | X7: =O7^2 -> 0 | Y7: =IF(Candidate_Gates!N7="Pass",MAX(0,Q7),0) -> 0 | Z7: =D7*J7 -> 0.12947057 | AA7: =O7*J7+M7*J7*N7 -> 0 | AB7: =D7*K7 -> 0.14500704 | AC7: =O7*K7+M7*K7*N7 -> 0 | AD7: =IF(AND(C7>=0,F7>0,E7>0,ISNUMBER(G7),COUNTIFS(Trade_Periods!$B$6:$B$125,Assumptions!$C$6,Trade_Periods!$C$6:$C$125,B7,Trade_Periods!$D$6:$D$125,A7)=1,COUNTIFS(Tariffs!$B$6:$B$45,B7,Tariffs!$C$6:$C$45,A7)=1),"Ready","Missing data") -> Ready | AE7: =IF(D7>0,R7/D7,"n.a.") -> 1 | AF7: =IF(M7>0,IF(D7>0,R7/D7,IF(R7=0,0,"n.a.")),0) -> 0 | AG7: =IF(AND(Assumptions!$F$14="Yes",M7>0),MAX(0,R7-Assumptions!$C$14*D7),0) -> 0
A8: 61091000 | B8: China | C8: =SUMIFS(Trade_Periods!$F$6:$F$125,Trade_Periods!$B$6:$B$125,"FY2025",Trade_Periods!$C$6:$C$125,B8,Trade_Periods!$D$6:$D$125,A8) -> 2430960 | D8: =C8/SUM(C6:C15) -> 0.032221227 | E8: =IF(Assumptions!$C$7="Reported",SUMIFS(Trade_Periods!$E$6:$E$125,Trade_Periods!$B$6:$B$125,Assumptions!$C$6,Trade_Periods!$C$6:$C$125,B8,Trade_Periods!$D$6:$D$125,A8),SUMIFS(Trade_Periods!$L$6:$L$125,Trade_Periods!$B$6:$B$125,Assumptions!$C$6,Trade_Periods!$C$6:$C$125,B8,Trade_Periods!$D$6:$D$125,A8)) -> 27268063 | F8: =IF(Assumptions!$C$7="Reported",SUMIFS(Trade_Periods!$F$6:$F$125,Trade_Periods!$B$6:$B$125,Assumptions!$C$6,Trade_Periods!$C$6:$C$125,B8,Trade_Periods!$D$6:$D$125,A8),SUMIFS(Trade_Periods!$M$6:$M$125,Trade_Periods!$B$6:$B$125,Assumptions!$C$6,Trade_Periods!$C$6:$C$125,B8,Trade_Periods!$D$6:$D$125,A8)) -> 1611661 | G8: =IF(F8>0,E8/F8,"n.a.") -> 16.91923 | H8: =IF(Assumptions!$C$8="2025",SUMIFS(Tariffs!$D$6:$D$45,Tariffs!$B$6:$B$45,B8,Tariffs!$C$6:$C$45,A8),IF(Assumptions!$C$8="1 Jan to 14 Jul 2026",SUMIFS(Tariffs!$E$6:$E$45,Tariffs!$B$6:$B$45,B8,Tariffs!$C$6:$C$45,A8),SUMIFS(Tariffs!$F$6:$F$45,Tariffs!$B$6:$B$45,B8,Tariffs!$C$6:$C$45,A8))) -> 0.12 | I8: =SUMIFS(Tariffs!$G$6:$G$45,Tariffs!$B$6:$B$45,B8,Tariffs!$C$6:$C$45,A8) -> 0.12 | J8: =G8*(1+H8) -> 18.949538 | K8: =G8*(1+I8) -> 18.949538 | L8: =IF(Assumptions!$C$9="Eligible preference",J8,K8) -> 18.949538 | M8: =Assumptions!B26 -> 0 | N8: =Assumptions!C26 -> 0 | O8: =IF(B8="China",-1,M8) -> -1 | P8: =IF(B8="China",D8,IF(M8>0,MAX(0,MIN(Assumptions!$C$10-D8,Assumptions!$C$11,IF(Assumptions!$F$14="Yes",(Assumptions!$C$14-1)*D8,1))/M8),1)) -> 0.032221227 | Q8: =$E51*O8 -> -0.032221227 | R8: =D8+Q8 -> 0 | S8: =D8*L8 -> 0.61057734 | T8: =R8*L8+MAX(0,Q8)*L8*N8 -> 0 | U8: =O8*L8+M8*L8*N8 -> -18.949538 | V8: =D8^2 -> 0.0010382075 | W8: =2*D8*O8 -> -0.064442454 | X8: =O8^2 -> 1 | Y8: =IF(Candidate_Gates!N8="Pass",MAX(0,Q8),0) -> 0 | Z8: =D8*J8 -> 0.61057734 | AA8: =O8*J8+M8*J8*N8 -> -18.949538 | AB8: =D8*K8 -> 0.61057734 | AC8: =O8*K8+M8*K8*N8 -> -18.949538 | AD8: =IF(AND(C8>=0,F8>0,E8>0,ISNUMBER(G8),COUNTIFS(Trade_Periods!$B$6:$B$125,Assumptions!$C$6,Trade_Periods!$C$6:$C$125,B8,Trade_Periods!$D$6:$D$125,A8)=1,COUNTIFS(Tariffs!$B$6:$B$45,B8,Tariffs!$C$6:$C$45,A8)=1),"Ready","Missing data") -> Ready | AE8: =IF(D8>0,R8/D8,"n.a.") -> 0 | AF8: =IF(M8>0,IF(D8>0,R8/D8,IF(R8=0,0,"n.a.")),0) -> 0 | AG8: =IF(AND(Assumptions!$F$14="Yes",M8>0),MAX(0,R8-Assumptions!$C$14*D8),0) -> 0
A9: 61091000 | B9: India | C9: =SUMIFS(Trade_Periods!$F$6:$F$125,Trade_Periods!$B$6:$B$125,"FY2025",Trade_Periods!$C$6:$C$125,B9,Trade_Periods!$D$6:$D$125,A9) -> 7735285 | D9: =C9/SUM(C6:C15) -> 0.10252755 | E9: =IF(Assumptions!$C$7="Reported",SUMIFS(Trade_Periods!$E$6:$E$125,Trade_Periods!$B$6:$B$125,Assumptions!$C$6,Trade_Periods!$C$6:$C$125,B9,Trade_Periods!$D$6:$D$125,A9),SUMIFS(Trade_Periods!$L$6:$L$125,Trade_Periods!$B$6:$B$125,Assumptions!$C$6,Trade_Periods!$C$6:$C$125,B9,Trade_Periods!$D$6:$D$125,A9)) -> 54416583 | F9: =IF(Assumptions!$C$7="Reported",SUMIFS(Trade_Periods!$F$6:$F$125,Trade_Periods!$B$6:$B$125,Assumptions!$C$6,Trade_Periods!$C$6:$C$125,B9,Trade_Periods!$D$6:$D$125,A9),SUMIFS(Trade_Periods!$M$6:$M$125,Trade_Periods!$B$6:$B$125,Assumptions!$C$6,Trade_Periods!$C$6:$C$125,B9,Trade_Periods!$D$6:$D$125,A9)) -> 4347817 | G9: =IF(F9>0,E9/F9,"n.a.") -> 12.51584 | H9: =IF(Assumptions!$C$8="2025",SUMIFS(Tariffs!$D$6:$D$45,Tariffs!$B$6:$B$45,B9,Tariffs!$C$6:$C$45,A9),IF(Assumptions!$C$8="1 Jan to 14 Jul 2026",SUMIFS(Tariffs!$E$6:$E$45,Tariffs!$B$6:$B$45,B9,Tariffs!$C$6:$C$45,A9),SUMIFS(Tariffs!$F$6:$F$45,Tariffs!$B$6:$B$45,B9,Tariffs!$C$6:$C$45,A9))) -> 0 | I9: =SUMIFS(Tariffs!$G$6:$G$45,Tariffs!$B$6:$B$45,B9,Tariffs!$C$6:$C$45,A9) -> 0.12 | J9: =G9*(1+H9) -> 12.51584 | K9: =G9*(1+I9) -> 14.017741 | L9: =IF(Assumptions!$C$9="Eligible preference",J9,K9) -> 12.51584 | M9: =Assumptions!B27 -> 0.5 | N9: =Assumptions!C27 -> 0 | O9: =IF(B9="China",-1,M9) -> 0.5 | P9: =IF(B9="China",D9,IF(M9>0,MAX(0,MIN(Assumptions!$C$10-D9,Assumptions!$C$11,IF(Assumptions!$F$14="Yes",(Assumptions!$C$14-1)*D9,1))/M9),1)) -> 0.2 | Q9: =$E51*O9 -> 0.016110613 | R9: =D9+Q9 -> 0.11863816 | S9: =D9*L9 -> 1.2832184 | T9: =R9*L9+MAX(0,Q9)*L9*N9 -> 1.4848563 | U9: =O9*L9+M9*L9*N9 -> 6.2579201 | V9: =D9^2 -> 0.010511898 | W9: =2*D9*O9 -> 0.10252755 | X9: =O9^2 -> 0.25 | Y9: =IF(Candidate_Gates!N9="Pass",MAX(0,Q9),0) -> 0 | Z9: =D9*J9 -> 1.2832184 | AA9: =O9*J9+M9*J9*N9 -> 6.2579201 | AB9: =D9*K9 -> 1.4372046 | AC9: =O9*K9+M9*K9*N9 -> 7.0088705 | AD9: =IF(AND(C9>=0,F9>0,E9>0,ISNUMBER(G9),COUNTIFS(Trade_Periods!$B$6:$B$125,Assumptions!$C$6,Trade_Periods!$C$6:$C$125,B9,Trade_Periods!$D$6:$D$125,A9)=1,COUNTIFS(Tariffs!$B$6:$B$45,B9,Tariffs!$C$6:$C$45,A9)=1),"Ready","Missing data") -> Ready | AE9: =IF(D9>0,R9/D9,"n.a.") -> 1.1571345 | AF9: =IF(M9>0,IF(D9>0,R9/D9,IF(R9=0,0,"n.a.")),0) -> 1.1571345 | AG9: =IF(AND(Assumptions!$F$14="Yes",M9>0),MAX(0,R9-Assumptions!$C$14*D9),0) -> 0
A10: 61091000 | B10: Morocco | C10: =SUMIFS(Trade_Periods!$F$6:$F$125,Trade_Periods!$B$6:$B$125,"FY2025",Trade_Periods!$C$6:$C$125,B10,Trade_Periods!$D$6:$D$125,A10) -> 1265062 | D10: =C10/SUM(C6:C15) -> 0.016767799 | E10: =IF(Assumptions!$C$7="Reported",SUMIFS(Trade_Periods!$E$6:$E$125,Trade_Periods!$B$6:$B$125,Assumptions!$C$6,Trade_Periods!$C$6:$C$125,B10,Trade_Periods!$D$6:$D$125,A10),SUMIFS(Trade_Periods!$L$6:$L$125,Trade_Periods!$B$6:$B$125,Assumptions!$C$6,Trade_Periods!$C$6:$C$125,B10,Trade_Periods!$D$6:$D$125,A10)) -> 4957179 | F10: =IF(Assumptions!$C$7="Reported",SUMIFS(Trade_Periods!$F$6:$F$125,Trade_Periods!$B$6:$B$125,Assumptions!$C$6,Trade_Periods!$C$6:$C$125,B10,Trade_Periods!$D$6:$D$125,A10),SUMIFS(Trade_Periods!$M$6:$M$125,Trade_Periods!$B$6:$B$125,Assumptions!$C$6,Trade_Periods!$C$6:$C$125,B10,Trade_Periods!$D$6:$D$125,A10)) -> 526732 | G10: =IF(F10>0,E10/F10,"n.a.") -> 9.4111977 | H10: =IF(Assumptions!$C$8="2025",SUMIFS(Tariffs!$D$6:$D$45,Tariffs!$B$6:$B$45,B10,Tariffs!$C$6:$C$45,A10),IF(Assumptions!$C$8="1 Jan to 14 Jul 2026",SUMIFS(Tariffs!$E$6:$E$45,Tariffs!$B$6:$B$45,B10,Tariffs!$C$6:$C$45,A10),SUMIFS(Tariffs!$F$6:$F$45,Tariffs!$B$6:$B$45,B10,Tariffs!$C$6:$C$45,A10))) -> 0 | I10: =SUMIFS(Tariffs!$G$6:$G$45,Tariffs!$B$6:$B$45,B10,Tariffs!$C$6:$C$45,A10) -> 0.12 | J10: =G10*(1+H10) -> 9.4111977 | K10: =G10*(1+I10) -> 10.540541 | L10: =IF(Assumptions!$C$9="Eligible preference",J10,K10) -> 9.4111977 | M10: =Assumptions!B28 -> 0 | N10: =Assumptions!C28 -> 0 | O10: =IF(B10="China",-1,M10) -> 0 | P10: =IF(B10="China",D10,IF(M10>0,MAX(0,MIN(Assumptions!$C$10-D10,Assumptions!$C$11,IF(Assumptions!$F$14="Yes",(Assumptions!$C$14-1)*D10,1))/M10),1)) -> 1 | Q10: =$E51*O10 -> 0 | R10: =D10+Q10 -> 0.016767799 | S10: =D10*L10 -> 0.15780508 | T10: =R10*L10+MAX(0,Q10)*L10*N10 -> 0.15780508 | U10: =O10*L10+M10*L10*N10 -> 0 | V10: =D10^2 -> 0.0002811591 | W10: =2*D10*O10 -> 0 | X10: =O10^2 -> 0 | Y10: =IF(Candidate_Gates!N10="Pass",MAX(0,Q10),0) -> 0 | Z10: =D10*J10 -> 0.15780508 | AA10: =O10*J10+M10*J10*N10 -> 0 | AB10: =D10*K10 -> 0.17674168 | AC10: =O10*K10+M10*K10*N10 -> 0 | AD10: =IF(AND(C10>=0,F10>0,E10>0,ISNUMBER(G10),COUNTIFS(Trade_Periods!$B$6:$B$125,Assumptions!$C$6,Trade_Periods!$C$6:$C$125,B10,Trade_Periods!$D$6:$D$125,A10)=1,COUNTIFS(Tariffs!$B$6:$B$45,B10,Tariffs!$C$6:$C$45,A10)=1),"Ready","Missing data") -> Ready | AE10: =IF(D10>0,R10/D10,"n.a.") -> 1 | AF10: =IF(M10>0,IF(D10>0,R10/D10,IF(R10=0,0,"n.a.")),0) -> 0 | AG10: =IF(AND(Assumptions!$F$14="Yes",M10>0),MAX(0,R10-Assumptions!$C$14*D10),0) -> 0
A11: 61091000 | B11: Myanmar | C11: =SUMIFS(Trade_Periods!$F$6:$F$125,Trade_Periods!$B$6:$B$125,"FY2025",Trade_Periods!$C$6:$C$125,B11,Trade_Periods!$D$6:$D$125,A11) -> 29326 | D11: =C11/SUM(C6:C15) -> 0.00038870228 | E11: =IF(Assumptions!$C$7="Reported",SUMIFS(Trade_Periods!$E$6:$E$125,Trade_Periods!$B$6:$B$125,Assumptions!$C$6,Trade_Periods!$C$6:$C$125,B11,Trade_Periods!$D$6:$D$125,A11),SUMIFS(Trade_Periods!$L$6:$L$125,Trade_Periods!$B$6:$B$125,Assumptions!$C$6,Trade_Periods!$C$6:$C$125,B11,Trade_Periods!$D$6:$D$125,A11)) -> 619607 | F11: =IF(Assumptions!$C$7="Reported",SUMIFS(Trade_Periods!$F$6:$F$125,Trade_Periods!$B$6:$B$125,Assumptions!$C$6,Trade_Periods!$C$6:$C$125,B11,Trade_Periods!$D$6:$D$125,A11),SUMIFS(Trade_Periods!$M$6:$M$125,Trade_Periods!$B$6:$B$125,Assumptions!$C$6,Trade_Periods!$C$6:$C$125,B11,Trade_Periods!$D$6:$D$125,A11)) -> 58361 | G11: =IF(F11>0,E11/F11,"n.a.") -> 10.616799 | H11: =IF(Assumptions!$C$8="2025",SUMIFS(Tariffs!$D$6:$D$45,Tariffs!$B$6:$B$45,B11,Tariffs!$C$6:$C$45,A11),IF(Assumptions!$C$8="1 Jan to 14 Jul 2026",SUMIFS(Tariffs!$E$6:$E$45,Tariffs!$B$6:$B$45,B11,Tariffs!$C$6:$C$45,A11),SUMIFS(Tariffs!$F$6:$F$45,Tariffs!$B$6:$B$45,B11,Tariffs!$C$6:$C$45,A11))) -> 0 | I11: =SUMIFS(Tariffs!$G$6:$G$45,Tariffs!$B$6:$B$45,B11,Tariffs!$C$6:$C$45,A11) -> 0.12 | J11: =G11*(1+H11) -> 10.616799 | K11: =G11*(1+I11) -> 11.890815 | L11: =IF(Assumptions!$C$9="Eligible preference",J11,K11) -> 10.616799 | M11: =Assumptions!B29 -> 0 | N11: =Assumptions!C29 -> 0 | O11: =IF(B11="China",-1,M11) -> 0 | P11: =IF(B11="China",D11,IF(M11>0,MAX(0,MIN(Assumptions!$C$10-D11,Assumptions!$C$11,IF(Assumptions!$F$14="Yes",(Assumptions!$C$14-1)*D11,1))/M11),1)) -> 1 | Q11: =$E51*O11 -> 0 | R11: =D11+Q11 -> 0.00038870228 | S11: =D11*L11 -> 0.0041267739 | T11: =R11*L11+MAX(0,Q11)*L11*N11 -> 0.0041267739 | U11: =O11*L11+M11*L11*N11 -> 0 | V11: =D11^2 -> 1.5108946e-07 | W11: =2*D11*O11 -> 0 | X11: =O11^2 -> 0 | Y11: =IF(Candidate_Gates!N11="Pass",MAX(0,Q11),0) -> 0 | Z11: =D11*J11 -> 0.0041267739 | AA11: =O11*J11+M11*J11*N11 -> 0 | AB11: =D11*K11 -> 0.0046219868 | AC11: =O11*K11+M11*K11*N11 -> 0 | AD11: =IF(AND(C11>=0,F11>0,E11>0,ISNUMBER(G11),COUNTIFS(Trade_Periods!$B$6:$B$125,Assumptions!$C$6,Trade_Periods!$C$6:$C$125,B11,Trade_Periods!$D$6:$D$125,A11)=1,COUNTIFS(Tariffs!$B$6:$B$45,B11,Tariffs!$C$6:$C$45,A11)=1),"Ready","Missing data") -> Ready | AE11: =IF(D11>0,R11/D11,"n.a.") -> 1 | AF11: =IF(M11>0,IF(D11>0,R11/D11,IF(R11=0,0,"n.a.")),0) -> 0 | AG11: =IF(AND(Assumptions!$F$14="Yes",M11>0),MAX(0,R11-Assumptions!$C$14*D11),0) -> 0
A12: 61091000 | B12: Pakistan | C12: =SUMIFS(Trade_Periods!$F$6:$F$125,Trade_Periods!$B$6:$B$125,"FY2025",Trade_Periods!$C$6:$C$125,B12,Trade_Periods!$D$6:$D$125,A12) -> 10896985 | D12: =C12/SUM(C6:C15) -> 0.14443439 | E12: =IF(Assumptions!$C$7="Reported",SUMIFS(Trade_Periods!$E$6:$E$125,Trade_Periods!$B$6:$B$125,Assumptions!$C$6,Trade_Periods!$C$6:$C$125,B12,Trade_Periods!$D$6:$D$125,A12),SUMIFS(Trade_Periods!$L$6:$L$125,Trade_Periods!$B$6:$B$125,Assumptions!$C$6,Trade_Periods!$C$6:$C$125,B12,Trade_Periods!$D$6:$D$125,A12)) -> 20868271 | F12: =IF(Assumptions!$C$7="Reported",SUMIFS(Trade_Periods!$F$6:$F$125,Trade_Periods!$B$6:$B$125,Assumptions!$C$6,Trade_Periods!$C$6:$C$125,B12,Trade_Periods!$D$6:$D$125,A12),SUMIFS(Trade_Periods!$M$6:$M$125,Trade_Periods!$B$6:$B$125,Assumptions!$C$6,Trade_Periods!$C$6:$C$125,B12,Trade_Periods!$D$6:$D$125,A12)) -> 1714193 | G12: =IF(F12>0,E12/F12,"n.a.") -> 12.173816 | H12: =IF(Assumptions!$C$8="2025",SUMIFS(Tariffs!$D$6:$D$45,Tariffs!$B$6:$B$45,B12,Tariffs!$C$6:$C$45,A12),IF(Assumptions!$C$8="1 Jan to 14 Jul 2026",SUMIFS(Tariffs!$E$6:$E$45,Tariffs!$B$6:$B$45,B12,Tariffs!$C$6:$C$45,A12),SUMIFS(Tariffs!$F$6:$F$45,Tariffs!$B$6:$B$45,B12,Tariffs!$C$6:$C$45,A12))) -> 0 | I12: =SUMIFS(Tariffs!$G$6:$G$45,Tariffs!$B$6:$B$45,B12,Tariffs!$C$6:$C$45,A12) -> 0.12 | J12: =G12*(1+H12) -> 12.173816 | K12: =G12*(1+I12) -> 13.634674 | L12: =IF(Assumptions!$C$9="Eligible preference",J12,K12) -> 12.173816 | M12: =Assumptions!B30 -> 0 | N12: =Assumptions!C30 -> 0 | O12: =IF(B12="China",-1,M12) -> 0 | P12: =IF(B12="China",D12,IF(M12>0,MAX(0,MIN(Assumptions!$C$10-D12,Assumptions!$C$11,IF(Assumptions!$F$14="Yes",(Assumptions!$C$14-1)*D12,1))/M12),1)) -> 1 | Q12: =$E51*O12 -> 0 | R12: =D12+Q12 -> 0.14443439 | S12: =D12*L12 -> 1.7583178 | T12: =R12*L12+MAX(0,Q12)*L12*N12 -> 1.7583178 | U12: =O12*L12+M12*L12*N12 -> 0 | V12: =D12^2 -> 0.020861293 | W12: =2*D12*O12 -> 0 | X12: =O12^2 -> 0 | Y12: =IF(Candidate_Gates!N12="Pass",MAX(0,Q12),0) -> 0 | Z12: =D12*J12 -> 1.7583178 | AA12: =O12*J12+M12*J12*N12 -> 0 | AB12: =D12*K12 -> 1.9693159 | AC12: =O12*K12+M12*K12*N12 -> 0 | AD12: =IF(AND(C12>=0,F12>0,E12>0,ISNUMBER(G12),COUNTIFS(Trade_Periods!$B$6:$B$125,Assumptions!$C$6,Trade_Periods!$C$6:$C$125,B12,Trade_Periods!$D$6:$D$125,A12)=1,COUNTIFS(Tariffs!$B$6:$B$45,B12,Tariffs!$C$6:$C$45,A12)=1),"Ready","Missing data") -> Ready | AE12: =IF(D12>0,R12/D12,"n.a.") -> 1 | AF12: =IF(M12>0,IF(D12>0,R12/D12,IF(R12=0,0,"n.a.")),0) -> 0 | AG12: =IF(AND(Assumptions!$F$14="Yes",M12>0),MAX(0,R12-Assumptions!$C$14*D12),0) -> 0
A13: 61091000 | B13: Sri Lanka | C13: =SUMIFS(Trade_Periods!$F$6:$F$125,Trade_Periods!$B$6:$B$125,"FY2025",Trade_Periods!$C$6:$C$125,B13,Trade_Periods!$D$6:$D$125,A13) -> 2215013 | D13: =C13/SUM(C6:C15) -> 0.029358951 | E13: =IF(Assumptions!$C$7="Reported",SUMIFS(Trade_Periods!$E$6:$E$125,Trade_Periods!$B$6:$B$125,Assumptions!$C$6,Trade_Periods!$C$6:$C$125,B13,Trade_Periods!$D$6:$D$125,A13),SUMIFS(Trade_Periods!$L$6:$L$125,Trade_Periods!$B$6:$B$125,Assumptions!$C$6,Trade_Periods!$C$6:$C$125,B13,Trade_Periods!$D$6:$D$125,A13)) -> 8791535 | F13: =IF(Assumptions!$C$7="Reported",SUMIFS(Trade_Periods!$F$6:$F$125,Trade_Periods!$B$6:$B$125,Assumptions!$C$6,Trade_Periods!$C$6:$C$125,B13,Trade_Periods!$D$6:$D$125,A13),SUMIFS(Trade_Periods!$M$6:$M$125,Trade_Periods!$B$6:$B$125,Assumptions!$C$6,Trade_Periods!$C$6:$C$125,B13,Trade_Periods!$D$6:$D$125,A13)) -> 729136 | G13: =IF(F13>0,E13/F13,"n.a.") -> 12.057469 | H13: =IF(Assumptions!$C$8="2025",SUMIFS(Tariffs!$D$6:$D$45,Tariffs!$B$6:$B$45,B13,Tariffs!$C$6:$C$45,A13),IF(Assumptions!$C$8="1 Jan to 14 Jul 2026",SUMIFS(Tariffs!$E$6:$E$45,Tariffs!$B$6:$B$45,B13,Tariffs!$C$6:$C$45,A13),SUMIFS(Tariffs!$F$6:$F$45,Tariffs!$B$6:$B$45,B13,Tariffs!$C$6:$C$45,A13))) -> 0 | I13: =SUMIFS(Tariffs!$G$6:$G$45,Tariffs!$B$6:$B$45,B13,Tariffs!$C$6:$C$45,A13) -> 0.12 | J13: =G13*(1+H13) -> 12.057469 | K13: =G13*(1+I13) -> 13.504366 | L13: =IF(Assumptions!$C$9="Eligible preference",J13,K13) -> 12.057469 | M13: =Assumptions!B31 -> 0 | N13: =Assumptions!C31 -> 0 | O13: =IF(B13="China",-1,M13) -> 0 | P13: =IF(B13="China",D13,IF(M13>0,MAX(0,MIN(Assumptions!$C$10-D13,Assumptions!$C$11,IF(Assumptions!$F$14="Yes",(Assumptions!$C$14-1)*D13,1))/M13),1)) -> 1 | Q13: =$E51*O13 -> 0 | R13: =D13+Q13 -> 0.029358951 | S13: =D13*L13 -> 0.35399466 | T13: =R13*L13+MAX(0,Q13)*L13*N13 -> 0.35399466 | U13: =O13*L13+M13*L13*N13 -> 0 | V13: =D13^2 -> 0.00086194802 | W13: =2*D13*O13 -> 0 | X13: =O13^2 -> 0 | Y13: =IF(Candidate_Gates!N13="Pass",MAX(0,Q13),0) -> 0 | Z13: =D13*J13 -> 0.35399466 | AA13: =O13*J13+M13*J13*N13 -> 0 | AB13: =D13*K13 -> 0.39647401 | AC13: =O13*K13+M13*K13*N13 -> 0 | AD13: =IF(AND(C13>=0,F13>0,E13>0,ISNUMBER(G13),COUNTIFS(Trade_Periods!$B$6:$B$125,Assumptions!$C$6,Trade_Periods!$C$6:$C$125,B13,Trade_Periods!$D$6:$D$125,A13)=1,COUNTIFS(Tariffs!$B$6:$B$45,B13,Tariffs!$C$6:$C$45,A13)=1),"Ready","Missing data") -> Ready | AE13: =IF(D13>0,R13/D13,"n.a.") -> 1 | AF13: =IF(M13>0,IF(D13>0,R13/D13,IF(R13=0,0,"n.a.")),0) -> 0 | AG13: =IF(AND(Assumptions!$F$14="Yes",M13>0),MAX(0,R13-Assumptions!$C$14*D13),0) -> 0
A14: 61091000 | B14: Turkey | C14: =SUMIFS(Trade_Periods!$F$6:$F$125,Trade_Periods!$B$6:$B$125,"FY2025",Trade_Periods!$C$6:$C$125,B14,Trade_Periods!$D$6:$D$125,A14) -> 4927477 | D14: =C14/SUM(C6:C15) -> 0.065311381 | E14: =IF(Assumptions!$C$7="Reported",SUMIFS(Trade_Periods!$E$6:$E$125,Trade_Periods!$B$6:$B$125,Assumptions!$C$6,Trade_Periods!$C$6:$C$125,B14,Trade_Periods!$D$6:$D$125,A14),SUMIFS(Trade_Periods!$L$6:$L$125,Trade_Periods!$B$6:$B$125,Assumptions!$C$6,Trade_Periods!$C$6:$C$125,B14,Trade_Periods!$D$6:$D$125,A14)) -> 58384062 | F14: =IF(Assumptions!$C$7="Reported",SUMIFS(Trade_Periods!$F$6:$F$125,Trade_Periods!$B$6:$B$125,Assumptions!$C$6,Trade_Periods!$C$6:$C$125,B14,Trade_Periods!$D$6:$D$125,A14),SUMIFS(Trade_Periods!$M$6:$M$125,Trade_Periods!$B$6:$B$125,Assumptions!$C$6,Trade_Periods!$C$6:$C$125,B14,Trade_Periods!$D$6:$D$125,A14)) -> 2450042 | G14: =IF(F14>0,E14/F14,"n.a.") -> 23.829821 | H14: =IF(Assumptions!$C$8="2025",SUMIFS(Tariffs!$D$6:$D$45,Tariffs!$B$6:$B$45,B14,Tariffs!$C$6:$C$45,A14),IF(Assumptions!$C$8="1 Jan to 14 Jul 2026",SUMIFS(Tariffs!$E$6:$E$45,Tariffs!$B$6:$B$45,B14,Tariffs!$C$6:$C$45,A14),SUMIFS(Tariffs!$F$6:$F$45,Tariffs!$B$6:$B$45,B14,Tariffs!$C$6:$C$45,A14))) -> 0 | I14: =SUMIFS(Tariffs!$G$6:$G$45,Tariffs!$B$6:$B$45,B14,Tariffs!$C$6:$C$45,A14) -> 0.12 | J14: =G14*(1+H14) -> 23.829821 | K14: =G14*(1+I14) -> 26.689399 | L14: =IF(Assumptions!$C$9="Eligible preference",J14,K14) -> 23.829821 | M14: =Assumptions!B32 -> 0.25 | N14: =Assumptions!C32 -> 0 | O14: =IF(B14="China",-1,M14) -> 0.25 | P14: =IF(B14="China",D14,IF(M14>0,MAX(0,MIN(Assumptions!$C$10-D14,Assumptions!$C$11,IF(Assumptions!$F$14="Yes",(Assumptions!$C$14-1)*D14,1))/M14),1)) -> 0.4 | Q14: =$E51*O14 -> 0.0080553067 | R14: =D14+Q14 -> 0.073366687 | S14: =D14*L14 -> 1.5563585 | T14: =R14*L14+MAX(0,Q14)*L14*N14 -> 1.748315 | U14: =O14*L14+M14*L14*N14 -> 5.9574552 | V14: =D14^2 -> 0.0042655764 | W14: =2*D14*O14 -> 0.03265569 | X14: =O14^2 -> 0.0625 | Y14: =IF(Candidate_Gates!N14="Pass",MAX(0,Q14),0) -> 0 | Z14: =D14*J14 -> 1.5563585 | AA14: =O14*J14+M14*J14*N14 -> 5.9574552 | AB14: =D14*K14 -> 1.7431215 | AC14: =O14*K14+M14*K14*N14 -> 6.6723498 | AD14: =IF(AND(C14>=0,F14>0,E14>0,ISNUMBER(G14),COUNTIFS(Trade_Periods!$B$6:$B$125,Assumptions!$C$6,Trade_Periods!$C$6:$C$125,B14,Trade_Periods!$D$6:$D$125,A14)=1,COUNTIFS(Tariffs!$B$6:$B$45,B14,Tariffs!$C$6:$C$45,A14)=1),"Ready","Missing data") -> Ready | AE14: =IF(D14>0,R14/D14,"n.a.") -> 1.123337 | AF14: =IF(M14>0,IF(D14>0,R14/D14,IF(R14=0,0,"n.a.")),0) -> 1.123337 | AG14: =IF(AND(Assumptions!$F$14="Yes",M14>0),MAX(0,R14-Assumptions!$C$14*D14),0) -> 0
A15: 61091000 | B15: Vietnam | C15: =SUMIFS(Trade_Periods!$F$6:$F$125,Trade_Periods!$B$6:$B$125,"FY2025",Trade_Periods!$C$6:$C$125,B15,Trade_Periods!$D$6:$D$125,A15) -> 1170082 | D15: =C15/SUM(C6:C15) -> 0.015508884 | E15: =IF(Assumptions!$C$7="Reported",SUMIFS(Trade_Periods!$E$6:$E$125,Trade_Periods!$B$6:$B$125,Assumptions!$C$6,Trade_Periods!$C$6:$C$125,B15,Trade_Periods!$D$6:$D$125,A15),SUMIFS(Trade_Periods!$L$6:$L$125,Trade_Periods!$B$6:$B$125,Assumptions!$C$6,Trade_Periods!$C$6:$C$125,B15,Trade_Periods!$D$6:$D$125,A15)) -> 13656174 | F15: =IF(Assumptions!$C$7="Reported",SUMIFS(Trade_Periods!$F$6:$F$125,Trade_Periods!$B$6:$B$125,Assumptions!$C$6,Trade_Periods!$C$6:$C$125,B15,Trade_Periods!$D$6:$D$125,A15),SUMIFS(Trade_Periods!$M$6:$M$125,Trade_Periods!$B$6:$B$125,Assumptions!$C$6,Trade_Periods!$C$6:$C$125,B15,Trade_Periods!$D$6:$D$125,A15)) -> 532624 | G15: =IF(F15>0,E15/F15,"n.a.") -> 25.639427 | H15: =IF(Assumptions!$C$8="2025",SUMIFS(Tariffs!$D$6:$D$45,Tariffs!$B$6:$B$45,B15,Tariffs!$C$6:$C$45,A15),IF(Assumptions!$C$8="1 Jan to 14 Jul 2026",SUMIFS(Tariffs!$E$6:$E$45,Tariffs!$B$6:$B$45,B15,Tariffs!$C$6:$C$45,A15),SUMIFS(Tariffs!$F$6:$F$45,Tariffs!$B$6:$B$45,B15,Tariffs!$C$6:$C$45,A15))) -> 0 | I15: =SUMIFS(Tariffs!$G$6:$G$45,Tariffs!$B$6:$B$45,B15,Tariffs!$C$6:$C$45,A15) -> 0.12 | J15: =G15*(1+H15) -> 25.639427 | K15: =G15*(1+I15) -> 28.716158 | L15: =IF(Assumptions!$C$9="Eligible preference",J15,K15) -> 25.639427 | M15: =Assumptions!B33 -> 0.25 | N15: =Assumptions!C33 -> 0 | O15: =IF(B15="China",-1,M15) -> 0.25 | P15: =IF(B15="China",D15,IF(M15>0,MAX(0,MIN(Assumptions!$C$10-D15,Assumptions!$C$11,IF(Assumptions!$F$14="Yes",(Assumptions!$C$14-1)*D15,1))/M15),1)) -> 0.12407107 | Q15: =$E51*O15 -> 0.0080553067 | R15: =D15+Q15 -> 0.023564191 | S15: =D15*L15 -> 0.3976389 | T15: =R15*L15+MAX(0,Q15)*L15*N15 -> 0.60417235 | U15: =O15*L15+M15*L15*N15 -> 6.4098567 | V15: =D15^2 -> 0.00024052549 | W15: =2*D15*O15 -> 0.0077544422 | X15: =O15^2 -> 0.0625 | Y15: =IF(Candidate_Gates!N15="Pass",MAX(0,Q15),0) -> 0 | Z15: =D15*J15 -> 0.3976389 | AA15: =O15*J15+M15*J15*N15 -> 6.4098567 | AB15: =D15*K15 -> 0.44535557 | AC15: =O15*K15+M15*K15*N15 -> 7.1790395 | AD15: =IF(AND(C15>=0,F15>0,E15>0,ISNUMBER(G15),COUNTIFS(Trade_Periods!$B$6:$B$125,Assumptions!$C$6,Trade_Periods!$C$6:$C$125,B15,Trade_Periods!$D$6:$D$125,A15)=1,COUNTIFS(Tariffs!$B$6:$B$45,B15,Tariffs!$C$6:$C$45,A15)=1),"Ready","Missing data") -> Ready | AE15: =IF(D15>0,R15/D15,"n.a.") -> 1.5193995 | AF15: =IF(M15>0,IF(D15>0,R15/D15,IF(R15=0,0,"n.a.")),0) -> 1.5193995 | AG15: =IF(AND(Assumptions!$F$14="Yes",M15>0),MAX(0,R15-Assumptions!$C$14*D15),0) -> 0
A16: 61103099 | B16: Bangladesh | C16: =SUMIFS(Trade_Periods!$F$6:$F$125,Trade_Periods!$B$6:$B$125,"FY2025",Trade_Periods!$C$6:$C$125,B16,Trade_Periods!$D$6:$D$125,A16) -> 13246692 | D16: =C16/SUM(C16:C25) -> 0.29466445 | E16: =IF(Assumptions!$C$7="Reported",SUMIFS(Trade_Periods!$E$6:$E$125,Trade_Periods!$B$6:$B$125,Assumptions!$C$6,Trade_Periods!$C$6:$C$125,B16,Trade_Periods!$D$6:$D$125,A16),SUMIFS(Trade_Periods!$L$6:$L$125,Trade_Periods!$B$6:$B$125,Assumptions!$C$6,Trade_Periods!$C$6:$C$125,B16,Trade_Periods!$D$6:$D$125,A16)) -> 41106466 | F16: =IF(Assumptions!$C$7="Reported",SUMIFS(Trade_Periods!$F$6:$F$125,Trade_Periods!$B$6:$B$125,Assumptions!$C$6,Trade_Periods!$C$6:$C$125,B16,Trade_Periods!$D$6:$D$125,A16),SUMIFS(Trade_Periods!$M$6:$M$125,Trade_Periods!$B$6:$B$125,Assumptions!$C$6,Trade_Periods!$C$6:$C$125,B16,Trade_Periods!$D$6:$D$125,A16)) -> 3340374 | G16: =IF(F16>0,E16/F16,"n.a.") -> 12.305947 | H16: =IF(Assumptions!$C$8="2025",SUMIFS(Tariffs!$D$6:$D$45,Tariffs!$B$6:$B$45,B16,Tariffs!$C$6:$C$45,A16),IF(Assumptions!$C$8="1 Jan to 14 Jul 2026",SUMIFS(Tariffs!$E$6:$E$45,Tariffs!$B$6:$B$45,B16,Tariffs!$C$6:$C$45,A16),SUMIFS(Tariffs!$F$6:$F$45,Tariffs!$B$6:$B$45,B16,Tariffs!$C$6:$C$45,A16))) -> 0 | I16: =SUMIFS(Tariffs!$G$6:$G$45,Tariffs!$B$6:$B$45,B16,Tariffs!$C$6:$C$45,A16) -> 0.12 | J16: =G16*(1+H16) -> 12.305947 | K16: =G16*(1+I16) -> 13.782661 | L16: =IF(Assumptions!$C$9="Eligible preference",J16,K16) -> 12.305947 | M16: =Assumptions!B24 -> 0 | N16: =Assumptions!C24 -> 0 | O16: =IF(B16="China",-1,M16) -> 0 | P16: =IF(B16="China",D16,IF(M16>0,MAX(0,MIN(Assumptions!$C$10-D16,Assumptions!$C$11,IF(Assumptions!$F$14="Yes",(Assumptions!$C$14-1)*D16,1))/M16),1)) -> 1 | Q16: =$E52*O16 -> 0 | R16: =D16+Q16 -> 0.29466445 | S16: =D16*L16 -> 3.6261252 | T16: =R16*L16+MAX(0,Q16)*L16*N16 -> 3.6261252 | U16: =O16*L16+M16*L16*N16 -> 0 | V16: =D16^2 -> 0.086827139 | W16: =2*D16*O16 -> 0 | X16: =O16^2 -> 0 | Y16: =IF(Candidate_Gates!N16="Pass",MAX(0,Q16),0) -> 0 | Z16: =D16*J16 -> 3.6261252 | AA16: =O16*J16+M16*J16*N16 -> 0 | AB16: =D16*K16 -> 4.0612602 | AC16: =O16*K16+M16*K16*N16 -> 0 | AD16: =IF(AND(C16>=0,F16>0,E16>0,ISNUMBER(G16),COUNTIFS(Trade_Periods!$B$6:$B$125,Assumptions!$C$6,Trade_Periods!$C$6:$C$125,B16,Trade_Periods!$D$6:$D$125,A16)=1,COUNTIFS(Tariffs!$B$6:$B$45,B16,Tariffs!$C$6:$C$45,A16)=1),"Ready","Missing data") -> Ready | AE16: =IF(D16>0,R16/D16,"n.a.") -> 1 | AF16: =IF(M16>0,IF(D16>0,R16/D16,IF(R16=0,0,"n.a.")),0) -> 0 | AG16: =IF(AND(Assumptions!$F$14="Yes",M16>0),MAX(0,R16-Assumptions!$C$14*D16),0) -> 0
A17: 61103099 | B17: Cambodia | C17: =SUMIFS(Trade_Periods!$F$6:$F$125,Trade_Periods!$B$6:$B$125,"FY2025",Trade_Periods!$C$6:$C$125,B17,Trade_Periods!$D$6:$D$125,A17) -> 6288565 | D17: =C17/SUM(C16:C25) -> 0.13988523 | E17: =IF(Assumptions!$C$7="Reported",SUMIFS(Trade_Periods!$E$6:$E$125,Trade_Periods!$B$6:$B$125,Assumptions!$C$6,Trade_Periods!$C$6:$C$125,B17,Trade_Periods!$D$6:$D$125,A17),SUMIFS(Trade_Periods!$L$6:$L$125,Trade_Periods!$B$6:$B$125,Assumptions!$C$6,Trade_Periods!$C$6:$C$125,B17,Trade_Periods!$D$6:$D$125,A17)) -> 20275618 | F17: =IF(Assumptions!$C$7="Reported",SUMIFS(Trade_Periods!$F$6:$F$125,Trade_Periods!$B$6:$B$125,Assumptions!$C$6,Trade_Periods!$C$6:$C$125,B17,Trade_Periods!$D$6:$D$125,A17),SUMIFS(Trade_Periods!$M$6:$M$125,Trade_Periods!$B$6:$B$125,Assumptions!$C$6,Trade_Periods!$C$6:$C$125,B17,Trade_Periods!$D$6:$D$125,A17)) -> 1804538 | G17: =IF(F17>0,E17/F17,"n.a.") -> 11.235905 | H17: =IF(Assumptions!$C$8="2025",SUMIFS(Tariffs!$D$6:$D$45,Tariffs!$B$6:$B$45,B17,Tariffs!$C$6:$C$45,A17),IF(Assumptions!$C$8="1 Jan to 14 Jul 2026",SUMIFS(Tariffs!$E$6:$E$45,Tariffs!$B$6:$B$45,B17,Tariffs!$C$6:$C$45,A17),SUMIFS(Tariffs!$F$6:$F$45,Tariffs!$B$6:$B$45,B17,Tariffs!$C$6:$C$45,A17))) -> 0 | I17: =SUMIFS(Tariffs!$G$6:$G$45,Tariffs!$B$6:$B$45,B17,Tariffs!$C$6:$C$45,A17) -> 0.12 | J17: =G17*(1+H17) -> 11.235905 | K17: =G17*(1+I17) -> 12.584214 | L17: =IF(Assumptions!$C$9="Eligible preference",J17,K17) -> 11.235905 | M17: =Assumptions!B25 -> 0 | N17: =Assumptions!C25 -> 0 | O17: =IF(B17="China",-1,M17) -> 0 | P17: =IF(B17="China",D17,IF(M17>0,MAX(0,MIN(Assumptions!$C$10-D17,Assumptions!$C$11,IF(Assumptions!$F$14="Yes",(Assumptions!$C$14-1)*D17,1))/M17),1)) -> 1 | Q17: =$E52*O17 -> 0 | R17: =D17+Q17 -> 0.13988523 | S17: =D17*L17 -> 1.5717372 | T17: =R17*L17+MAX(0,Q17)*L17*N17 -> 1.5717372 | U17: =O17*L17+M17*L17*N17 -> 0 | V17: =D17^2 -> 0.019567878 | W17: =2*D17*O17 -> 0 | X17: =O17^2 -> 0 | Y17: =IF(Candidate_Gates!N17="Pass",MAX(0,Q17),0) -> 0 | Z17: =D17*J17 -> 1.5717372 | AA17: =O17*J17+M17*J17*N17 -> 0 | AB17: =D17*K17 -> 1.7603457 | AC17: =O17*K17+M17*K17*N17 -> 0 | AD17: =IF(AND(C17>=0,F17>0,E17>0,ISNUMBER(G17),COUNTIFS(Trade_Periods!$B$6:$B$125,Assumptions!$C$6,Trade_Periods!$C$6:$C$125,B17,Trade_Periods!$D$6:$D$125,A17)=1,COUNTIFS(Tariffs!$B$6:$B$45,B17,Tariffs!$C$6:$C$45,A17)=1),"Ready","Missing data") -> Ready | AE17: =IF(D17>0,R17/D17,"n.a.") -> 1 | AF17: =IF(M17>0,IF(D17>0,R17/D17,IF(R17=0,0,"n.a.")),0) -> 0 | AG17: =IF(AND(Assumptions!$F$14="Yes",M17>0),MAX(0,R17-Assumptions!$C$14*D17),0) -> 0
A18: 61103099 | B18: China | C18: =SUMIFS(Trade_Periods!$F$6:$F$125,Trade_Periods!$B$6:$B$125,"FY2025",Trade_Periods!$C$6:$C$125,B18,Trade_Periods!$D$6:$D$125,A18) -> 16459562 | D18: =C18/SUM(C16:C25) -> 0.36613275 | E18: =IF(Assumptions!$C$7="Reported",SUMIFS(Trade_Periods!$E$6:$E$125,Trade_Periods!$B$6:$B$125,Assumptions!$C$6,Trade_Periods!$C$6:$C$125,B18,Trade_Periods!$D$6:$D$125,A18),SUMIFS(Trade_Periods!$L$6:$L$125,Trade_Periods!$B$6:$B$125,Assumptions!$C$6,Trade_Periods!$C$6:$C$125,B18,Trade_Periods!$D$6:$D$125,A18)) -> 44515052 | F18: =IF(Assumptions!$C$7="Reported",SUMIFS(Trade_Periods!$F$6:$F$125,Trade_Periods!$B$6:$B$125,Assumptions!$C$6,Trade_Periods!$C$6:$C$125,B18,Trade_Periods!$D$6:$D$125,A18),SUMIFS(Trade_Periods!$M$6:$M$125,Trade_Periods!$B$6:$B$125,Assumptions!$C$6,Trade_Periods!$C$6:$C$125,B18,Trade_Periods!$D$6:$D$125,A18)) -> 2608798 | G18: =IF(F18>0,E18/F18,"n.a.") -> 17.063434 | H18: =IF(Assumptions!$C$8="2025",SUMIFS(Tariffs!$D$6:$D$45,Tariffs!$B$6:$B$45,B18,Tariffs!$C$6:$C$45,A18),IF(Assumptions!$C$8="1 Jan to 14 Jul 2026",SUMIFS(Tariffs!$E$6:$E$45,Tariffs!$B$6:$B$45,B18,Tariffs!$C$6:$C$45,A18),SUMIFS(Tariffs!$F$6:$F$45,Tariffs!$B$6:$B$45,B18,Tariffs!$C$6:$C$45,A18))) -> 0.12 | I18: =SUMIFS(Tariffs!$G$6:$G$45,Tariffs!$B$6:$B$45,B18,Tariffs!$C$6:$C$45,A18) -> 0.12 | J18: =G18*(1+H18) -> 19.111046 | K18: =G18*(1+I18) -> 19.111046 | L18: =IF(Assumptions!$C$9="Eligible preference",J18,K18) -> 19.111046 | M18: =Assumptions!B26 -> 0 | N18: =Assumptions!C26 -> 0 | O18: =IF(B18="China",-1,M18) -> -1 | P18: =IF(B18="China",D18,IF(M18>0,MAX(0,MIN(Assumptions!$C$10-D18,Assumptions!$C$11,IF(Assumptions!$F$14="Yes",(Assumptions!$C$14-1)*D18,1))/M18),1)) -> 0.36613275 | Q18: =$E52*O18 -> -0.014153298 | R18: =D18+Q18 -> 0.35197946 | S18: =D18*L18 -> 6.9971798 | T18: =R18*L18+MAX(0,Q18)*L18*N18 -> 6.7266955 | U18: =O18*L18+M18*L18*N18 -> -19.111046 | V18: =D18^2 -> 0.13405319 | W18: =2*D18*O18 -> -0.73226551 | X18: =O18^2 -> 1 | Y18: =IF(Candidate_Gates!N18="Pass",MAX(0,Q18),0) -> 0 | Z18: =D18*J18 -> 6.9971798 | AA18: =O18*J18+M18*J18*N18 -> -19.111046 | AB18: =D18*K18 -> 6.9971798 | AC18: =O18*K18+M18*K18*N18 -> -19.111046 | AD18: =IF(AND(C18>=0,F18>0,E18>0,ISNUMBER(G18),COUNTIFS(Trade_Periods!$B$6:$B$125,Assumptions!$C$6,Trade_Periods!$C$6:$C$125,B18,Trade_Periods!$D$6:$D$125,A18)=1,COUNTIFS(Tariffs!$B$6:$B$45,B18,Tariffs!$C$6:$C$45,A18)=1),"Ready","Missing data") -> Ready | AE18: =IF(D18>0,R18/D18,"n.a.") -> 0.96134381 | AF18: =IF(M18>0,IF(D18>0,R18/D18,IF(R18=0,0,"n.a.")),0) -> 0 | AG18: =IF(AND(Assumptions!$F$14="Yes",M18>0),MAX(0,R18-Assumptions!$C$14*D18),0) -> 0
A19: 61103099 | B19: India | C19: =SUMIFS(Trade_Periods!$F$6:$F$125,Trade_Periods!$B$6:$B$125,"FY2025",Trade_Periods!$C$6:$C$125,B19,Trade_Periods!$D$6:$D$125,A19) -> 159066 | D19: =C19/SUM(C16:C25) -> 0.0035383246 | E19: =IF(Assumptions!$C$7="Reported",SUMIFS(Trade_Periods!$E$6:$E$125,Trade_Periods!$B$6:$B$125,Assumptions!$C$6,Trade_Periods!$C$6:$C$125,B19,Trade_Periods!$D$6:$D$125,A19),SUMIFS(Trade_Periods!$L$6:$L$125,Trade_Periods!$B$6:$B$125,Assumptions!$C$6,Trade_Periods!$C$6:$C$125,B19,Trade_Periods!$D$6:$D$125,A19)) -> 709744 | F19: =IF(Assumptions!$C$7="Reported",SUMIFS(Trade_Periods!$F$6:$F$125,Trade_Periods!$B$6:$B$125,Assumptions!$C$6,Trade_Periods!$C$6:$C$125,B19,Trade_Periods!$D$6:$D$125,A19),SUMIFS(Trade_Periods!$M$6:$M$125,Trade_Periods!$B$6:$B$125,Assumptions!$C$6,Trade_Periods!$C$6:$C$125,B19,Trade_Periods!$D$6:$D$125,A19)) -> 46899 | G19: =IF(F19>0,E19/F19,"n.a.") -> 15.133457 | H19: =IF(Assumptions!$C$8="2025",SUMIFS(Tariffs!$D$6:$D$45,Tariffs!$B$6:$B$45,B19,Tariffs!$C$6:$C$45,A19),IF(Assumptions!$C$8="1 Jan to 14 Jul 2026",SUMIFS(Tariffs!$E$6:$E$45,Tariffs!$B$6:$B$45,B19,Tariffs!$C$6:$C$45,A19),SUMIFS(Tariffs!$F$6:$F$45,Tariffs!$B$6:$B$45,B19,Tariffs!$C$6:$C$45,A19))) -> 0 | I19: =SUMIFS(Tariffs!$G$6:$G$45,Tariffs!$B$6:$B$45,B19,Tariffs!$C$6:$C$45,A19) -> 0.12 | J19: =G19*(1+H19) -> 15.133457 | K19: =G19*(1+I19) -> 16.949472 | L19: =IF(Assumptions!$C$9="Eligible preference",J19,K19) -> 15.133457 | M19: =Assumptions!B27 -> 0.5 | N19: =Assumptions!C27 -> 0 | O19: =IF(B19="China",-1,M19) -> 0.5 | P19: =IF(B19="China",D19,IF(M19>0,MAX(0,MIN(Assumptions!$C$10-D19,Assumptions!$C$11,IF(Assumptions!$F$14="Yes",(Assumptions!$C$14-1)*D19,1))/M19),1)) -> 0.014153298 | Q19: =$E52*O19 -> 0.0070766491 | R19: =D19+Q19 -> 0.010614974 | S19: =D19*L19 -> 0.053547083 | T19: =R19*L19+MAX(0,Q19)*L19*N19 -> 0.16064125 | U19: =O19*L19+M19*L19*N19 -> 7.5667285 | V19: =D19^2 -> 1.2519741e-05 | W19: =2*D19*O19 -> 0.0035383246 | X19: =O19^2 -> 0.25 | Y19: =IF(Candidate_Gates!N19="Pass",MAX(0,Q19),0) -> 0 | Z19: =D19*J19 -> 0.053547083 | AA19: =O19*J19+M19*J19*N19 -> 7.5667285 | AB19: =D19*K19 -> 0.059972733 | AC19: =O19*K19+M19*K19*N19 -> 8.4747359 | AD19: =IF(AND(C19>=0,F19>0,E19>0,ISNUMBER(G19),COUNTIFS(Trade_Periods!$B$6:$B$125,Assumptions!$C$6,Trade_Periods!$C$6:$C$125,B19,Trade_Periods!$D$6:$D$125,A19)=1,COUNTIFS(Tariffs!$B$6:$B$45,B19,Tariffs!$C$6:$C$45,A19)=1),"Ready","Missing data") -> Ready | AE19: =IF(D19>0,R19/D19,"n.a.") -> 3 | AF19: =IF(M19>0,IF(D19>0,R19/D19,IF(R19=0,0,"n.a.")),0) -> 3 | AG19: =IF(AND(Assumptions!$F$14="Yes",M19>0),MAX(0,R19-Assumptions!$C$14*D19),0) -> 0
A20: 61103099 | B20: Morocco | C20: =SUMIFS(Trade_Periods!$F$6:$F$125,Trade_Periods!$B$6:$B$125,"FY2025",Trade_Periods!$C$6:$C$125,B20,Trade_Periods!$D$6:$D$125,A20) -> 19704 | D20: =C20/SUM(C16:C25) -> 0.00043830327 | E20: =IF(Assumptions!$C$7="Reported",SUMIFS(Trade_Periods!$E$6:$E$125,Trade_Periods!$B$6:$B$125,Assumptions!$C$6,Trade_Periods!$C$6:$C$125,B20,Trade_Periods!$D$6:$D$125,A20),SUMIFS(Trade_Periods!$L$6:$L$125,Trade_Periods!$B$6:$B$125,Assumptions!$C$6,Trade_Periods!$C$6:$C$125,B20,Trade_Periods!$D$6:$D$125,A20)) -> 94543 | F20: =IF(Assumptions!$C$7="Reported",SUMIFS(Trade_Periods!$F$6:$F$125,Trade_Periods!$B$6:$B$125,Assumptions!$C$6,Trade_Periods!$C$6:$C$125,B20,Trade_Periods!$D$6:$D$125,A20),SUMIFS(Trade_Periods!$M$6:$M$125,Trade_Periods!$B$6:$B$125,Assumptions!$C$6,Trade_Periods!$C$6:$C$125,B20,Trade_Periods!$D$6:$D$125,A20)) -> 3440 | G20: =IF(F20>0,E20/F20,"n.a.") -> 27.48343 | H20: =IF(Assumptions!$C$8="2025",SUMIFS(Tariffs!$D$6:$D$45,Tariffs!$B$6:$B$45,B20,Tariffs!$C$6:$C$45,A20),IF(Assumptions!$C$8="1 Jan to 14 Jul 2026",SUMIFS(Tariffs!$E$6:$E$45,Tariffs!$B$6:$B$45,B20,Tariffs!$C$6:$C$45,A20),SUMIFS(Tariffs!$F$6:$F$45,Tariffs!$B$6:$B$45,B20,Tariffs!$C$6:$C$45,A20))) -> 0 | I20: =SUMIFS(Tariffs!$G$6:$G$45,Tariffs!$B$6:$B$45,B20,Tariffs!$C$6:$C$45,A20) -> 0.12 | J20: =G20*(1+H20) -> 27.48343 | K20: =G20*(1+I20) -> 30.781442 | L20: =IF(Assumptions!$C$9="Eligible preference",J20,K20) -> 27.48343 | M20: =Assumptions!B28 -> 0 | N20: =Assumptions!C28 -> 0 | O20: =IF(B20="China",-1,M20) -> 0 | P20: =IF(B20="China",D20,IF(M20>0,MAX(0,MIN(Assumptions!$C$10-D20,Assumptions!$C$11,IF(Assumptions!$F$14="Yes",(Assumptions!$C$14-1)*D20,1))/M20),1)) -> 1 | Q20: =$E52*O20 -> 0 | R20: =D20+Q20 -> 0.00043830327 | S20: =D20*L20 -> 0.012046077 | T20: =R20*L20+MAX(0,Q20)*L20*N20 -> 0.012046077 | U20: =O20*L20+M20*L20*N20 -> 0 | V20: =D20^2 -> 1.9210975e-07 | W20: =2*D20*O20 -> 0 | X20: =O20^2 -> 0 | Y20: =IF(Candidate_Gates!N20="Pass",MAX(0,Q20),0) -> 0 | Z20: =D20*J20 -> 0.012046077 | AA20: =O20*J20+M20*J20*N20 -> 0 | AB20: =D20*K20 -> 0.013491606 | AC20: =O20*K20+M20*K20*N20 -> 0 | AD20: =IF(AND(C20>=0,F20>0,E20>0,ISNUMBER(G20),COUNTIFS(Trade_Periods!$B$6:$B$125,Assumptions!$C$6,Trade_Periods!$C$6:$C$125,B20,Trade_Periods!$D$6:$D$125,A20)=1,COUNTIFS(Tariffs!$B$6:$B$45,B20,Tariffs!$C$6:$C$45,A20)=1),"Ready","Missing data") -> Ready | AE20: =IF(D20>0,R20/D20,"n.a.") -> 1 | AF20: =IF(M20>0,IF(D20>0,R20/D20,IF(R20=0,0,"n.a.")),0) -> 0 | AG20: =IF(AND(Assumptions!$F$14="Yes",M20>0),MAX(0,R20-Assumptions!$C$14*D20),0) -> 0
A21: 61103099 | B21: Myanmar | C21: =SUMIFS(Trade_Periods!$F$6:$F$125,Trade_Periods!$B$6:$B$125,"FY2025",Trade_Periods!$C$6:$C$125,B21,Trade_Periods!$D$6:$D$125,A21) -> 508754 | D21: =C21/SUM(C16:C25) -> 0.011316917 | E21: =IF(Assumptions!$C$7="Reported",SUMIFS(Trade_Periods!$E$6:$E$125,Trade_Periods!$B$6:$B$125,Assumptions!$C$6,Trade_Periods!$C$6:$C$125,B21,Trade_Periods!$D$6:$D$125,A21),SUMIFS(Trade_Periods!$L$6:$L$125,Trade_Periods!$B$6:$B$125,Assumptions!$C$6,Trade_Periods!$C$6:$C$125,B21,Trade_Periods!$D$6:$D$125,A21)) -> 1019595 | F21: =IF(Assumptions!$C$7="Reported",SUMIFS(Trade_Periods!$F$6:$F$125,Trade_Periods!$B$6:$B$125,Assumptions!$C$6,Trade_Periods!$C$6:$C$125,B21,Trade_Periods!$D$6:$D$125,A21),SUMIFS(Trade_Periods!$M$6:$M$125,Trade_Periods!$B$6:$B$125,Assumptions!$C$6,Trade_Periods!$C$6:$C$125,B21,Trade_Periods!$D$6:$D$125,A21)) -> 72000 | G21: =IF(F21>0,E21/F21,"n.a.") -> 14.161042 | H21: =IF(Assumptions!$C$8="2025",SUMIFS(Tariffs!$D$6:$D$45,Tariffs!$B$6:$B$45,B21,Tariffs!$C$6:$C$45,A21),IF(Assumptions!$C$8="1 Jan to 14 Jul 2026",SUMIFS(Tariffs!$E$6:$E$45,Tariffs!$B$6:$B$45,B21,Tariffs!$C$6:$C$45,A21),SUMIFS(Tariffs!$F$6:$F$45,Tariffs!$B$6:$B$45,B21,Tariffs!$C$6:$C$45,A21))) -> 0 | I21: =SUMIFS(Tariffs!$G$6:$G$45,Tariffs!$B$6:$B$45,B21,Tariffs!$C$6:$C$45,A21) -> 0.12 | J21: =G21*(1+H21) -> 14.161042 | K21: =G21*(1+I21) -> 15.860367 | L21: =IF(Assumptions!$C$9="Eligible preference",J21,K21) -> 14.161042 | M21: =Assumptions!B29 -> 0 | N21: =Assumptions!C29 -> 0 | O21: =IF(B21="China",-1,M21) -> 0 | P21: =IF(B21="China",D21,IF(M21>0,MAX(0,MIN(Assumptions!$C$10-D21,Assumptions!$C$11,IF(Assumptions!$F$14="Yes",(Assumptions!$C$14-1)*D21,1))/M21),1)) -> 1 | Q21: =$E52*O21 -> 0 | R21: =D21+Q21 -> 0.011316917 | S21: =D21*L21 -> 0.16025934 | T21: =R21*L21+MAX(0,Q21)*L21*N21 -> 0.16025934 | U21: =O21*L21+M21*L21*N21 -> 0 | V21: =D21^2 -> 0.00012807262 | W21: =2*D21*O21 -> 0 | X21: =O21^2 -> 0 | Y21: =IF(Candidate_Gates!N21="Pass",MAX(0,Q21),0) -> 0 | Z21: =D21*J21 -> 0.16025934 | AA21: =O21*J21+M21*J21*N21 -> 0 | AB21: =D21*K21 -> 0.17949046 | AC21: =O21*K21+M21*K21*N21 -> 0 | AD21: =IF(AND(C21>=0,F21>0,E21>0,ISNUMBER(G21),COUNTIFS(Trade_Periods!$B$6:$B$125,Assumptions!$C$6,Trade_Periods!$C$6:$C$125,B21,Trade_Periods!$D$6:$D$125,A21)=1,COUNTIFS(Tariffs!$B$6:$B$45,B21,Tariffs!$C$6:$C$45,A21)=1),"Ready","Missing data") -> Ready | AE21: =IF(D21>0,R21/D21,"n.a.") -> 1 | AF21: =IF(M21>0,IF(D21>0,R21/D21,IF(R21=0,0,"n.a.")),0) -> 0 | AG21: =IF(AND(Assumptions!$F$14="Yes",M21>0),MAX(0,R21-Assumptions!$C$14*D21),0) -> 0
A22: 61103099 | B22: Pakistan | C22: =SUMIFS(Trade_Periods!$F$6:$F$125,Trade_Periods!$B$6:$B$125,"FY2025",Trade_Periods!$C$6:$C$125,B22,Trade_Periods!$D$6:$D$125,A22) -> 427235 | D22: =C22/SUM(C16:C25) -> 0.0095035777 | E22: =IF(Assumptions!$C$7="Reported",SUMIFS(Trade_Periods!$E$6:$E$125,Trade_Periods!$B$6:$B$125,Assumptions!$C$6,Trade_Periods!$C$6:$C$125,B22,Trade_Periods!$D$6:$D$125,A22),SUMIFS(Trade_Periods!$L$6:$L$125,Trade_Periods!$B$6:$B$125,Assumptions!$C$6,Trade_Periods!$C$6:$C$125,B22,Trade_Periods!$D$6:$D$125,A22)) -> 2797761 | F22: =IF(Assumptions!$C$7="Reported",SUMIFS(Trade_Periods!$F$6:$F$125,Trade_Periods!$B$6:$B$125,Assumptions!$C$6,Trade_Periods!$C$6:$C$125,B22,Trade_Periods!$D$6:$D$125,A22),SUMIFS(Trade_Periods!$M$6:$M$125,Trade_Periods!$B$6:$B$125,Assumptions!$C$6,Trade_Periods!$C$6:$C$125,B22,Trade_Periods!$D$6:$D$125,A22)) -> 189105 | G22: =IF(F22>0,E22/F22,"n.a.") -> 14.794749 | H22: =IF(Assumptions!$C$8="2025",SUMIFS(Tariffs!$D$6:$D$45,Tariffs!$B$6:$B$45,B22,Tariffs!$C$6:$C$45,A22),IF(Assumptions!$C$8="1 Jan to 14 Jul 2026",SUMIFS(Tariffs!$E$6:$E$45,Tariffs!$B$6:$B$45,B22,Tariffs!$C$6:$C$45,A22),SUMIFS(Tariffs!$F$6:$F$45,Tariffs!$B$6:$B$45,B22,Tariffs!$C$6:$C$45,A22))) -> 0 | I22: =SUMIFS(Tariffs!$G$6:$G$45,Tariffs!$B$6:$B$45,B22,Tariffs!$C$6:$C$45,A22) -> 0.12 | J22: =G22*(1+H22) -> 14.794749 | K22: =G22*(1+I22) -> 16.570119 | L22: =IF(Assumptions!$C$9="Eligible preference",J22,K22) -> 14.794749 | M22: =Assumptions!B30 -> 0 | N22: =Assumptions!C30 -> 0 | O22: =IF(B22="China",-1,M22) -> 0 | P22: =IF(B22="China",D22,IF(M22>0,MAX(0,MIN(Assumptions!$C$10-D22,Assumptions!$C$11,IF(Assumptions!$F$14="Yes",(Assumptions!$C$14-1)*D22,1))/M22),1)) -> 1 | Q22: =$E52*O22 -> 0 | R22: =D22+Q22 -> 0.0095035777 | S22: =D22*L22 -> 0.14060305 | T22: =R22*L22+MAX(0,Q22)*L22*N22 -> 0.14060305 | U22: =O22*L22+M22*L22*N22 -> 0 | V22: =D22^2 -> 9.031799e-05 | W22: =2*D22*O22 -> 0 | X22: =O22^2 -> 0 | Y22: =IF(Candidate_Gates!N22="Pass",MAX(0,Q22),0) -> 0 | Z22: =D22*J22 -> 0.14060305 | AA22: =O22*J22+M22*J22*N22 -> 0 | AB22: =D22*K22 -> 0.15747541 | AC22: =O22*K22+M22*K22*N22 -> 0 | AD22: =IF(AND(C22>=0,F22>0,E22>0,ISNUMBER(G22),COUNTIFS(Trade_Periods!$B$6:$B$125,Assumptions!$C$6,Trade_Periods!$C$6:$C$125,B22,Trade_Periods!$D$6:$D$125,A22)=1,COUNTIFS(Tariffs!$B$6:$B$45,B22,Tariffs!$C$6:$C$45,A22)=1),"Ready","Missing data") -> Ready | AE22: =IF(D22>0,R22/D22,"n.a.") -> 1 | AF22: =IF(M22>0,IF(D22>0,R22/D22,IF(R22=0,0,"n.a.")),0) -> 0 | AG22: =IF(AND(Assumptions!$F$14="Yes",M22>0),MAX(0,R22-Assumptions!$C$14*D22),0) -> 0
A23: 61103099 | B23: Sri Lanka | C23: =SUMIFS(Trade_Periods!$F$6:$F$125,Trade_Periods!$B$6:$B$125,"FY2025",Trade_Periods!$C$6:$C$125,B23,Trade_Periods!$D$6:$D$125,A23) -> 100905 | D23: =C23/SUM(C16:C25) -> 0.0022445692 | E23: =IF(Assumptions!$C$7="Reported",SUMIFS(Trade_Periods!$E$6:$E$125,Trade_Periods!$B$6:$B$125,Assumptions!$C$6,Trade_Periods!$C$6:$C$125,B23,Trade_Periods!$D$6:$D$125,A23),SUMIFS(Trade_Periods!$L$6:$L$125,Trade_Periods!$B$6:$B$125,Assumptions!$C$6,Trade_Periods!$C$6:$C$125,B23,Trade_Periods!$D$6:$D$125,A23)) -> 732589 | F23: =IF(Assumptions!$C$7="Reported",SUMIFS(Trade_Periods!$F$6:$F$125,Trade_Periods!$B$6:$B$125,Assumptions!$C$6,Trade_Periods!$C$6:$C$125,B23,Trade_Periods!$D$6:$D$125,A23),SUMIFS(Trade_Periods!$M$6:$M$125,Trade_Periods!$B$6:$B$125,Assumptions!$C$6,Trade_Periods!$C$6:$C$125,B23,Trade_Periods!$D$6:$D$125,A23)) -> 34757 | G23: =IF(F23>0,E23/F23,"n.a.") -> 21.077452 | H23: =IF(Assumptions!$C$8="2025",SUMIFS(Tariffs!$D$6:$D$45,Tariffs!$B$6:$B$45,B23,Tariffs!$C$6:$C$45,A23),IF(Assumptions!$C$8="1 Jan to 14 Jul 2026",SUMIFS(Tariffs!$E$6:$E$45,Tariffs!$B$6:$B$45,B23,Tariffs!$C$6:$C$45,A23),SUMIFS(Tariffs!$F$6:$F$45,Tariffs!$B$6:$B$45,B23,Tariffs!$C$6:$C$45,A23))) -> 0 | I23: =SUMIFS(Tariffs!$G$6:$G$45,Tariffs!$B$6:$B$45,B23,Tariffs!$C$6:$C$45,A23) -> 0.12 | J23: =G23*(1+H23) -> 21.077452 | K23: =G23*(1+I23) -> 23.606746 | L23: =IF(Assumptions!$C$9="Eligible preference",J23,K23) -> 21.077452 | M23: =Assumptions!B31 -> 0 | N23: =Assumptions!C31 -> 0 | O23: =IF(B23="China",-1,M23) -> 0 | P23: =IF(B23="China",D23,IF(M23>0,MAX(0,MIN(Assumptions!$C$10-D23,Assumptions!$C$11,IF(Assumptions!$F$14="Yes",(Assumptions!$C$14-1)*D23,1))/M23),1)) -> 1 | Q23: =$E52*O23 -> 0 | R23: =D23+Q23 -> 0.0022445692 | S23: =D23*L23 -> 0.047309799 | T23: =R23*L23+MAX(0,Q23)*L23*N23 -> 0.047309799 | U23: =O23*L23+M23*L23*N23 -> 0 | V23: =D23^2 -> 5.0380908e-06 | W23: =2*D23*O23 -> 0 | X23: =O23^2 -> 0 | Y23: =IF(Candidate_Gates!N23="Pass",MAX(0,Q23),0) -> 0 | Z23: =D23*J23 -> 0.047309799 | AA23: =O23*J23+M23*J23*N23 -> 0 | AB23: =D23*K23 -> 0.052986975 | AC23: =O23*K23+M23*K23*N23 -> 0 | AD23: =IF(AND(C23>=0,F23>0,E23>0,ISNUMBER(G23),COUNTIFS(Trade_Periods!$B$6:$B$125,Assumptions!$C$6,Trade_Periods!$C$6:$C$125,B23,Trade_Periods!$D$6:$D$125,A23)=1,COUNTIFS(Tariffs!$B$6:$B$45,B23,Tariffs!$C$6:$C$45,A23)=1),"Ready","Missing data") -> Ready | AE23: =IF(D23>0,R23/D23,"n.a.") -> 1 | AF23: =IF(M23>0,IF(D23>0,R23/D23,IF(R23=0,0,"n.a.")),0) -> 0 | AG23: =IF(AND(Assumptions!$F$14="Yes",M23>0),MAX(0,R23-Assumptions!$C$14*D23),0) -> 0
