Workbook

Sheet README
A1: NEXT WP004 - Category, Commodity and Tariff Lock
A3: Field | B3: Value
A4: Work package | B4: WP004A category screen + WP004B tariff/origin lock
A5: Status | B5: Closed - evidence reconciled; ready for WP005 monthly HMRC extraction
A6: Closure date | B6: 46260
A7: Evidence archive | B7: NEXT_WP004_API_Evidence_JSON_Closed_2026-08-26.zip
A8: Evidence files | B8: 9 HMRC JSON responses (Q0-Q7) and 11 UKGT JSON responses (T01-T11); all hashes in the query manifests
A9: Basket name | B9: Paired strategic product basket
A10: Core CN8 codes | B10: 61091000, 61103099, 62044300, 62052000
A11: Core code count | B11: =COUNTIF(Commodity_Shortlist!P2:P6,"Core") -> 4
A12: Reserve CN8 | B12: 62063000 - inactive; India-only trigger is representation ratio below 0.80, or a later code-level mass failure
A13: Trade period | B13: WP004 screen: 2025 plus India H1 2025/H1 2026 diagnostic. WP005 contract: monthly 2019-01 through 2026-06; 2019-2025 full years and 2026 YTD separately.
A14: Extraction grain | B14: CN8 x origin x month in WP005; present headline outputs at CN8, HS4 or named probe-pair level without mixing product composition
A15: Origins | B15: Bangladesh, Cambodia, China, India, Morocco, Myanmar, Pakistan, Sri Lanka, Turkey and Vietnam; inclusive World denominator
A16: 2025 four-code basket value | B16: =SUM(Commodity_Shortlist!G2:G5) -> 2554995126
A17: Share of 2025 inclusive HS61+62 imports | B17: =B16/SUM(Category_Screen!D2:D3) -> 0.15793753
A18: India blended representation ratio | B18: =Basket_Representativeness!F4 -> 1.2019665
A19: China synthetic-probe representation ratio | B19: =Basket_Representativeness!I3 -> 1.5745212
A20: Bangladesh cotton-probe representation ratio | B20: =Basket_Representativeness!L2 -> 1.8463992
A21: India cotton-probe representation ratio | B21: =Basket_Representativeness!L4 -> 1.6081226
A22: Reserve trigger result | B22: =Basket_Representativeness!N4 -> No activation
A23: 2025 minimum world net-mass value coverage | B23: =MIN(Mass_Coverage_QC!D2:D5) -> 1
A24: China value in synthetic probe pair | B24: =SUM(Commodity_Shortlist!J3:J4)/SUM(Commodity_Shortlist!J2:J5) -> 0.85610483
A25: China discount vs zero-duty alternative | B25: =Duty_BreakEven!G2 -> 0.10714286
A26: China discount vs Vietnam 1.5% alternative | B26: =Duty_BreakEven!G3 -> 0.09375
A28: Formula / rule | B28: Meaning
A29: Observed import unit value | B29: HMRC statistical value / net mass. For imports, HMRC statistical value is CIF-style; this is not NEXT FOB.
A30: Basket representation ratio | B30: Selected-basket origin share / total HS61+62 origin share. The 0.80 reserve trigger was pre-committed for India only.
A31: Probe-pair representation | B31: Each focal origin is also tested against the pair designed for its strategic question; this avoids misreading the deliberately bimodal four-code basket.
A32: Duty-adjusted border unit value | B32: Observed import unit value x (1 + effective tariff). Do not add international freight again to the HMRC value.
A33: China break-even discount | B33: 1 - (1 + alternative tariff)/(1 + 12%). It is 10.71% versus a zero-duty alternative and 9.38% versus Vietnam at 1.5%.
A34: Mass coverage gate | B34: WP004 verifies the 2025 screen. WP005 must repeat value-with-positive-mass / total-value at CN8 x origin x month; pass threshold = 99.5%.
A35: Natural experiment | B35: India HS62 versus HS61 in 2026 H1 is exploratory only. Observed mass movements run opposite to the simple tariff-response hypothesis; no causal elasticity is estimated.
A36: APPAREL label screen | B36: Keyword-based non-garment flags are a lower-bound diagnostic, not a definitive factory classification; unflagged rows are not proven garment factories.
A37: HMRC residual denominator | B37: Inclusive HS61+62 totals contain £9.94m (0.061%) in EU residual codes 61------/62------. Include in the market denominator; exclude from exact-CN8 product analysis.
A39: Key decision | B39: Locked treatment
A40: Scope | B40: HS61 and HS62 only; HS63 excluded from the core basket because it is heavy, low-value and too heterogeneous for the planned GBP/kg landed-cost comparison.
... A45: Model focus | B45: The central break-even is what China capability/price advantage is required to justify a 12% duty burden relative to origin-compliant lower-duty alternatives.

Sheet Task_Flow
A1: Step | B1: Task | C1: Why it matters | D1: Inputs reviewed | E1: Operation | F1: Workbook output | G1: QC / lock condition
A2: 1 | B2: Confirm project boundary and kill criteria | C2: D010 prevents presenting the basket as NEXT own-brand sales; WP004 must serve landed-cost and break-even analysis. | D2: Scope record D010, L007-L009; WP003 outputs | E2: Restate the outside-in scope and define what would exclude a code. | F2: README; Scope_Lock | G2: No own-brand or procurement-spend claim.
A3: 2 | B3: Freeze the data cut, evidence archive and official source set | C3: Reproducibility requires a dated HMRC/tariff cut. | D3: HMRC Q0-Q8 JSON; UKGT T01-T11 JSON; official tariff/origin documents | E3: Record canonical replay queries, evidence filenames, hashes, row counts, pagination status and closure date. | F3: Source_Register; HMRC_Query_Manifest; UKGT_Query_Manifest; Tariff_Snapshot | G3: Every numerical/rate claim reconciles to an archived response or named official legal source.
A4: 3 | B4: Screen HS61, HS62 and HS63 | C4: Tests materiality and whether £/kg has a coherent interpretation. | D4: 2025 UK imports: value and net mass | E4: Aggregate at HS2 and calculate value/net mass. | F4: Category_Screen | G4: Exclude broad categories that are structurally heterogeneous for the model.
A5: 4 | B5: Rank material HS4 headings | C5: Avoid selecting codes from a minor heading while preserving knit/woven coverage. | D5: 2025 HS4 value and net mass | E5: Rank 6109, 6110, 6203 and 6204; inspect product meaning. | F5: Category_Screen | G5: At least one material knit and one material woven heading.
A6: 5 | B6: Screen exact CN8 codes | C6: Unit values and tariffs are code-specific; residual baskets are avoided where possible. | D6: 2025 CN8 value, unit value and focal-origin shares | E6: Compare product specificity, materiality, fibre and country pattern. | F6: Commodity_Shortlist | G6: Four core codes, two knit/two woven; reserve explicitly inactive.
A7: 6 | B7: Design the paired strategic basket | C7: The basket must answer two commercial questions rather than mimic the whole market. | D7: Commodity shortlist | E7: Pair China synthetic-capability probes with Bangladesh-vs-India cotton probes. | F7: Scope_Lock; Commodity_Shortlist | G7: Each code has an explicit role and caveat.
A8: 7 | B8: Test representativeness before extraction | C8: Prevents a purpose-built basket from being misdescribed as market representative. | D8: 2025 focal-origin values in basket and total HS61+62 | E8: Compute selected-basket share / total HS61+62 share. | F8: Basket_Representativeness | G8: India-only reserve trigger: activate 62063000 if India blended ratio <0.80. Also report pair-specific ratios for all focal origins.
A9: 8 | B9: Verify date-specific tariff paths | C9: A single 'country tariff' hides India graduation/CETA and Vietnam staging. | D9: UKGT current descendants; historical Vietnam and pre-CETA spot checks; DCTS graduation; CETA tariff schedule | E9: Reconcile eight current 10-digit descendants and three historical responses; join policy/legal rules for country applicability. | F9: Tariff_Matrix | G9: All 40 origin-code rows complete; preference marked conditional.
A10: 9 | B10: Read product-specific origin rules | C10: Generic QVC thresholds are insufficient if the annex requires a combined rule. | D10: CETA Chapter 3 and Annex 3A; DCTS rules | E10: Record CTH + Standard QVC and proof-of-origin requirements. | F10: Origin_Rules | G10: India 0% never used as unconditional base case.
A11: 10 | B11: Lock customs-value and duty basis | C11: Prevents double-counting freight in WP008. | D11: HMRC technical specification; HMRC customs valuation guidance | E11: Define HMRC value as CIF-style border value and write formulas. | F11: Duty_BreakEven | G11: No second addition of international freight to HMRC unit value.
A12: 11 | B12: Audit the WP003 APPAREL proxy | C12: China's APPAREL site count contains many non-garment factories and can mislead category capability claims. | D12: WP003 site master; keyword diagnostic | E12: Report lower-bound non-garment flags by country. | F12: APPAREL_Scope_Check | G12: No direct use of APPAREL site count as HS61/62 capacity.
A13: 12 | B13: Run mass-coverage QC | C13: A £/kg series can be biased if value exists without mass. | D13: 2025 HMRC Q2/Q3 screen | E13: Calculate 2025 value coverage with positive net mass by core CN8; define the full country-month re-test for WP005. | F13: Mass_Coverage_QC | G13: 2025 screen passes; WP005 must repeat at CN8 x origin x month with >=99.5% threshold.
... A16: 15 | B16: Publication QA and closure | C16: Makes the workbook interview-defensible and handoff-ready. | D16: All sheets plus 20 archived JSON responses | E16: Formula scan, source/query-ID audit, evidence reconciliation, formatting review and attribution scan. | F16: QC_Checks | G16: All checks pass; Arial, neutral formatting and stable source/query identifiers applied.

Sheet Source_Register
A1: Source_ID | B1: Source_Type | C1: Official document / dataset | D1: Publisher | E1: Publication / cut date | F1: Reporting period | G1: Suggested local filename | H1: Official URL | I1: Used for | J1: Download / capture instruction | K1: Review status | L1: Known limitation
A2: EXT_HMRC_OTS | B2: Trade data | C2: UK Trade Info API - Overseas Trade Statistics | D2: HM Revenue & Customs | E2: 46260 | F2: WP004: 2025 screen and India H1 2025/H1 2026; WP005 monthly pull not yet executed | G2: NEXT_WP004_API_Evidence_JSON_Closed_2026-08-26.zip | H2: https://www.uktradeinfo.com/api-documentation/ | I2: Category screen, code selection, focal-origin shares, representativeness, 2025 mass coverage and India H1 diagnostic | J2: Retain Q0-Q8 JSON with the manifest and SHA-256 hashes. No static PDF is required for API output. | K2: Reconciled | L2: Live data can be revised. Q3/Q4 contain true CN8 only; Q7 supplies the inclusive market denominator.
A3: EXT_HMRC_SPEC | B3: Methodology | C3: Bulk data set export and import technical specifications | D3: HM Revenue & Customs | E3: 46258 | F3: Current specification | G3: HMRC_OTS_Bulk_Data_Technical_Specification_2026.html | H3: https://www.uktradeinfo.com/trade-data/latest-bulk-data-sets/bulk-data-set-export-and-import-technical-specifications/ | I3: Defines statistical value and net mass | J3: Use browser Print > Save as PDF or save the page as HTML. | K3: Reviewed | L3: Web page may be updated; retain a dated local snapshot.
A4: EXT_HMRC_JUN26 | B4: Release notice | C4: UK overseas trade in goods statistics: June 2026 | D4: HM Revenue & Customs | E4: 46247 | F4: Through June 2026 | G4: HMRC_UK_OTS_June_2026_Release.html | H4: https://www.uktradeinfo.com/trade-data/overseas/2026/uk-overseas-trade-in-goods-statistics-june-2026/ | I4: Confirms latest monthly data cut | J4: Save page as HTML/PDF; the detailed WP005 pull still comes from the API. | K4: Reviewed | L4: Release page is summary-level, not the CN8 dataset.
A5: EXT_UKGT | B5: Tariff data | C5: Tariffs to trade with the UK / UK Integrated Online Tariff | D5: UK Government | E5: 46259 | F5: As-of 2025-12-31, 2026-07-14 and 2026-08-24 | G5: NEXT_WP004_API_Evidence_JSON_Closed_2026-08-26.zip | H5: https://www.gov.uk/guidance/tariffs-on-goods-imported-into-the-uk | I5: MFN, DCTS and direct country-preference measures for all core/reserve 10-digit descendants plus historical spot checks | J5: Retain T01-T11 JSON with the manifest, readable snapshot and SHA-256 hashes. | K5: Reconciled | L5: A tariff measure is not proof that a particular supplier satisfies origin requirements.
A6: EXT_DCTS_2026 | B6: Preference guidance | C6: Preference tiers under the Developing Countries Trading Scheme | D6: UK Government | E6: 46258 | F6: 2026 | G6: DCTS_Preference_Tiers_2026.html | H6: https://www.gov.uk/guidance/preference-tiers-under-the-developing-countries-trading-scheme | I6: Country tier mapping and general preference coverage | J6: Save page as HTML/PDF. | K6: Reviewed | L6: Tier-wide percentages do not prove a selected code's exact rate.
A7: EXT_DCTS_GRAD | B7: Graduation notice | C7: DCTS goods graduation from 1 January 2026 to 31 December 2028 | D7: UK Government | E7: 46258 | F7: 2026-2028 | G7: DCTS_Goods_Graduation_2026-2028.html | H7: https://www.gov.uk/government/publications/developing-countries-trading-scheme-dcts-goods-graduation-notice/developing-countries-trading-scheme-dcts-goods-graduation-from-1-january-2026-to-31-december-2028 | I7: India chapter 62/63 graduation | J7: Save page as HTML/PDF. | K7: Reviewed | L7: Graduation identifies chapters, not supplier origin compliance.
A8: EXT_DCTS_ROO | B8: Rules of origin guidance | C8: Improved DCTS rules of origin in effect from 1 January 2026 | D8: UK Government | E8: 46041 | F8: From 2026-01-01 | G8: DCTS_Improved_Rules_of_Origin_2026.html | H8: https://www.gov.uk/government/publications/rules-of-origin-changes-under-the-developing-countries-trading-scheme-are-now-in-effect/update-improved-rules-of-origin-under-the-developing-countries-trading-dcts-are-now-in-effect | I8: Enhanced/Comprehensive garment-rule change | J8: Save page as HTML/PDF. | K8: Reviewed | L8: Eligibility still requires product-specific processing and proof.
A9: EXT_CETA_CH2 | B9: Trade agreement | C9: UK-India CETA Chapter 2: Trade in Goods | D9: UK Government | E9: 46218 | F9: Effective 2026-07-15 | G9: UK_India_CETA_Chapter_2_Trade_in_Goods.pdf | H9: https://assets.publishing.service.gov.uk/media/687e518d9914d1f63267c605/uk_india_ceta_chapter_2_trade_in_goods.pdf | I9: Entry into force and tariff-treatment framework | J9: Download the PDF directly. | K9: Reviewed | L9: Framework chapter; code treatment is in Annex 2A / Appendix 2A-b.
A10: EXT_CETA_ANNEX2A | B10: Tariff schedule rules | C10: UK-India CETA Annex 2A - Schedules of Tariff Commitments for Goods | D10: UK Government | E10: 46218 | F10: Effective 2026-07-15 | G10: UK_India_CETA_Annex_2A_Tariff_Staging_Rules.pdf | H10: https://assets.publishing.service.gov.uk/media/687f692d92957f2ec567c6ad/uk_india_ceta_annex2a_schedules_tariff_commitments_for_goods.pdf | I10: Defines staging category A as elimination at entry into force | J10: Download the PDF directly. | K10: Reviewed | L10: Must be read with the UK schedule and applies only to originating goods.
A11: EXT_CETA_TARIFF | B11: Tariff schedule | C11: UK-India CETA Appendix 2A-b - UK tariff commitments | D11: UK Government | E11: 46218 | F11: Effective 2026-07-15 | G11: UK_India_CETA_Appendix_2A-b_UK_Tariff_Commitments.pdf | H11: https://assets.publishing.service.gov.uk/media/687f69a177a3acd9f4d0e1cc/uk_india_ceta_annex2a_b_schedules_tariff_commitments_of_united_kingdom.pdf | I11: Confirms Chapters 61/62 staging category A | J11: Download the PDF directly. | K11: Reviewed | L11: Must be read with Annex 2A; applies only to originating goods.
A12: EXT_CETA_CH3 | B12: Rules of origin | C12: UK-India CETA Chapter 3: Rules of Origin | D12: UK Government | E12: 46218 | F12: Effective 2026-07-15 | G12: UK_India_CETA_Chapter_3_Rules_of_Origin.pdf | H12: https://assets.publishing.service.gov.uk/media/687e58acae8555bab409a070/uk_india_ceta_chapter_3_rules_of_origin.pdf | I12: Proof-of-origin options and claim procedures | J12: Download the PDF directly. | K12: Reviewed | L12: Supplier-level evidence is unavailable publicly.
A13: EXT_CETA_PSR | B13: Product-specific rules | C13: UK-India CETA Annex 3A: Product Specific Rules of Origin | D13: UK Government | E13: 46218 | F13: HS 2022 | G13: UK_India_CETA_Annex_3A_Product_Specific_Rules_of_Origin.pdf | H13: https://assets.publishing.service.gov.uk/media/687e5e378adf4250705c96db/uk_india_ceta_annex3a_product_specific_rules_of_origin.pdf | I13: CTH + Standard QVC for Chapters 61/62 | J13: Download the PDF directly. | K13: Reviewed | L13: Rules are legal eligibility tests, not evidence that any named supplier passes.
... A18: EXT_UN_LDC_BGD | B18: Policy Status | C18: Bangladesh graduation status | D18: United Nations LDC Portal / UN-OHRLLS | E18: 46260 | F18: Scheduled graduation 2026-11-24 | G18: UN_Bangladesh_LDC_Graduation_Status_2026.html | H18: https://www.un.org/ldcportal/content/bangladesh-graduation-status | I18: Bangladesh LDC graduation date and future DCTS monitoring trigger | J18: Save the official page as HTML or PDF with the capture date. | K18: Reviewed | L18: Confirms the UN graduation date only; the exact UK post-transition tier and effective rate require a later UK notice.

Sheet Scope_Lock
A1: Decision_ID | B1: Decision area | C1: Locked decision | D1: Rationale | E1: Alternative rejected | F1: Downstream consequence | G1: Revisit trigger | H1: Status
A2: D013 | B2: Product basket | C2: Core CN8: 61091000, 61103099, 62044300 and 62052000. Reserve 62063000 remains inactive. | D2: Two knit/two woven codes span cotton and man-made fibres, China capability/duty exposure and Bangladesh-vs-India competition. India blended ratio is 1.202; focal probe-pair ratios are 1.575 for China, 1.846 for Bangladesh and 1.608 for India. | E2: Broad HS61/62 basket; HS63; five-code scope from the outset | F2: WP005 extracts exactly four core CN8 codes; results are product-specific, not a total-apparel estimate. | G2: Activate reserve only if India's representation ratio is below 0.80 or a core code fails mass coverage. | H2: Confirmed
A3: D014 | B3: Duty/value basis | C3: Use HMRC CIF-style statistical value as the observed border-value proxy; apply tariff once; do not add international freight again. | D3: HMRC technical specification includes costs to arrival at the UK border for imports. | E3: Treat HMRC value as FOB and then add freight | F3: WP008 starts from border unit value; separate operational adjustments must be labelled and must not duplicate freight. | G3: A supplier-specific FOB dataset replaces HMRC market data. | H3: Confirmed
A4: D015 | B4: Trade extraction contract | C4: Monthly 2019-01 to 2026-06 at CN8 x origin x month for 10 named origins plus World; 2019-2025 full years and 2026 YTD separately. | D4: Preserves seasonality, pre-COVID context and the latest complete HMRC release while keeping 2026 partial-year treatment explicit. | E4: Annual-only; stop at 2025; include every country in the raw analytical table | F4: WP005 has a fixed grain, key, fields and coverage gate. | G4: HMRC revises June 2026 or a later release is intentionally adopted before extraction begins. | H4: Confirmed
A5: D016 | B5: Preference treatment | C5: Zero preferential rates are conditional on origin eligibility and valid proof; India CETA Chapters 61/62 require CTH and Standard QVC. | D5: CETA Annex 3A imposes a combined rule; Chapter 3 requires an origin declaration, certificate or importer knowledge for UK claims. | E5: Use statutory zero rate as an automatic base case | F5: WP008 must include eligible-preference and non-qualifying tariff scenarios. | G5: Supplier bill-of-materials and origin documentation become available. | H5: Confirmed
A6: D017 | B6: WP004 evidence closure | C6: Lock WP004 to HMRC Q0-Q8 and UKGT T01-T11 archived responses. Use inclusive HS2 totals for the market denominator and true-CN8 results for exact product analysis. | D6: Separates small residual EU commodity totals from exact-CN8 analysis and preserves a reproducible point-in-time tariff/data cut. | E6: Re-query live APIs on every open; silently overwrite the existing screen | F6: WP005 begins from a formally versioned scope and must produce its own monthly evidence archive. | G6: An intentional source refresh is approved and archived under a new decision date/version. | H6: Confirmed

Sheet Category_Screen
A1: Level | B1: Code | C1: Description | D1: 2025 UK import value GBP | E1: 2025 net mass kg | F1: Observed unit value GBP/kg | G1: Selection note | H1: Decision | I1: Source_ID | J1: Evidence_Query_ID
A2: HS2 | B2: 61 | C2: Articles of apparel, knitted or crocheted | D2: 9076640036 | E2: 610892405 | F2: =IFERROR(D2/E2,"") -> 14.858001 | G2: Largest of the three screened categories by value; coherent apparel scope. | H2: Retain for CN8 screening | I2: EXT_HMRC_OTS | J2: Q7
A3: HS2 | B3: 62 | C3: Articles of apparel, not knitted or crocheted | D3: 7100611784 | E3: 323849334 | F3: =IFERROR(D3/E3,"") -> 21.925664 | G3: Higher unit value and contains the 2026 India graduation event. | H3: Retain for CN8 screening | I3: EXT_HMRC_OTS | J3: Q7
A4: HS2 | B4: 63 | C4: Other made-up textiles, worn clothing and rags | D4: 2073800925 | E4: 446237905 | F4: =IFERROR(D4/E4,"") -> 4.6472989 | G4: Low GBP/kg and heterogeneous heavy products make a landed-cost basket misleading. | H4: Exclude from core | I4: EXT_HMRC_OTS | J4: Q6
A5: HS4 | B5: 6109 | C5: T-shirts, singlets and other vests, knitted or crocheted | D5: 1766783189 | E5: 115336777 | F5: =IFERROR(D5/E5,"") -> 15.318472 | G5: Large replenishment heading; 61091000 represents about 69% of heading value. | H5: Candidate heading | I5: EXT_HMRC_OTS | J5: Q3
A6: HS4 | B6: 6110 | C6: Jerseys, pullovers, cardigans and similar, knitted or crocheted | D6: 2416205305 | E6: 148636475 | F6: =IFERROR(D6/E6,"") -> 16.255803 | G6: Largest screened knit heading; supports the man-made-fibre China probe. | H6: Candidate heading | I6: EXT_HMRC_OTS | J6: Q3
A7: HS4 | B7: 6203 | C7: Men's/boys' woven suits, jackets and trousers | D7: 1357918091 | E7: 71787577 | F7: =IFERROR(D7/E7,"") -> 18.915781 | G7: Material woven heading, but more heterogeneous at heading level. | H7: Screened; not core | I7: EXT_HMRC_OTS | J7: Q3
A8: HS4 | B8: 6204 | C8: Women's/girls' woven outerwear and garments | D8: 2200050494 | E8: 97035965 | F8: =IFERROR(D8/E8,"") -> 22.672527 | G8: Largest screened woven heading; 62044300 provides a narrow synthetic dress line. | H8: Candidate heading | I8: EXT_HMRC_OTS | J8: Q3

Sheet Commodity_Shortlist
A1: CN8 code | B1: HS4 | C1: Product description | D1: Construction | E1: Fibre | F1: Basket role | G1: 2025 world value GBP | H1: 2025 world net mass kg | I1: World unit value GBP/kg | J1: China value GBP | K1: China share | L1: Bangladesh value GBP | M1: Bangladesh share | N1: India value GBP | O1: India share | P1: Inclusion status | Q1: Decision rationale | R1: Caveat | S1: Source_ID | T1: Evidence_Query_ID
A2: 61091000 | B2: 6109 | C2: T-shirts, singlets and other vests of cotton, knitted or crocheted | D2: Knitted | E2: Cotton | F2: Bangladesh-vs-India zero-duty contest | G2: 1223299784 | H2: 90508362 | I2: =IFERROR(G2/H2,"") -> 13.515876 | J2: 44790747 | K2: =IFERROR(J2/G2,"") -> 0.036614694 | L2: 455361217 | M2: =IFERROR(L2/G2,"") -> 0.37224009 | N2: 100902224 | O2: =IFERROR(N2/G2,"") -> 0.082483644 | P2: Core | Q2: High-volume, narrow cotton replenishment line with material Bangladesh and India presence. | R2: Whole-market unit value, not NEXT FOB. | S2: EXT_HMRC_OTS | T2: Q2; Q3
A3: 61103099 | B3: 6110 | C3: Women's/girls' jerseys, pullovers, cardigans and similar of man-made fibres, residual line | D3: Knitted | E3: Man-made fibres | F3: China capability / duty exposure probe | G3: 719371758 | H3: 51671885 | I3: =IFERROR(G3/H3,"") -> 13.921918 | J3: 235660674 | K3: =IFERROR(J3/G3,"") -> 0.32759234 | L3: 164836619 | M3: =IFERROR(L3/G3,"") -> 0.22913969 | N3: 2259458 | O3: =IFERROR(N3/G3,"") -> 0.0031408767 | P3: Core | Q3: China has a large share; tests whether 12% duty is justified by capability. | R3: Least homogeneous core code; expect broader product-mix dispersion. | S3: EXT_HMRC_OTS | T3: Q2; Q3
A4: 62044300 | B4: 6204 | C4: Women's/girls' dresses of synthetic fibres, not knitted or crocheted | D4: Woven | E4: Synthetic fibres | F4: China capability / duty exposure probe | G4: 349077816 | H4: 10212693 | I4: =IFERROR(G4/H4,"") -> 34.18078 | J4: 102164136 | K4: =IFERROR(J4/G4,"") -> 0.29266866 | L4: 12960863 | M4: =IFERROR(L4/G4,"") -> 0.037128865 | N4: 35008468 | O4: =IFERROR(N4/G4,"") -> 0.10028844 | P4: Core | Q4: Narrow high-unit-value fashion line with strong China exposure and India presence. | R4: Fashion and quality mix can move GBP/kg. | S4: EXT_HMRC_OTS | T4: Q2; Q3
A5: 62052000 | B5: 6205 | C5: Men's/boys' shirts of cotton, not knitted or crocheted | D5: Woven | E5: Cotton | F5: Bangladesh-vs-India zero-duty contest | G5: 263245768 | H5: 10289911 | I5: =IFERROR(G5/H5,"") -> 25.5829 | J5: 11991268 | K5: =IFERROR(J5/G5,"") -> 0.045551608 | L5: 81131664 | M5: =IFERROR(L5/G5,"") -> 0.30819741 | N5: 30022861 | O5: =IFERROR(N5/G5,"") -> 0.11404879 | P5: Core | Q5: Cotton woven line with meaningful Bangladesh and India shares and low China exposure. | R5: India remains modest in absolute UK value. | S5: EXT_HMRC_OTS | T5: Q2; Q3
A6: 62063000 | B6: 6206 | C6: Women's/girls' blouses and shirts of cotton, not knitted or crocheted | D6: Woven | E6: Cotton | F6: Reserve India representation code | P6: Reserve - inactive | Q6: Activate only if India's blended representation ratio <0.80 or a later core code fails mass coverage. | R6: Adding it now would multiply WP005-WP008 work without changing the current decision. | S6: EXT_HMRC_OTS | T6: Not extracted - inactive reserve

Sheet Basket_Representativeness
A1: Origin | B1: 2025 total HS61+62 value GBP | C1: Overall HS61+62 share | D1: Core-basket value GBP | E1: Core-basket share | F1: Blended representation ratio | G1: China-probe pair value GBP | H1: China-probe pair share | I1: China-probe representation ratio | J1: Bangladesh-India pair value GBP | K1: Bangladesh-India pair share | L1: Bangladesh-India representation ratio | M1: India reserve threshold | N1: Reserve result | O1: Interpretation | P1: Source_ID | Q1: Evidence_Query_ID
A2: Bangladesh | B2: 3162021909 | C2: =B2/$B$5 -> 0.19546101 | D2: 714290363 | E2: =D2/$D$5 -> 0.27956623 | F2: =E2/C2 -> 1.4302916 | G2: 177797482 | H2: =G2/$G$5 -> 0.16640699 | I2: =H2/C2 -> 0.85135648 | J2: 536492881 | K2: =J2/$J$5 -> 0.36089905 | L2: =K2/C2 -> 1.8463992 | N2: Not applicable - pair diagnostic | O2: Cotton probe intentionally over-represents Bangladesh (pair ratio 1.846). | P2: EXT_HMRC_OTS | Q2: Q2; Q3; Q4; Q7
A3: China | B3: 3248581237 | C3: =B3/$B$5 -> 0.20081169 | D3: 394606825 | E3: =D3/$D$5 -> 0.15444524 | F3: =E3/C3 -> 0.76910482 | G3: 337824810 | H3: =G3/$G$5 -> 0.31618227 | I3: =H3/C3 -> 1.5745212 | J3: 56782015 | K3: =J3/$J$5 -> 0.038197292 | L3: =K3/C3 -> 0.19021449 | N3: Not applicable - pair diagnostic | O3: Blended ratio is 0.769, but the designated synthetic probe over-represents China (1.575); the reserve trigger is India-only. | P3: EXT_HMRC_OTS | Q3: Q2; Q3; Q4; Q7
A4: India | B4: 885992895 | C4: =B4/$B$5 -> 0.054767825 | D4: 168193011 | E4: =D4/$D$5 -> 0.065829093 | F4: =E4/C4 -> 1.2019665 | G4: 37267926 | H4: =G4/$G$5 -> 0.034880379 | I4: =H4/C4 -> 0.6368772 | J4: 130925085 | K4: =J4/$J$5 -> 0.088073376 | L4: =K4/C4 -> 1.6081226 | M4: 0.8 | N4: =IF(F4<M4,"Activate reserve","No activation") -> No activation | O4: India passes the blended 0.80 trigger (1.202) and is over-represented in its designated cotton pair (1.608). | P4: EXT_HMRC_OTS | Q4: Q2; Q3; Q4; Q7
A5: World | B5: 16177251820 | C5: 1 | D5: 2554995126 | E5: 1 | G5: 1068449574 | H5: 1 | J5: 1486545552 | K5: 1 | N5: Denominator | O5: Inclusive world denominator; never add this row to origin values. | P5: EXT_HMRC_OTS | Q5: Q3; Q7

Sheet Tariff_Matrix
A1: Origin | B1: CN8 code | C1: HS chapter | D1: 2025 regime | E1: 2025 rate | F1: 2026-01-01 to 2026-07-14 regime | G1: Pre-CETA 2026 rate | H1: From 2026-07-15 regime | I1: Current rate | J1: Preference conditional? | K1: Origin / policy note | L1: Future regime change | M1: Source_IDs | N1: Evidence_Query_ID
A2: Bangladesh | B2: 61091000 | C2: 61 | D2: DCTS Comprehensive | E2: 0 | F2: DCTS Comprehensive | G2: 0 | H2: DCTS Comprehensive | I2: 0 | J2: Yes | K2: Preference requires the applicable origin rule and proof. | L2: UN LDC graduation scheduled for 2026-11-24. DCTS Comprehensive Preferences continue during a three-year transition; UK guidance states that a 2026 graduate remains Comprehensive until 2029. Treat 2029 as a mandatory rate/tier recheck, not a confirmed tariff cliff. Apparel origin rules are currently intended to remain unchanged on transition to Enhanced Preferences. | M2: EXT_UKGT; EXT_DCTS_2026; EXT_DCTS_ROO; EXT_UN_LDC_BGD | N2: T01; T02
A3: Bangladesh | B3: 61103099 | C3: 61 | D3: DCTS Comprehensive | E3: 0 | F3: DCTS Comprehensive | G3: 0 | H3: DCTS Comprehensive | I3: 0 | J3: Yes | K3: Preference requires the applicable origin rule and proof. | L3: UN LDC graduation scheduled for 2026-11-24. DCTS Comprehensive Preferences continue during a three-year transition; UK guidance states that a 2026 graduate remains Comprehensive until 2029. Treat 2029 as a mandatory rate/tier recheck, not a confirmed tariff cliff. Apparel origin rules are currently intended to remain unchanged on transition to Enhanced Preferences. | M3: EXT_UKGT; EXT_DCTS_2026; EXT_DCTS_ROO; EXT_UN_LDC_BGD | N3: T03
A4: Bangladesh | B4: 62044300 | C4: 62 | D4: DCTS Comprehensive | E4: 0 | F4: DCTS Comprehensive | G4: 0 | H4: DCTS Comprehensive | I4: 0 | J4: Yes | K4: Preference requires the applicable origin rule and proof. | L4: UN LDC graduation scheduled for 2026-11-24. DCTS Comprehensive Preferences continue during a three-year transition; UK guidance states that a 2026 graduate remains Comprehensive until 2029. Treat 2029 as a mandatory rate/tier recheck, not a confirmed tariff cliff. Apparel origin rules are currently intended to remain unchanged on transition to Enhanced Preferences. | M4: EXT_UKGT; EXT_DCTS_2026; EXT_DCTS_ROO; EXT_UN_LDC_BGD | N4: T04; T09; T11
A5: Bangladesh | B5: 62052000 | C5: 62 | D5: DCTS Comprehensive | E5: 0 | F5: DCTS Comprehensive | G5: 0 | H5: DCTS Comprehensive | I5: 0 | J5: Yes | K5: Preference requires the applicable origin rule and proof. | L5: UN LDC graduation scheduled for 2026-11-24. DCTS Comprehensive Preferences continue during a three-year transition; UK guidance states that a 2026 graduate remains Comprehensive until 2029. Treat 2029 as a mandatory rate/tier recheck, not a confirmed tariff cliff. Apparel origin rules are currently intended to remain unchanged on transition to Enhanced Preferences. | M5: EXT_UKGT; EXT_DCTS_2026; EXT_DCTS_ROO; EXT_UN_LDC_BGD | N5: T05; T06
A6: Cambodia | B6: 61091000 | C6: 61 | D6: DCTS Comprehensive | E6: 0 | F6: DCTS Comprehensive | G6: 0 | H6: DCTS Comprehensive | I6: 0 | J6: Yes | K6: Preference requires the applicable origin rule and proof. | M6: EXT_UKGT; EXT_DCTS_2026 | N6: T01; T02
A7: Cambodia | B7: 61103099 | C7: 61 | D7: DCTS Comprehensive | E7: 0 | F7: DCTS Comprehensive | G7: 0 | H7: DCTS Comprehensive | I7: 0 | J7: Yes | K7: Preference requires the applicable origin rule and proof. | M7: EXT_UKGT; EXT_DCTS_2026 | N7: T03
A8: Cambodia | B8: 62044300 | C8: 62 | D8: DCTS Comprehensive | E8: 0 | F8: DCTS Comprehensive | G8: 0 | H8: DCTS Comprehensive | I8: 0 | J8: Yes | K8: Preference requires the applicable origin rule and proof. | M8: EXT_UKGT; EXT_DCTS_2026 | N8: T04; T09; T11
A9: Cambodia | B9: 62052000 | C9: 62 | D9: DCTS Comprehensive | E9: 0 | F9: DCTS Comprehensive | G9: 0 | H9: DCTS Comprehensive | I9: 0 | J9: Yes | K9: Preference requires the applicable origin rule and proof. | M9: EXT_UKGT; EXT_DCTS_2026 | N9: T05; T06
A10: China | B10: 61091000 | C10: 61 | D10: UKGT / MFN | E10: 0.12 | F10: UKGT / MFN | G10: 0.12 | H10: UKGT / MFN | I10: 0.12 | J10: No | K10: No preferential arrangement assumed; UKGT/MFN rate. | M10: EXT_UKGT | N10: T01; T02
A11: China | B11: 61103099 | C11: 61 | D11: UKGT / MFN | E11: 0.12 | F11: UKGT / MFN | G11: 0.12 | H11: UKGT / MFN | I11: 0.12 | J11: No | K11: No preferential arrangement assumed; UKGT/MFN rate. | M11: EXT_UKGT | N11: T03
A12: China | B12: 62044300 | C12: 62 | D12: UKGT / MFN | E12: 0.12 | F12: UKGT / MFN | G12: 0.12 | H12: UKGT / MFN | I12: 0.12 | J12: No | K12: No preferential arrangement assumed; UKGT/MFN rate. | M12: EXT_UKGT | N12: T04; T09; T11
A13: China | B13: 62052000 | C13: 62 | D13: UKGT / MFN | E13: 0.12 | F13: UKGT / MFN | G13: 0.12 | H13: UKGT / MFN | I13: 0.12 | J13: No | K13: No preferential arrangement assumed; UKGT/MFN rate. | M13: EXT_UKGT | N13: T05; T06
A14: India | B14: 61091000 | C14: 61 | D14: DCTS Standard | E14: 0.096 | F14: DCTS Standard | G14: 0.096 | H14: UK-India CETA | I14: 0 | J14: Yes | K14: Chapter 61 remained on DCTS Standard until CETA entry into force; CETA zero is origin-conditional. | M14: EXT_UKGT; EXT_DCTS_GRAD; EXT_CETA_ANNEX2A; EXT_CETA_TARIFF; EXT_CETA_PSR | N14: T01; T02
A15: India | B15: 61103099 | C15: 61 | D15: DCTS Standard | E15: 0.096 | F15: DCTS Standard | G15: 0.096 | H15: UK-India CETA | I15: 0 | J15: Yes | K15: Chapter 61 remained on DCTS Standard until CETA entry into force; CETA zero is origin-conditional. | M15: EXT_UKGT; EXT_DCTS_GRAD; EXT_CETA_ANNEX2A; EXT_CETA_TARIFF; EXT_CETA_PSR | N15: T03
A16: India | B16: 62044300 | C16: 62 | D16: DCTS Standard | E16: 0.096 | F16: UKGT after DCTS graduation | G16: 0.12 | H16: UK-India CETA | I16: 0 | J16: Yes | K16: Chapter 62 graduated from DCTS on 2026-01-01; CETA zero from 2026-07-15 for originating goods. | M16: EXT_UKGT; EXT_DCTS_GRAD; EXT_CETA_ANNEX2A; EXT_CETA_TARIFF; EXT_CETA_PSR | N16: T04; T09; T11
A17: India | B17: 62052000 | C17: 62 | D17: DCTS Standard | E17: 0.096 | F17: UKGT after DCTS graduation | G17: 0.12 | H17: UK-India CETA | I17: 0 | J17: Yes | K17: Chapter 62 graduated from DCTS on 2026-01-01; CETA zero from 2026-07-15 for originating goods. | M17: EXT_UKGT; EXT_DCTS_GRAD; EXT_CETA_ANNEX2A; EXT_CETA_TARIFF; EXT_CETA_PSR | N17: T05; T06
... A41: Vietnam | B41: 62052000 | C41: 62 | D41: UKVFTA / CPTPP | E41: 0 | F41: UKVFTA / CPTPP | G41: 0 | H41: UKVFTA / CPTPP | I41: 0 | J41: Yes | K41: Preference requires the applicable origin rule and proof. | M41: EXT_UKGT; EXT_UK_VIETNAM | N41: T05; T06

Sheet Origin_Rules
A1: Origin / group | B1: Regime | C1: Selected-code tariff treatment | D1: Product-specific origin rule / claim basis | E1: Required proof or evidence | F1: WP008 treatment | G1: Gate status | H1: Source_IDs | I1: Caveat | J1: UKGT_Query_IDs
A2: China | B2: UKGT / MFN | C2: 12% on all four core codes | D2: No preference claimed | E2: Customs classification and origin declaration under normal import rules | F2: Use 12% base case | G2: Locked | H2: EXT_UKGT | I2: Does not include VAT or product-specific trade remedies. | J2: T01-T08 current descendants
A3: India | B3: UK-India CETA | C3: 0% from 2026-07-15 for originating Chapters 61/62 goods | D3: CTH AND Standard QVC: 40% ex-works build-down, 45% FOB build-down, or 35% build-up | E3: Exporter/producer origin declaration; certificate of origin; or importer knowledge with supporting records | F3: Model eligible 0% and non-qualifying 12% scenarios | G3: Conditional | H3: EXT_CETA_CH3; EXT_CETA_PSR; EXT_CETA_ANNEX2A; EXT_CETA_TARIFF | I3: DCTS declarations do not automatically establish CETA origin. | J3: T01-T08; T10; T11 plus DCTS/CETA legal sources
A4: Bangladesh / Cambodia / Myanmar | B4: DCTS Comprehensive | C4: 0% selected codes if DCTS origin rules are met | D4: Applicable DCTS garment product-specific rule | E4: Valid DCTS proof of origin and processing evidence | F4: 0% only after origin and D008 gates | G4: Conditional | H4: EXT_DCTS_2026; EXT_DCTS_ROO | I4: Myanmar requires a separate mandatory responsible-sourcing decision. | J4: T01-T08 current descendants
A5: Pakistan / Sri Lanka | B5: DCTS Enhanced | C5: 0% selected codes verified; garment rules liberalised from 2026-01-01 | D5: Enhanced garment rules aligned with Comprehensive garment PSRs for Chapters 61/62 | E5: Valid DCTS proof of origin and processing evidence | F5: 0% only after origin gate | G5: Conditional | H5: EXT_DCTS_2026; EXT_DCTS_ROO | I5: Tier-wide 92% duty-free coverage is not itself evidence for a code; selected codes were checked. | J5: T01-T08 current descendants
A6: Turkey | B6: UK-Turkey FTA | C6: 0% selected codes if origin conditions are met | D6: FTA product-specific origin rule | E6: Valid preferential-origin evidence | F6: 0% eligible scenario; retain 12% fallback | G6: Conditional | H6: EXT_UKGT; EXT_UK_TURKEY | I6: Supplier-specific origin compliance is not public. | J6: T01-T08 current descendants
A7: Morocco | B7: UK-Morocco Association Agreement | C7: 0% selected codes if origin conditions are met | D7: Agreement product-specific origin rule | E7: Valid preferential-origin evidence | F7: 0% eligible scenario; retain 12% fallback | G7: Conditional | H7: EXT_UKGT; EXT_UK_MOROCCO | I7: Supplier-specific origin compliance is not public. | J7: T01-T08 current descendants
A8: Vietnam | B8: UKVFTA / CPTPP | C8: 0% on three core codes; 62044300 staged at 3% in 2025 and 1.5% in 2026 | D8: Agreement product-specific origin rule | E8: Valid preferential-origin evidence | F8: Use code-specific eligible rate and 12% fallback | G8: Conditional | H8: EXT_UKGT; EXT_UK_VIETNAM | I8: Do not simplify Vietnam to 0% for every selected code. | J8: T01-T09; T11

Sheet Duty_BreakEven
A1: Alternative scenario | B1: Alternative pre-duty border index | C1: China tariff | D1: Alternative tariff | E1: Alternative duty-paid index | F1: China maximum pre-duty index at parity | G1: Required China discount | H1: Formula / use | I1: Interpretation | J1: Source_ID | K1: Evidence_Query_ID
A2: Origin-compliant zero-duty alternative | B2: 100 | C2: 0.12 | D2: 0 | E2: =B2*(1+D2) -> 100 | F2: =E2/(1+C2) -> 89.285714 | G2: =1-F2/B2 -> 0.10714286 | H2: E=B*(1+D); F=E/(1+C); G=1-F/B | I2: China must be 10.71% cheaper before duty to match a zero-duty alternative. | J2: EXT_UKGT | K2: T01-T08
A3: Vietnam 62044300 at 1.5% | B3: 100 | C3: 0.12 | D3: 0.015 | E3: =B3*(1+D3) -> 101.5 | F3: =E3/(1+C3) -> 90.625 | G3: =1-F3/B3 -> 0.09375 | H3: Same general formula with the alternative's non-zero tariff. | I3: China must be 9.38% cheaper before duty; do not default every comparison to 10.71%. | J3: EXT_UKGT; EXT_UK_VIETNAM | K3: T04; T09; T11
A4: Both origins fall back to 12% | B4: 100 | C4: 0.12 | D4: 0.12 | E4: =B4*(1+D4) -> 112 | F4: =E4/(1+C4) -> 100 | G4: =1-F4/B4 -> 0 | H4: Non-qualifying preference scenario. | I4: No tariff-driven China discount is required when both origins face 12%; other costs/capability still matter. | J4: EXT_UKGT | K4: T01-T08

Sheet APPAREL_Scope_Check
A1: Origin / group | B1: APPAREL-labelled sites | C1: Keyword-flagged non-garment sites | D1: Flagged share | E1: Residual garment-proxy maximum | F1: Interpretation | G1: Rule
A2: China | B2: 507 | C2: 159 | D2: =IFERROR(C2/B2,"") -> 0.31360947 | E2: =B2-C2 -> 348 | F2: Distortion is China-specific: footwear, leather goods, headwear, eyewear, umbrellas and jewellery appear inside APPAREL. | G2: Lower-bound keyword diagnostic; not a reclassification.
A3: India | B3: 212 | C3: 11 | D3: =IFERROR(C3/B3,"") -> 0.051886792 | E3: =B3-C3 -> 201 | F3: APPAREL is a much stronger garment proxy than in China, but still not an HS mapping. | G3: Lower-bound keyword diagnostic; not a reclassification.
A4: Bangladesh | B4: 192 | C4: 1 | D4: =IFERROR(C4/B4,"") -> 0.0052083333 | E4: =B4-C4 -> 191 | F4: APPAREL is a strong garment proxy in this screen. | G4: Lower-bound keyword diagnostic; not a reclassification.
A5: Turkey + Sri Lanka + Cambodia + Morocco + Myanmar | B5: 228 | C5: 0 | D5: =IFERROR(C5/B5,"") -> 0 | E5: =B5-C5 -> 228 | F5: No keyword-flagged non-garment sites in the combined screen. | G5: Zero flags do not prove every site is a garment factory.

Sheet Natural_Experiment
A1: Series | B1: H1 2025 net mass kg | C1: H1 2026 net mass kg | D1: H1 2025 index | E1: H1 2026 index | F1: Change | G1: Expected under simple tariff hypothesis | H1: Observed verdict | I1: Use in project | J1: Source_ID | K1: Evidence_Query_ID
A2: India HS61 net mass | B2: 17715335 | C2: 16301594 | D2: 100 | E2: =C2/B2*100 -> 92.019677 | F2: =E2/D2-1 -> -0.079803233 | G2: Control: remained at 9.6% through H1 2026 | H2: Fell about 8.0% | I2: Context only | J2: EXT_HMRC_OTS; EXT_DCTS_GRAD | K2: Q5
A3: India HS62 net mass | B3: 11557061 | C3: 12647573 | D3: 100 | E3: =C3/B3*100 -> 109.43589 | F3: =E3/D3-1 -> 0.094358938 | G3: Treatment: duty rose 9.6% to 12% | H3: Rose about 9.4% | I3: Context only | J3: EXT_HMRC_OTS; EXT_DCTS_GRAD | K3: Q5
A4: HS62 minus HS61 change | F4: =F3-F2 -> 0.17416217 | G4: Negative if the tariff increase reduced relative volume | H4: +17.4 percentage points; opposite sign | I4: Do not estimate causal elasticity | J4: EXT_HMRC_OTS; EXT_DCTS_GRAD | K4: Q5
A5: Cambodia placebo — HS62 minus HS61 change | F5: 0.135 | G5: No India-specific Chapter 62 graduation; DCTS Comprehensive rate remained 0%. | H5: +13.5pp; same direction and similar magnitude to India. | I5: Placebo evidence — undermines simple causal attribution. | J5: EXT_HMRC_OTS | K5: Q8
A6: Pakistan placebo — HS62 minus HS61 change | F6: 0.437 | G6: No India-specific Chapter 62 graduation; DCTS Enhanced rate remained 0%. | H6: +43.7pp; materially larger than India. | I6: Placebo evidence — rejects simple causal attribution. | J6: EXT_HMRC_OTS | K6: Q8
A7: Vietnam comparison — HS62 minus HS61 change | F7: 0.475 | G7: Comparison origin; not a clean untreated control because UKVFTA staging continued for some lines. | H7: +47.5pp; materially larger than India, but interpret cautiously. | I7: Supporting comparison — reinforces rejection of the simple design. | J7: EXT_HMRC_OTS | K7: Q8

Sheet Mass_Coverage_QC
A1: CN8 code | B1: 2025 world total value GBP | C1: World value with positive net mass | D1: World value coverage | E1: Ten-origin total value GBP | F1: Ten-origin value with positive net mass | G1: Ten-origin value coverage | H1: Threshold | I1: Status | J1: WP005 requirement | K1: Source_ID | L1: Evidence_Query_ID
A2: 61091000 | B2: 1223299784 | C2: 1223299784 | D2: =IFERROR(C2/B2,0) -> 1 | E2: 830546091 | F2: 830546091 | G2: =IFERROR(F2/E2,0) -> 1 | H2: 0.995 | I2: =IF(AND(D2>=H2,G2>=H2),"Pass","Fail") -> Pass | J2: Repeat at CN8 x origin x month for 2019-01 to 2026-06; flag/impute nothing silently. | K2: EXT_HMRC_OTS | L2: Q2; Q3
A3: 61103099 | B3: 719371758 | C3: 719371758 | D3: =IFERROR(C3/B3,0) -> 1 | E3: 560567400 | F3: 560567400 | G3: =IFERROR(F3/E3,0) -> 1 | H3: 0.995 | I3: =IF(AND(D3>=H3,G3>=H3),"Pass","Fail") -> Pass | J3: Repeat at CN8 x origin x month for 2019-01 to 2026-06; flag/impute nothing silently. | K3: EXT_HMRC_OTS | L3: Q2; Q3
A4: 62044300 | B4: 349077816 | C4: 349077816 | D4: =IFERROR(C4/B4,0) -> 1 | E4: 201158776 | F4: 201158776 | G4: =IFERROR(F4/E4,0) -> 1 | H4: 0.995 | I4: =IF(AND(D4>=H4,G4>=H4),"Pass","Fail") -> Pass | J4: Repeat at CN8 x origin x month for 2019-01 to 2026-06; flag/impute nothing silently. | K4: EXT_HMRC_OTS | L4: Q2; Q3
A5: 62052000 | B5: 263245768 | C5: 263245768 | D5: =IFERROR(C5/B5,0) -> 1 | E5: 171628888 | F5: 171628888 | G5: =IFERROR(F5/E5,0) -> 1 | H5: 0.995 | I5: =IF(AND(D5>=H5,G5>=H5),"Pass","Fail") -> Pass | J5: Repeat at CN8 x origin x month for 2019-01 to 2026-06; flag/impute nothing silently. | K5: EXT_HMRC_OTS | L5: Q2; Q3

Sheet Data_Dictionary
A1: Sheet | B1: Field / term | C1: Type | D1: Definition | E1: Formula / rule | F1: Source | G1: Known limitation
A2: Category_Screen | B2: Observed unit value GBP/kg | C2: Decimal | D2: Market-level import value per kilogram. | E2: Import value GBP / net mass kg | F2: EXT_HMRC_OTS (Q3/Q6/Q7) | G2: Mix, quality and CIF-style valuation; not NEXT FOB.
A3: Commodity_Shortlist | B3: CN8 code | C3: Text | D3: Eight-digit commodity used in HMRC statistics. | E3: Preserve as text | F3: EXT_HMRC_OTS Q0 | G3: Import tariff declarations use more granular 10-digit descendants.
A4: Commodity_Shortlist | B4: Basket role | C4: Text | D4: Strategic question each code is designed to test. | E4: China capability/duty or Bangladesh-vs-India contest | F4: D013 | G4: Purpose-built basket is not a whole-market estimate.
A5: Basket_Representativeness | B5: Blended representation ratio | C5: Decimal | D5: Core-basket origin share divided by total HS61+62 origin share. | E5: Core basket share / overall share | F5: EXT_HMRC_OTS Q2-Q4/Q7 | G5: The 0.80 reserve rule applies to India only.
A6: Basket_Representativeness | B6: Probe-pair representation ratio | C6: Decimal | D6: Named probe-pair origin share divided by the same origin's overall HS61+62 share. | E6: Probe pair share / overall share | F6: EXT_HMRC_OTS Q2-Q4/Q7 | G6: Purpose-specific diagnostic, not a statistical confidence test.
A7: Basket_Representativeness | B7: India reserve threshold | C7: Percentage | D7: Pre-committed trigger for activating 62063000. | E7: 0.80; India blended ratio only | F7: D013 | G7: Governance trigger, not a confidence interval.
A8: Tariff_Matrix | B8: Current rate | C8: Percentage | D8: Selected-code rate from 2026-07-15 under the named regime. | E8: Date/origin/code-specific lookup | F8: EXT_UKGT T01-T08 plus legal sources | G8: Preference requires origin compliance.
A9: HMRC_Query_Manifest | B9: Canonical replay URL | C9: Text/URL | D9: Deterministic OData request that reproduces the archived response logic. | E9: Endpoint + encoded query parameters | F9: EXT_HMRC_OTS | G9: A live replay can change if HMRC revises data.
A10: UKGT_Query_Manifest | B10: Canonical replay URL | C10: Text/URL | D10: Dated Trade Tariff API request for one 10-digit commodity. | E10: Commodity endpoint + as_of date | F10: EXT_UKGT | G10: Response does not prove supplier origin eligibility.
A11: Tariff_Snapshot | B11: Direct preference | C11: Percentage | D11: Direct geographical-area tariff-preference measure parsed from the dated response. | E11: Measure type 142 + country geography | F11: EXT_UKGT | G11: Blank means no direct measure in that response; a scheme/group measure may still require a legal membership check.
A12: Origin_Rules | B12: CTH | C12: Text | D12: Change in tariff heading: non-originating materials must change at the four-digit level. | E12: Annex 3A headnote | F12: EXT_CETA_PSR | G12: Only one part of a combined rule for Chapters 61/62.
... A20: Tariff_Matrix | B20: Future regime change | C20: Text | D20: Known dated policy transition or mandatory future tariff/tier recheck. | E20: Record the official date, transition mechanism and monitoring trigger; blank means no change was logged, not proof that no future change exists. | F20: EXT_UN_LDC_BGD; EXT_DCTS_2026; EXT_DCTS_ROO | G20: The exact post-transition UK tier, effective date and selected-code rates may require a later country-graduation notice.

Sheet WP005_Handoff
A1: Handoff item | B1: Locked specification | C1: Why / QC requirement | D1: WP005 output field or file
A2: Period | B2: 2019-01 to 2026-06 monthly; 2019-2025 full-year; 2026 YTD separate | C2: Never annualise the partial 2026 observation. | D2: month_id; period_type
A3: Core CN8 | B3: 61091000; 61103099; 62044300; 62052000 | C3: Reserve 62063000 is not extracted unless trigger changes. | D3: commodity_code_cn8
A4: Origins | B4: Bangladesh; Cambodia; China; India; Morocco; Myanmar; Pakistan; Sri Lanka; Turkey; Vietnam; World | C4: World is denominator, not an origin row to combine with countries. | D4: origin_country; origin_iso
A5: Grain | B5: One row per CN8 x origin x month x flow after summing ports/suppression rows as appropriate | C5: Composite key must be unique after aggregation. | D5: commodity_code_cn8 + origin_iso + month_id + flow
A6: Flow | B6: UK imports only | C6: Do not mix exports or EU/non-EU flow definitions. | D6: flow = Import
A7: Required measures | B7: Statistical value GBP; net mass kg; supplementary quantity where available; suppression index | C7: Keep raw and aggregated fields; do not impute suppressed mass silently. | D7: import_value_gbp; net_mass_kg; supplementary_quantity; suppression_index
A8: Derived measures | B8: Unit value GBP/kg; origin market share; YoY; rolling 12-month value/mass; volatility | C8: Calculate at CN8 before product aggregation. | D8: unit_value_gbp_per_kg; value_share; yoy; r12; volatility
A9: Mass coverage gate | B9: >=99.5% of value has positive mass at CN8 x origin x month; WP004's 2025 screen is only the pre-check | C9: If failed, use value/alternative quantity or flag series; do not report partial £/kg as complete. | D9: mass_value_coverage; mass_gate_status
A10: 2022 break | B10: For market-wide EU comparisons, 2022 onward is primary like-for-like; 2019-2021 context only | C10: Carry comparability flag into every market-wide output. | D10: eu_methodology_comparable_flag
A11: Tariff join | B11: Join by origin + code + effective date; retain statutory and eligible-preference scenario rates | C11: Use Tariff_Matrix plus T01-T11 evidence; preference is conditional and must not overwrite the statutory fallback. | D11: statutory_rate; preference_rate; preference_eligibility_status
A12: Output file | B12: NEXT_WP005_HMRC_Monthly_Trade_Core4_2019-01_to_2026-06.csv | C12: SQL-ready UTF-8 CSV; codes/IDs stored as text; archive the exact API response and query manifest. | D12: File deliverable
A13: SQL table | B13: stg_hmrc_imports_core4 then fct_hmrc_import_monthly | C13: Load raw/staging first; aggregate and validate in SQL. | D13: Database deliverable

Sheet QC_Checks
A1: QC_ID | B1: Check | C1: Expected rule | D1: Actual result | E1: Exception count | F1: Status | G1: Resolution / handoff | H1: Reviewer | I1: Review date
A2: QC001 | B2: Core-code count | C2: Exactly four core CN8 codes; reserve excluded. | D2: Four core and one inactive reserve. | E2: 0 | F2: Pass | G2: D013 locked. | H2: Project analyst | I2: 46259
A3: QC002 | B3: Knit/woven balance | C3: At least two knit and two woven core codes. | D3: 2 knit / 2 woven. | E3: 0 | F3: Pass | G3: Policy split retained. | H3: Project analyst | I3: 46259
A4: QC003 | B4: Cotton/MMF balance | C4: Core basket includes cotton and man-made/synthetic fibres. | D4: Two cotton and two MMF/synthetic probes. | E4: 0 | F4: Pass | G4: Capability contrast retained. | H4: Project analyst | I4: 46259
A5: QC004 | B5: Basket arithmetic | C5: Core values reconcile to the inclusive HS61+62 denominator. | D5: GBP 2,554,995,126; 15.79% of GBP 16,177,251,820. | E5: 0 | F5: Pass | G5: Q3 numerator; Q7 inclusive denominator. | H5: Project analyst | I5: 46259
A6: QC005 | B6: India reserve trigger | C6: India blended representation ratio >=0.80 or reserve activates. | D6: 1.202; reserve inactive. | E6: 0 | F6: Pass | G6: Keep 62063000 out of WP005. | H6: Project analyst | I6: 46259
A7: QC006 | B7: Probe-pair representativeness | C7: Report the pair designed for each focal origin; do not apply the India threshold to China. | D7: China 1.575; Bangladesh 1.846; India 1.608. | E7: 0 | F7: Pass | G7: Blended China 0.769 is explained by the bimodal design. | H7: Project analyst | I7: 46259
A8: QC007 | B8: 2025 mass coverage | C8: Each core code has >=99.5% value coverage in the 2025 screen. | D8: All four core codes: 100% world and ten-origin coverage. | E8: 0 | F8: Pass | G8: Repeat at CN8 x origin x month in WP005. | H8: Project analyst | I8: 46259
A9: QC008 | B9: Tariff matrix completeness | C9: 10 origins x 4 codes = 40 rows with three time windows. | D9: 40 complete origin-code rows. | E9: 0 | F9: Pass | G9: Date-specific join ready. | H9: Project analyst | I9: 46259
A10: QC009 | B10: India graduation split | C10: 2026 H1 HS61=9.6%; HS62=12%; current CETA=0% conditional. | D10: Split recorded; pre-CETA API checks contain no direct India measure. | E10: 0 | F10: Pass | G10: DCTS graduation + CETA legal sources retained. | H10: Project analyst | I10: 46259
A11: QC010 | B11: Vietnam staging | C11: 62044300 is 3.0% in 2025 and 1.5% in 2026. | D11: T09=3.0%; T04/T11=1.5%. | E11: 0 | F11: Pass | G11: 9.38% break-even scenario added. | H11: Project analyst | I11: 46259
A12: QC011 | B12: CETA combined origin rule | C12: Chapters 61/62 = CTH AND Standard QVC. | D12: Combined rule and three QVC methods recorded. | E12: 0 | F12: Pass | G12: Zero rate remains conditional. | H12: Project analyst | I12: 46259
A13: QC012 | B13: Duty basis | C13: HMRC import value is CIF-style; freight is not added twice. | D13: D014 and break-even formula use border value. | E13: 0 | F13: Pass | G13: WP008 handoff explicit. | H13: Project analyst | I13: 46259
... A20: QC019 | B20: Natural-experiment placebo record | C20: Record comparison-origin divergences and reject elasticity estimation when the India result is not distinct. | D20: India +17.4pp; Cambodia +13.5pp; Pakistan +43.7pp; Vietnam +47.5pp. | E20: 0 | F20: Pass | G20: Simple causal design rejected; no duty-elasticity coefficient estimated. | H20: Project analyst | I20: 46260

Sheet HMRC_Query_Manifest
A1: Query_ID | B1: Source_ID | C1: Purpose | D1: Endpoint | E1: Filter / scope | F1: Grouping / aggregation | G1: Canonical replay URL | H1: Evidence file | I1: SHA256 | J1: Bytes | K1: Rows | L1: NextLink present? | M1: Reporting period | N1: Reconciliation | O1: Notes
A2: Q0 | B2: EXT_HMRC_OTS | C2: Commodity lookup for true CN8 records in HS61/62 | D2: /Commodity | E2: CommodityId ge 61000000 and CommodityId lt 63000000 | F2: $select=CommodityId,Cn8Code,Hs2Code,Hs4Code,Hs6Code,Hs2Description,Hs4Description,Hs6Description,Cn8LongDescription | G2: https://api.uktradeinfo.com/Commodity?%24filter=CommodityId+ge+61000000+and+CommodityId+lt+63000000&%24select=CommodityId%2CCn8Code%2CHs2Code%2CHs4Code%2CHs6Code%2CHs2Description%2CHs4Description%2CHs6Description%2CCn8LongDescription | H2: EXT_HMRC_OTS_WP004_Commodity_Lookup_HS61_HS62_2026-08-25.json | I2: 049af23fc0eccae4f725d080653f103892af74bf270f072ca4bf0c6c50124724 | J2: 317103 | K2: 449 | L2: No | M2: Current lookup at capture | N2: Pass - schema and figures reconciled | O2: Numeric CN8 range intentionally excludes HS2/pseudo residual identifiers.
A3: Q1 | B3: EXT_HMRC_OTS | C3: Country lookup and ISO mapping | D3: /Country | E3: None | F3: $select=CountryId,CountryCodeNumeric,CountryName,CountryCodeAlpha | G3: https://api.uktradeinfo.com/Country?%24select=CountryId%2CCountryCodeNumeric%2CCountryName%2CCountryCodeAlpha | H3: EXT_HMRC_OTS_WP004_Country_Lookup_2026-08-25.json | I3: 0d2b9a7a5357b00ee0365f34bfc7fda43a34ad7cbfeb4f225aac51ca89cee7dd | J3: 25081 | K3: 263 | L3: No | M3: Current lookup at capture | N3: Pass - schema and figures reconciled | O3: Used to map the ten focal HMRC CountryIds.
A4: Q2 | B4: EXT_HMRC_OTS | C4: 2025 true-CN8 screen for ten focal non-EU origins | D4: /OTS | E4: MonthId 202501-202512; FlowTypeId=3; CommodityId ge 61000000 and CommodityId lt 63000000; focal CountryIds | F4: Group by CommodityId, CountryId, FlowTypeId, SuppressionIndex; sum Value, NetMass, SuppUnit | G4: https://api.uktradeinfo.com/OTS?%24apply=filter%28MonthId+ge+202501+and+MonthId+le+202512+and+FlowTypeId+eq+3+and+%28CountryId+eq+52+or+CountryId+eq+204+or+CountryId+eq+662+or+CountryId+eq+664+or+CountryId+eq+666+or+CountryId+eq+669+or+CountryId+eq+676+or+CountryId+eq+690+or+CountryId+eq+696+or+CountryId+eq+720%29+and+CommodityId+ge+61000000+and+CommodityId+lt+63000000%29%2Fgroupby%28%28CommodityId%2CCountryId%2CFlowTypeId%2CSuppressionIndex%29%2Caggregate%28Value+with+sum+as+Value%2CNetMass+with+sum+as+NetMass%2CSuppUnit+with+sum+as+SuppUnit%29%29 | H4: EXT_HMRC_OTS_WP004_2025_Category_Screen_10Origins_Raw_2026-08-25.json | I4: 1b79bdcb6bad6fdb37a0ffff1d64a5cb7543100debdf1f87cb44e3e4245deccf | J4: 392325 | K4: 2664 | L4: No | M4: 2025-01 to 2025-12 | N4: Pass - schema and figures reconciled | O4: All ten focal origins are non-EU, so FlowTypeId 3 is correct.
A5: Q3 | B5: EXT_HMRC_OTS | C5: 2025 true-CN8 world denominator and code-level value/mass | D5: /OTS | E5: MonthId 202501-202512; imports (1 or 3); CommodityId ge 61000000 and CommodityId lt 63000000 | F5: Group by CommodityId, FlowTypeId, SuppressionIndex; sum Value, NetMass, SuppUnit | G5: https://api.uktradeinfo.com/OTS?%24apply=filter%28MonthId+ge+202501+and+MonthId+le+202512+and+%28FlowTypeId+eq+1+or+FlowTypeId+eq+3%29+and+CommodityId+ge+61000000+and+CommodityId+lt+63000000%29%2Fgroupby%28%28CommodityId%2CFlowTypeId%2CSuppressionIndex%29%2Caggregate%28Value+with+sum+as+Value%2CNetMass+with+sum+as+NetMass%2CSuppUnit+with+sum+as+SuppUnit%29%29 | H5: EXT_HMRC_OTS_WP004_2025_CN8_World_Denominator_Raw_2026-08-25.json | I5: bef8b48afb98564ef329ac4b7036d7c750c8df6b4dcdbdbbfe4d86b387aa2119 | J5: 89360 | K5: 665 | L5: No | M5: 2025-01 to 2025-12 | N5: Pass - schema and figures reconciled | O5: Correct for exact-CN8 analysis; excludes residual 61------ and 62------ values.
A6: Q4 | B6: EXT_HMRC_OTS | C6: 2025 all-origin HS61+62 true-CN8 benchmark | D6: /OTS | E6: MonthId 202501-202512; imports (1 or 3); CommodityId ge 61000000 and CommodityId lt 63000000 | F6: Group by CountryId, FlowTypeId, SuppressionIndex; sum Value, NetMass | G6: https://api.uktradeinfo.com/OTS?%24apply=filter%28MonthId+ge+202501+and+MonthId+le+202512+and+%28FlowTypeId+eq+1+or+FlowTypeId+eq+3%29+and+CommodityId+ge+61000000+and+CommodityId+lt+63000000%29%2Fgroupby%28%28CountryId%2CFlowTypeId%2CSuppressionIndex%29%2Caggregate%28Value+with+sum+as+Value%2CNetMass+with+sum+as+NetMass%29%29 | H6: EXT_HMRC_OTS_WP004_2025_HS61_HS62_AllOrigin_Benchmark_Raw_2026-08-25.json | I6: 51977e168611ad1d4cea119a75c559cc7a321f1dd59ba3e0d7815bf784da091a | J6: 17073 | K6: 160 | L6: No | M6: 2025-01 to 2025-12 | N6: Pass - schema and figures reconciled | O6: Focal non-EU country totals reconcile; full-market denominator is taken from Q7.
A7: Q5 | B7: EXT_HMRC_OTS | C7: India H1 2025 versus H1 2026 HS61/62 diagnostic | D7: /OTS | E7: H1 2025 or H1 2026; CountryId=664; FlowTypeId=3; CommodityId ge 61000000 and CommodityId lt 63000000 | F7: Group by MonthId, CommodityId, CountryId, FlowTypeId, SuppressionIndex; sum Value, NetMass, SuppUnit | G7: https://api.uktradeinfo.com/OTS?%24apply=filter%28%28%28MonthId+ge+202501+and+MonthId+le+202506%29+or+%28MonthId+ge+202601+and+MonthId+le+202606%29%29+and+FlowTypeId+eq+3+and+CountryId+eq+664+and+CommodityId+ge+61000000+and+CommodityId+lt+63000000%29%2Fgroupby%28%28MonthId%2CCommodityId%2CCountryId%2CFlowTypeId%2CSuppressionIndex%29%2Caggregate%28Value+with+sum+as+Value%2CNetMass+with+sum+as+NetMass%2CSuppUnit+with+sum+as+SuppUnit%29%29 | H7: EXT_HMRC_OTS_WP004_India_H1_2025_vs_H1_2026_Raw_2026-08-25.json | I7: 5dd317d917db167cb8ed70406dcd738aa5b18fbe42794b6e059600c4ddb1ee88 | J7: 442612 | K7: 2733 | L7: No | M7: 2025-H1 and 2026-H1 | N7: Pass - schema and figures reconciled | O7: Diagnostic only; no causal elasticity is estimated.
A8: Q6 | B8: EXT_HMRC_OTS | C8: 2025 inclusive HS63 category total | D8: /OTS | E8: MonthId 202501-202512; imports (1 or 3); Commodity/Hs2Code='63' | F8: Group by FlowTypeId, SuppressionIndex; sum Value, NetMass | G8: https://api.uktradeinfo.com/OTS?%24apply=filter%28MonthId+ge+202501+and+MonthId+le+202512+and+%28FlowTypeId+eq+1+or+FlowTypeId+eq+3%29+and+Commodity%2FHs2Code+eq+%2763%27%29%2Fgroupby%28%28FlowTypeId%2CSuppressionIndex%29%2Caggregate%28Value+with+sum+as+Value%2CNetMass+with+sum+as+NetMass%29%29 | H8: EXT_HMRC_OTS_WP004_2025_HS63_Category_Total_Raw_2026-08-25.json | I8: ecbfbdbbe118897cd3e7502fb057f80fd1fb426954d0a38371eb7452eefe9c09 | J8: 309 | K8: 2 | L8: No | M8: 2025-01 to 2025-12 | N8: Pass - schema and figures reconciled | O8: Closure addition: archives the HS63 total already used in the screen.
