Workbook

Sheet README
A1: NEXT WP005 — HMRC Monthly Trade Extraction
A2: Controlled monthly evidence for the four locked CN8 codes, with source reconciliation and quality checks.
A4: Field | B4: Value
A5: Work package | B5: WP005 — monthly HMRC extraction and SQL-ready preparation
A6: Status | B6: Final monthly-trade evidence; QC complete; fixed extracts used in WP006 SQL core
A7: Data cut | B7: 2019-01 through 2026-06 (90 months)
A8: Reporting treatment | B8: 2019-2025 complete calendar years; 2026 H1/YTD June reported separately
A9: Core CN8 codes | B9: 61091000, 61103099, 62044300, 62052000
A10: Reserve code | B10: 62063000 remains inactive and was not extracted
A11: Selected partner countries | B11: Bangladesh, Cambodia, China, India, Morocco, Myanmar, Pakistan, Sri Lanka, Turkey and Vietnam
A12: World denominator | B12: EU imports (FlowTypeId 1) plus non-EU imports (FlowTypeId 3), stored separately from partner-country facts
A13: Raw evidence | B13: 3,588 partner rows; 720 World-flow rows; no pagination
A14: Final analytical rows | B14: 3,600 partner rows; 360 World rows
A15: No-API-record combinations | B15: 12; retained explicitly with zero measures and record_status=NO_API_RECORD
... A19: Primary key | B19: cn8_code + partner_country_iso2 + month_id + flow
A21: Formula and interpretation rules
A22: Metric | B22: Rule | C22: Control | D22: Interpretation
A23: Observed unit value | B23: import_value_gbp / net_mass_kg | C23: Calculate only where net mass is positive. | D23: Market import unit value; not NEXT FOB or an item price.
A24: Aggregated unit value | B24: SUM(import_value_gbp) / SUM(net_mass_kg) | C24: Never average row-level unit values. | D24: Avoids mix-weighting error.
A25: Partner value share | B25: partner import value / World import value | C25: Join on CN8 and month. | D25: World is a denominator, never an additional partner row.
A26: Mass coverage | B26: value with positive mass / total value | C26: Locked pass threshold 99.5%. | D26: A zero-value no-API-record month does not reduce coverage.
A27: Rest of World | B27: World value - sum(selected ten partner values) | C27: Must never be negative. | D27: Captures countries outside the selected set without downloading every country.
A28: 2026 comparison | B28: 2026 H1 versus 2025 H1 | C28: Do not compare H1 2026 with full-year 2025. | D28: No post-CETA outturn claim; CETA began 15 July 2026.
A29: Unit-value exception review | B29: monthly unit value / full-period reference median | C29: Primary 2.5x multiplier with 2x/3x/4x sensitivity counts; retain official-data base | D29: Diagnostic only; REVIEW is not proof of error
A30: Sheet guide
A31: Sheet / group | B31: Purpose
A32: Scope_Contract | B32: Locked boundary, terminology and handoff rules
A33: Source_Register / Query_Manifest | B33: Evidence lineage, replay URLs, hashes, bytes and row counts
A34: dim_* | B34: Stable code, geography and month dimensions
A35: raw_* | B35: Unaltered API-returned grouped records represented as rows
A36: fct_* | B36: Final one-row-per-grain tables; suitable for SQL loading
A37: Reconciliation | B37: Population controls, annual context, 2025 tie-back and missing-record detail
A38: Mass_Coverage_QC / QC_Checks | B38: Coverage gate and formal validation evidence
A39: Data_Dictionary / SQL_Load_Map | B39: Field meanings, types, keys and target tables
A40: Unit_Value_Review_QC | B40: Review counts, threshold sensitivity, material examples and downstream handling

Sheet Scope_Contract
A1: WP005 Scope Contract
A2: Operational contract inherited from WP004 and refined only where HMRC field semantics required a more accurate label.
A4: Contract_ID | B4: Area | C4: Locked treatment | D4: Control / implication | E4: Status
A5: W5C01 | B5: Product scope | C5: Exactly four core CN8s: 61091000, 61103099, 62044300, 62052000 | D5: Reserve 62063000 remains inactive | E5: Confirmed
A6: W5C02 | B6: Period | C6: Monthly 2019-01 to 2026-06 | D6: 2019-2025 full calendar years; 2026 H1 separately | E6: Confirmed
A7: W5C03 | B7: Trade flow | C7: UK imports only | D7: FlowTypeId 3 for the ten non-EU partners; FlowTypeIds 1+3 for World | E7: Confirmed
A8: W5C04 | B8: Partner scope | C8: Ten named partner countries plus a separate inclusive World denominator | D8: Do not extract every country; derive Rest of World by subtraction | E8: Confirmed
A9: W5C05 | B9: Country meaning | C9: Use partner_country / country_of_dispatch terminology | D9: Do not present HMRC partner country as manufacturing origin | E9: Confirmed for WP005
A10: W5C06 | B10: Extraction grain | C10: Raw: month x CN8 x partner/flow x suppression index | D10: Final: month x CN8 x partner x import flow | E10: Confirmed
A11: W5C07 | B11: Measures | C11: Value, NetMass, SuppUnit and SuppressionIndex | D11: Retain raw measures before derivation | E11: Confirmed
A12: W5C08 | B12: Valuation | C12: HMRC import statistical value is CIF-style and excludes UK duty/tax | D12: Do not add international freight again | E12: Confirmed
A13: W5C09 | B13: No API row | C13: Retain a complete 3,600-row panel with api_row_present_flag and record_status | D13: Zero measures are analytical placeholders only where the API returned no grouped record | E13: Confirmed
A14: W5C10 | B14: Mass gate | C14: Value with positive mass / total value must be at least 99.5% | D14: Review any value-without-mass observation; reserve-code trigger remains available | E14: Confirmed
A15: W5C11 | B15: 2026 comparison | C15: Compare H1 2026 only with H1 2025 or other H1 periods | D15: No post-CETA behavioural inference | E15: Confirmed
... A18: W5C14 | B18: Unit-value exception review | C18: Use 2.50x from the full-period median (reciprocal lower bound 0.40x) as a provisional monthly review parameter within CN8 x partner and CN8 x World; disclose 2x/2.5x/3x/4x sensitivity counts. | D18: Diagnostic only: retain official observations in the base case; REVIEW is not proof of error; show a separately labelled exclusion sensitivity. | E18: Approved for diagnostic use

Sheet Source_Register
A1: WP005 Source Register
A2: Only the two monthly API extracts are new evidence; WP004 lookups and official methodology are reused without duplication.
A4: Source_ID | B4: Source_Type | C4: Official source | D4: Publisher | E4: Reporting period / date | F4: Local evidence filename | G4: Official / replay URL | H4: Used for | I4: Status | J4: Known limitation
A5: EXT_HMRC_OTS_WP005_PARTNER_MONTHLY | B5: Trade data | C5: HMRC UK Trade Info OTS API | D5: HM Revenue & Customs | E5: 2019-01 to 2026-06 | F5: EXT_HMRC_OTS_WP005_Core4_10PartnerCountries_Monthly_2019-01_to_2026-06_Raw_2026-08-26.json | G5: https://api.uktradeinfo.com/OTS?%24apply=filter%28MonthId+ge+201901+and+MonthId+le+202606+and+FlowTypeId+eq+3+and+%28CountryId+eq+52+or+CountryId+eq+204+or+CountryId+eq+662+or+CountryId+eq+664+or+CountryId+eq+666+or+CountryId+eq+669+or+CountryId+eq+676+or+CountryId+eq+690+or+CountryId+eq+696+or+CountryId+eq+720%29+and+%28CommodityId+eq+61091000+or+CommodityId+eq+61103099+or+CommodityId+eq+62044300+or+CommodityId+eq+62052000%29%29%2Fgroupby%28%28MonthId%2CCommodityId%2CCountryId%2CFlowTypeId%2CSuppressionIndex%29%2Caggregate%28Value+with+sum+as+Value%2CNetMass+with+sum+as+NetMass%2CSuppUnit+with+sum+as+SuppUnit%29%29 | H5: Monthly core-four imports for ten selected partner countries | I5: Retrieved and reconciled | J5: Country field is country-of-dispatch / partner basis
A6: EXT_HMRC_OTS_WP005_WORLD_MONTHLY | B6: Trade data | C6: HMRC UK Trade Info OTS API | D6: HM Revenue & Customs | E6: 2019-01 to 2026-06 | F6: EXT_HMRC_OTS_WP005_Core4_World_Monthly_2019-01_to_2026-06_Raw_2026-08-26.json | G6: https://api.uktradeinfo.com/OTS?%24apply=filter%28MonthId+ge+201901+and+MonthId+le+202606+and+%28FlowTypeId+eq+1+or+FlowTypeId+eq+3%29+and+%28CommodityId+eq+61091000+or+CommodityId+eq+61103099+or+CommodityId+eq+62044300+or+CommodityId+eq+62052000%29%29%2Fgroupby%28%28MonthId%2CCommodityId%2CFlowTypeId%2CSuppressionIndex%29%2Caggregate%28Value+with+sum+as+Value%2CNetMass+with+sum+as+NetMass%2CSuppUnit+with+sum+as+SuppUnit%29%29 | H6: Monthly inclusive World denominator | I6: Retrieved and reconciled | J6: EU and non-EU flows combined only after extraction
A7: EXT_HMRC_OTS | B7: Reference data | C7: WP004 commodity and country lookups | D7: HM Revenue & Customs | E7: Current at 2026-08-25 | F7: NEXT_WP004_API_Evidence_JSON_Closed_2026-08-26.zip | G7: https://www.uktradeinfo.com/api-documentation | H7: CN8 descriptions and HMRC country/ISO mapping | I7: Reused; no duplicate download | J7: Live reference data can change
A8: EXT_HMRC_API | B8: API documentation | C8: HM Revenue and Customs UK Trade Info API | D8: HM Revenue & Customs | E8: Current | F8: HMRC_UK_Trade_Info_API_Documentation_2026.pdf | G8: https://www.uktradeinfo.com/api-documentation | H8: Endpoint, pagination and field mechanics | I8: Reviewed | J8: Web documentation may be updated
A9: EXT_HMRC_SPEC | B9: Methodology | C9: Overseas trade in goods methodology and quality report | D9: HM Revenue & Customs | E9: Published 2025-12-09 | F9: HMRC_OTS_Methodology_and_Quality_Report_2025.pdf | G9: https://www.gov.uk/government/statistics/overseas-trade-statistics-methodologies/overseas-trade-in-goods-statistics-methodology-and-quality-report--3 | H9: CIF valuation, mass estimation, suppression, revisions and comparability | I9: Reviewed | J9: Provisional figures may be revised
A10: EXT_HMRC_JUN26 | B10: Release notice | C10: UK overseas trade in goods statistics: June 2026 | D10: HM Revenue & Customs | E10: Published 2026-08-13 | F10: HMRC_UK_OTS_June_2026_Release.pdf | G10: https://www.uktradeinfo.com/news/uk-overseas-trade-in-goods-statistics-june-2026/ | H10: Confirms latest complete month for the extraction | I10: Reviewed | J10: Summary release, not the detailed CN8 data
A11: EXT_HMRC_COD | B11: Methodology evidence | C11: UK imports by country of origin and country of dispatch, 2024 | D11: HM Revenue & Customs | E11: Published 2026-05-21 | F11: HMRC_UK_Imports_CoO_vs_CoD_2024.pdf | G11: https://www.gov.uk/government/statistics/uk-import-trade-in-goods-by-country-of-origin-and-country-of-dispatch-2024/uk-import-trade-in-goods-by-country-of-origin-and-country-of-dispatch-2024 | H11: Supports partner-country / country-of-dispatch labelling | I11: Reviewed | J11: Ad hoc 2024 comparison; not the WP005 monthly dataset

Sheet Query_Manifest
A1: HMRC Query Manifest
A2: Canonical replay information for the two immutable WP005 raw JSON responses.
A4: Query_ID | B4: Source_ID | C4: Purpose | D4: Endpoint | E4: Filter / scope | F4: Grouping / aggregation | G4: Canonical replay URL | H4: Evidence file | I4: SHA256 | J4: Bytes | K4: Rows | L4: NextLink present? | M4: Reporting period | N4: Retrieval timestamp UTC | O4: Reconciliation | P4: Notes
A5: W5Q01 | B5: EXT_HMRC_OTS_WP005_PARTNER_MONTHLY | C5: Core-four monthly imports for ten selected non-EU partner countries | D5: /OTS | E5: MonthId 201901-202606; FlowTypeId=3; four locked CN8s; ten selected CountryIds | F5: Group by MonthId, CommodityId, CountryId, FlowTypeId, SuppressionIndex; sum Value, NetMass, SuppUnit | G5: https://api.uktradeinfo.com/OTS?%24apply=filter%28MonthId+ge+201901+and+MonthId+le+202606+and+FlowTypeId+eq+3+and+%28CountryId+eq+52+or+CountryId+eq+204+or+CountryId+eq+662+or+CountryId+eq+664+or+CountryId+eq+666+or+CountryId+eq+669+or+CountryId+eq+676+or+CountryId+eq+690+or+CountryId+eq+696+or+CountryId+eq+720%29+and+%28CommodityId+eq+61091000+or+CommodityId+eq+61103099+or+CommodityId+eq+62044300+or+CommodityId+eq+62052000%29%29%2Fgroupby%28%28MonthId%2CCommodityId%2CCountryId%2CFlowTypeId%2CSuppressionIndex%29%2Caggregate%28Value+with+sum+as+Value%2CNetMass+with+sum+as+NetMass%2CSuppUnit+with+sum+as+SuppUnit%29%29 | H5: EXT_HMRC_OTS_WP005_Core4_10PartnerCountries_Monthly_2019-01_to_2026-06_Raw_2026-08-26.json | I5: 37109cf0da13cf9f51e353589b8ea54d539ec01a8d387ec531ab90b45d449469 | J5: 596978 | K5: 3588 | L5: No | M5: 2019-01 to 2026-06 | N5: 46260.818 | O5: PASS - 2025 values/mass reconcile to WP004 | P5: Partner-country field follows HMRC OTS country-of-dispatch convention; do not label as manufacturing origin.
A6: W5Q02 | B6: EXT_HMRC_OTS_WP005_WORLD_MONTHLY | C6: Core-four monthly World denominator across EU and non-EU import flows | D6: /OTS | E6: MonthId 201901-202606; FlowTypeId=1 or 3; four locked CN8s; no country filter | F6: Group by MonthId, CommodityId, FlowTypeId, SuppressionIndex; sum Value, NetMass, SuppUnit | G6: https://api.uktradeinfo.com/OTS?%24apply=filter%28MonthId+ge+201901+and+MonthId+le+202606+and+%28FlowTypeId+eq+1+or+FlowTypeId+eq+3%29+and+%28CommodityId+eq+61091000+or+CommodityId+eq+61103099+or+CommodityId+eq+62044300+or+CommodityId+eq+62052000%29%29%2Fgroupby%28%28MonthId%2CCommodityId%2CFlowTypeId%2CSuppressionIndex%29%2Caggregate%28Value+with+sum+as+Value%2CNetMass+with+sum+as+NetMass%2CSuppUnit+with+sum+as+SuppUnit%29%29 | H6: EXT_HMRC_OTS_WP005_Core4_World_Monthly_2019-01_to_2026-06_Raw_2026-08-26.json | I6: 678a6a10ed9288e5083f7b7a0f444d61563eb4fc71b39d901001c3ac086634d2 | J6: 110968 | K6: 720 | L6: No | M6: 2019-01 to 2026-06 | N6: 46260.819 | O6: PASS - 2025 values/mass reconcile to WP004 | P6: EU and non-EU flows are kept in raw evidence and combined only in the World fact table.

Sheet dim_commodity
A1: cn8_code | B1: hs2_code | C1: hs4_code | D1: hs6_code | E1: description | F1: construction | G1: fibre | H1: basket_role | I1: inclusion_status
A2: 61091000 | B2: 61 | C2: 6109 | D2: 610910 | E2: T-shirts, singlets and other vests of cotton, knitted or crocheted | F2: Knitted | G2: Cotton | H2: Bangladesh-vs-India zero-duty contest | I2: Core
A3: 61103099 | B3: 61 | C3: 6110 | D3: 611030 | E3: Women's/girls' jerseys, pullovers, cardigans and similar of man-made fibres, residual line | F3: Knitted | G3: Man-made fibres | H3: China capability / duty exposure probe | I3: Core
A4: 62044300 | B4: 62 | C4: 6204 | D4: 620443 | E4: Women's/girls' dresses of synthetic fibres, not knitted or crocheted | F4: Woven | G4: Synthetic fibres | H4: China capability / duty exposure probe | I4: Core
A5: 62052000 | B5: 62 | C5: 6205 | D5: 620520 | E5: Men's/boys' shirts of cotton, not knitted or crocheted | F5: Woven | G5: Cotton | H5: Bangladesh-vs-India zero-duty contest | I5: Core
A6: 62063000 | B6: 62 | C6: 6206 | D6: 620630 | E6: Women's/girls' blouses and shirts of cotton, not knitted or crocheted | F6: Woven | G6: Cotton | H6: Reserve India representation code | I6: Reserve - inactive; not extracted

Sheet dim_partner_country
A1: partner_country_id | B1: country_code_numeric | C1: partner_country_iso2 | D1: partner_country_name | E1: hmrc_flow_type_id | F1: scope_status | G1: geographical_basis
A2: 52 | B2: 052 | C2: TR | D2: Turkey | E2: 3 | F2: Selected partner country | G2: HMRC OTS country of dispatch / partner-country basis
A3: 204 | B3: 204 | C3: MA | D3: Morocco | E3: 3 | F3: Selected partner country | G3: HMRC OTS country of dispatch / partner-country basis
A4: 662 | B4: 662 | C4: PK | D4: Pakistan | E4: 3 | F4: Selected partner country | G4: HMRC OTS country of dispatch / partner-country basis
A5: 664 | B5: 664 | C5: IN | D5: India | E5: 3 | F5: Selected partner country | G5: HMRC OTS country of dispatch / partner-country basis
A6: 666 | B6: 666 | C6: BD | D6: Bangladesh | E6: 3 | F6: Selected partner country | G6: HMRC OTS country of dispatch / partner-country basis
A7: 669 | B7: 669 | C7: LK | D7: Sri Lanka | E7: 3 | F7: Selected partner country | G7: HMRC OTS country of dispatch / partner-country basis
A8: 676 | B8: 676 | C8: MM | D8: Myanmar | E8: 3 | F8: Selected partner country | G8: HMRC OTS country of dispatch / partner-country basis
A9: 690 | B9: 690 | C9: VN | D9: Vietnam | E9: 3 | F9: Selected partner country | G9: HMRC OTS country of dispatch / partner-country basis
A10: 696 | B10: 696 | C10: KH | D10: Cambodia | E10: 3 | F10: Selected partner country | G10: HMRC OTS country of dispatch / partner-country basis
A11: 720 | B11: 720 | C11: CN | D11: China | E11: 3 | F11: Selected partner country | G11: HMRC OTS country of dispatch / partner-country basis

Sheet dim_month
A1: month_id | B1: month_date | C1: calendar_year | D1: month_number | E1: month_name | F1: calendar_quarter | G1: half_year | H1: complete_calendar_year_flag | I1: ytd_2026_flag | J1: like_for_like_h1_flag
A2: 201901 | B2: 43466 | C2: 2019 | D2: 1 | E2: January | F2: Q1 | G2: H1 | H2: 1 | I2: 0 | J2: 1
A3: 201902 | B3: 43497 | C3: 2019 | D3: 2 | E3: February | F3: Q1 | G3: H1 | H3: 1 | I3: 0 | J3: 1
A4: 201903 | B4: 43525 | C4: 2019 | D4: 3 | E4: March | F4: Q1 | G4: H1 | H4: 1 | I4: 0 | J4: 1
A5: 201904 | B5: 43556 | C5: 2019 | D5: 4 | E5: April | F5: Q2 | G5: H1 | H5: 1 | I5: 0 | J5: 1
A6: 201905 | B6: 43586 | C6: 2019 | D6: 5 | E6: May | F6: Q2 | G6: H1 | H6: 1 | I6: 0 | J6: 1
A7: 201906 | B7: 43617 | C7: 2019 | D7: 6 | E7: June | F7: Q2 | G7: H1 | H7: 1 | I7: 0 | J7: 1
A8: 201907 | B8: 43647 | C8: 2019 | D8: 7 | E8: July | F8: Q3 | G8: H2 | H8: 1 | I8: 0 | J8: 0
A9: 201908 | B9: 43678 | C9: 2019 | D9: 8 | E9: August | F9: Q3 | G9: H2 | H9: 1 | I9: 0 | J9: 0
A10: 201909 | B10: 43709 | C10: 2019 | D10: 9 | E10: September | F10: Q3 | G10: H2 | H10: 1 | I10: 0 | J10: 0
A11: 201910 | B11: 43739 | C11: 2019 | D11: 10 | E11: October | F11: Q4 | G11: H2 | H11: 1 | I11: 0 | J11: 0
A12: 201911 | B12: 43770 | C12: 2019 | D12: 11 | E12: November | F12: Q4 | G12: H2 | H12: 1 | I12: 0 | J12: 0
A13: 201912 | B13: 43800 | C13: 2019 | D13: 12 | E13: December | F13: Q4 | G13: H2 | H13: 1 | I13: 0 | J13: 0
... A91: 202606 | B91: 46174 | C91: 2026 | D91: 6 | E91: June | F91: Q2 | G91: H1 | H91: 0 | I91: 1 | J91: 1

Sheet raw_partner_monthly
A1: source_query_id | B1: source_record_no | C1: month_id | D1: commodity_id | E1: country_id | F1: flow_type_id | G1: suppression_index | H1: supp_unit | I1: net_mass | J1: value_gbp | K1: source_file
A2: W5Q01 | B2: 1 | C2: 201901 | D2: 61091000 | E2: 52 | F2: 3 | G2: 0 | H2: 3275398 | I2: 583502 | J2: 11803255 | K2: EXT_HMRC_OTS_WP005_Core4_10PartnerCountries_Monthly_2019-01_to_2026-06_Raw_2026-08-26.json
A3: W5Q01 | B3: 2 | C3: 201901 | D3: 61091000 | E3: 204 | F3: 3 | G3: 0 | H3: 419760 | I3: 65037 | J3: 585401 | K3: EXT_HMRC_OTS_WP005_Core4_10PartnerCountries_Monthly_2019-01_to_2026-06_Raw_2026-08-26.json
A4: W5Q01 | B4: 3 | C4: 201901 | D4: 61091000 | E4: 662 | F4: 3 | G4: 0 | H4: 876746 | I4: 237071 | J4: 2434227 | K4: EXT_HMRC_OTS_WP005_Core4_10PartnerCountries_Monthly_2019-01_to_2026-06_Raw_2026-08-26.json
A5: W5Q01 | B5: 4 | C5: 201901 | D5: 61091000 | E5: 664 | F5: 3 | G5: 0 | H5: 5479197 | I5: 809198 | J5: 11462560 | K5: EXT_HMRC_OTS_WP005_Core4_10PartnerCountries_Monthly_2019-01_to_2026-06_Raw_2026-08-26.json
A6: W5Q01 | B6: 5 | C6: 201901 | D6: 61091000 | E6: 666 | F6: 3 | G6: 0 | H6: 20912727 | I6: 3063058 | J6: 31071303 | K6: EXT_HMRC_OTS_WP005_Core4_10PartnerCountries_Monthly_2019-01_to_2026-06_Raw_2026-08-26.json
A7: W5Q01 | B7: 6 | C7: 201901 | D7: 61091000 | E7: 669 | F7: 3 | G7: 0 | H7: 1425640 | I7: 195374 | J7: 2899724 | K7: EXT_HMRC_OTS_WP005_Core4_10PartnerCountries_Monthly_2019-01_to_2026-06_Raw_2026-08-26.json
A8: W5Q01 | B8: 7 | C8: 201901 | D8: 61091000 | E8: 676 | F8: 3 | G8: 0 | H8: 72843 | I8: 8991 | J8: 130735 | K8: EXT_HMRC_OTS_WP005_Core4_10PartnerCountries_Monthly_2019-01_to_2026-06_Raw_2026-08-26.json
A9: W5Q01 | B9: 8 | C9: 201901 | D9: 61091000 | E9: 690 | F9: 3 | G9: 0 | H9: 907773 | I9: 129933 | J9: 2130290 | K9: EXT_HMRC_OTS_WP005_Core4_10PartnerCountries_Monthly_2019-01_to_2026-06_Raw_2026-08-26.json
A10: W5Q01 | B10: 9 | C10: 201901 | D10: 61091000 | E10: 696 | F10: 3 | G10: 0 | H10: 596102 | I10: 116043 | J10: 1625044 | K10: EXT_HMRC_OTS_WP005_Core4_10PartnerCountries_Monthly_2019-01_to_2026-06_Raw_2026-08-26.json
A11: W5Q01 | B11: 10 | C11: 201901 | D11: 61091000 | E11: 720 | F11: 3 | G11: 0 | H11: 2250468 | I11: 421440 | J11: 7421237 | K11: EXT_HMRC_OTS_WP005_Core4_10PartnerCountries_Monthly_2019-01_to_2026-06_Raw_2026-08-26.json
A12: W5Q01 | B12: 11 | C12: 201901 | D12: 61103099 | E12: 52 | F12: 3 | G12: 0 | H12: 1619995 | I12: 514509 | J12: 9735289 | K12: EXT_HMRC_OTS_WP005_Core4_10PartnerCountries_Monthly_2019-01_to_2026-06_Raw_2026-08-26.json
A13: W5Q01 | B13: 12 | C13: 201901 | D13: 61103099 | E13: 204 | F13: 3 | G13: 0 | H13: 63819 | I13: 21338 | J13: 425648 | K13: EXT_HMRC_OTS_WP005_Core4_10PartnerCountries_Monthly_2019-01_to_2026-06_Raw_2026-08-26.json
... A3589: W5Q01 | B3589: 3588 | C3589: 202606 | D3589: 62052000 | E3589: 720 | F3589: 3 | G3589: 0 | H3589: 133261 | I3589: 44185 | J3589: 824050 | K3589: EXT_HMRC_OTS_WP005_Core4_10PartnerCountries_Monthly_2019-01_to_2026-06_Raw_2026-08-26.json

Sheet raw_world_monthly
A1: source_query_id | B1: source_record_no | C1: month_id | D1: commodity_id | E1: flow_type_id | F1: suppression_index | G1: supp_unit | H1: net_mass | I1: value_gbp | J1: source_file
A2: W5Q02 | B2: 1 | C2: 201901 | D2: 61091000 | E2: 1 | F2: 0 | G2: 6244608 | H2: 1481908 | I2: 35985209 | J2: EXT_HMRC_OTS_WP005_Core4_World_Monthly_2019-01_to_2026-06_Raw_2026-08-26.json
A3: W5Q02 | B3: 2 | C3: 201901 | D3: 61091000 | E3: 3 | F3: 0 | G3: 38767222 | H3: 6093137 | I3: 80208250 | J3: EXT_HMRC_OTS_WP005_Core4_World_Monthly_2019-01_to_2026-06_Raw_2026-08-26.json
A4: W5Q02 | B4: 3 | C4: 201901 | D4: 61103099 | E4: 1 | F4: 0 | G4: 1405722 | H4: 576538 | I4: 13578781 | J4: EXT_HMRC_OTS_WP005_Core4_World_Monthly_2019-01_to_2026-06_Raw_2026-08-26.json
A5: W5Q02 | B5: 4 | C5: 201901 | D5: 61103099 | E5: 3 | F5: 0 | G5: 9119844 | H5: 3055918 | I5: 47371893 | J5: EXT_HMRC_OTS_WP005_Core4_World_Monthly_2019-01_to_2026-06_Raw_2026-08-26.json
A6: W5Q02 | B6: 5 | C6: 201901 | D6: 62044300 | E6: 1 | F6: 0 | G6: 825232 | H6: 370783 | I6: 12076146 | J6: EXT_HMRC_OTS_WP005_Core4_World_Monthly_2019-01_to_2026-06_Raw_2026-08-26.json
A7: W5Q02 | B7: 6 | C7: 201901 | D7: 62044300 | E7: 3 | F7: 0 | G7: 3192668 | H7: 1052946 | I7: 29720603 | J7: EXT_HMRC_OTS_WP005_Core4_World_Monthly_2019-01_to_2026-06_Raw_2026-08-26.json
A8: W5Q02 | B8: 7 | C8: 201901 | D8: 62052000 | E8: 1 | F8: 0 | G8: 642842 | H8: 247078 | I8: 11020709 | J8: EXT_HMRC_OTS_WP005_Core4_World_Monthly_2019-01_to_2026-06_Raw_2026-08-26.json
A9: W5Q02 | B9: 8 | C9: 201901 | D9: 62052000 | E9: 3 | F9: 0 | G9: 4548480 | H9: 1380647 | I9: 27996728 | J9: EXT_HMRC_OTS_WP005_Core4_World_Monthly_2019-01_to_2026-06_Raw_2026-08-26.json
A10: W5Q02 | B10: 9 | C10: 201902 | D10: 61091000 | E10: 1 | F10: 0 | G10: 5912322 | H10: 1388810 | I10: 36142839 | J10: EXT_HMRC_OTS_WP005_Core4_World_Monthly_2019-01_to_2026-06_Raw_2026-08-26.json
A11: W5Q02 | B11: 10 | C11: 201902 | D11: 61091000 | E11: 3 | F11: 0 | G11: 39948795 | H11: 6198768 | I11: 75712600 | J11: EXT_HMRC_OTS_WP005_Core4_World_Monthly_2019-01_to_2026-06_Raw_2026-08-26.json
A12: W5Q02 | B12: 11 | C12: 201902 | D12: 61103099 | E12: 1 | F12: 0 | G12: 1028059 | H12: 381789 | I12: 9258019 | J12: EXT_HMRC_OTS_WP005_Core4_World_Monthly_2019-01_to_2026-06_Raw_2026-08-26.json
A13: W5Q02 | B13: 12 | C13: 201902 | D13: 61103099 | E13: 3 | F13: 0 | G13: 5550700 | H13: 1785137 | I13: 26284848 | J13: EXT_HMRC_OTS_WP005_Core4_World_Monthly_2019-01_to_2026-06_Raw_2026-08-26.json
... A721: W5Q02 | B721: 720 | C721: 202606 | D721: 62052000 | E721: 3 | F721: 0 | G721: 1767724 | H721: 592015 | I721: 12257949 | J721: EXT_HMRC_OTS_WP005_Core4_World_Monthly_2019-01_to_2026-06_Raw_2026-08-26.json

Sheet fct_partner_monthly
A1: monthly_import_key | B1: month_date | C1: month_id | D1: calendar_year | E1: calendar_month | F1: cn8_code | G1: hs4_code | H1: partner_country_id | I1: partner_country_iso2 | J1: partner_country_name | K1: flow | L1: flow_type_id | M1: api_row_present_flag | N1: record_status | O1: suppression_index_list | P1: suppression_flag | Q1: import_value_gbp | R1: net_mass_kg | S1: supplementary_quantity | T1: mass_status | U1: unit_value_gbp_per_kg | V1: world_import_value_gbp | W1: partner_value_share | X1: source_query_id | Y1: source_file | Z1: reference_median_unit_value_gbp_per_kg | AA1: unit_value_ratio_to_reference_median | AB1: unit_value_review_flag_2_5x
A2: 61091000_TR_201901_IMPORT | B2: 43466 | C2: 201901 | D2: 2019 | E2: 1 | F2: 61091000 | G2: 6109 | H2: 52 | I2: TR | J2: Turkey | K2: IMPORT | L2: 3 | M2: 1 | N2: REPORTED | O2: 0 | P2: 0 | Q2: 11803255 | R2: 583502 | S2: 3275398 | T2: USABLE | U2: =IF(R2>0,Q2/R2,"") -> 20.228303 | V2: =SUMIFS(fct_world_monthly!$J$2:$J$361,fct_world_monthly!$C$2:$C$361,C2,fct_world_monthly!$F$2:$F$361,F2) -> 116193459 | W2: =IF(V2>0,Q2/V2,"") -> 0.10158278 | X2: W5Q01 | Y2: EXT_HMRC_OTS_WP005_Core4_10PartnerCountries_Monthly_2019-01_to_2026-06_Raw_2026-08-26.json | Z2: =IF(U2="","",SUMIFS(Unit_Value_Review_QC!$K$10:$K$53,Unit_Value_Review_QC!$I$10:$I$53,"PARTNER|"&F2&"|"&I2)) -> 20.461445 | AA2: =IFERROR(U2/Z2,"") -> 0.98860578 | AB2: =IF(OR(N2<>"REPORTED",U2=""),"NOT_APPLICABLE",IF(OR(AA2<Unit_Value_Review_QC!$I$6,AA2>Unit_Value_Review_QC!$I$5),"REVIEW","WITHIN_BAND")) -> WITHIN_BAND
A3: 61091000_MA_201901_IMPORT | B3: 43466 | C3: 201901 | D3: 2019 | E3: 1 | F3: 61091000 | G3: 6109 | H3: 204 | I3: MA | J3: Morocco | K3: IMPORT | L3: 3 | M3: 1 | N3: REPORTED | O3: 0 | P3: 0 | Q3: 585401 | R3: 65037 | S3: 419760 | T3: USABLE | U3: =IF(R3>0,Q3/R3,"") -> 9.0010456 | V3: =SUMIFS(fct_world_monthly!$J$2:$J$361,fct_world_monthly!$C$2:$C$361,C3,fct_world_monthly!$F$2:$F$361,F3) -> 116193459 | W3: =IF(V3>0,Q3/V3,"") -> 0.005038158 | X3: W5Q01 | Y3: EXT_HMRC_OTS_WP005_Core4_10PartnerCountries_Monthly_2019-01_to_2026-06_Raw_2026-08-26.json | Z3: =IF(U3="","",SUMIFS(Unit_Value_Review_QC!$K$10:$K$53,Unit_Value_Review_QC!$I$10:$I$53,"PARTNER|"&F3&"|"&I3)) -> 7.8392981 | AA3: =IFERROR(U3/Z3,"") -> 1.1481953 | AB3: =IF(OR(N3<>"REPORTED",U3=""),"NOT_APPLICABLE",IF(OR(AA3<Unit_Value_Review_QC!$I$6,AA3>Unit_Value_Review_QC!$I$5),"REVIEW","WITHIN_BAND")) -> WITHIN_BAND
A4: 61091000_PK_201901_IMPORT | B4: 43466 | C4: 201901 | D4: 2019 | E4: 1 | F4: 61091000 | G4: 6109 | H4: 662 | I4: PK | J4: Pakistan | K4: IMPORT | L4: 3 | M4: 1 | N4: REPORTED | O4: 0 | P4: 0 | Q4: 2434227 | R4: 237071 | S4: 876746 | T4: USABLE | U4: =IF(R4>0,Q4/R4,"") -> 10.267924 | V4: =SUMIFS(fct_world_monthly!$J$2:$J$361,fct_world_monthly!$C$2:$C$361,C4,fct_world_monthly!$F$2:$F$361,F4) -> 116193459 | W4: =IF(V4>0,Q4/V4,"") -> 0.020949777 | X4: W5Q01 | Y4: EXT_HMRC_OTS_WP005_Core4_10PartnerCountries_Monthly_2019-01_to_2026-06_Raw_2026-08-26.json | Z4: =IF(U4="","",SUMIFS(Unit_Value_Review_QC!$K$10:$K$53,Unit_Value_Review_QC!$I$10:$I$53,"PARTNER|"&F4&"|"&I4)) -> 10.235891 | AA4: =IFERROR(U4/Z4,"") -> 1.0031294 | AB4: =IF(OR(N4<>"REPORTED",U4=""),"NOT_APPLICABLE",IF(OR(AA4<Unit_Value_Review_QC!$I$6,AA4>Unit_Value_Review_QC!$I$5),"REVIEW","WITHIN_BAND")) -> WITHIN_BAND
A5: 61091000_IN_201901_IMPORT | B5: 43466 | C5: 201901 | D5: 2019 | E5: 1 | F5: 61091000 | G5: 6109 | H5: 664 | I5: IN | J5: India | K5: IMPORT | L5: 3 | M5: 1 | N5: REPORTED | O5: 0 | P5: 0 | Q5: 11462560 | R5: 809198 | S5: 5479197 | T5: USABLE | U5: =IF(R5>0,Q5/R5,"") -> 14.165334 | V5: =SUMIFS(fct_world_monthly!$J$2:$J$361,fct_world_monthly!$C$2:$C$361,C5,fct_world_monthly!$F$2:$F$361,F5) -> 116193459 | W5: =IF(V5>0,Q5/V5,"") -> 0.098650648 | X5: W5Q01 | Y5: EXT_HMRC_OTS_WP005_Core4_10PartnerCountries_Monthly_2019-01_to_2026-06_Raw_2026-08-26.json | Z5: =IF(U5="","",SUMIFS(Unit_Value_Review_QC!$K$10:$K$53,Unit_Value_Review_QC!$I$10:$I$53,"PARTNER|"&F5&"|"&I5)) -> 13.59406 | AA5: =IFERROR(U5/Z5,"") -> 1.0420238 | AB5: =IF(OR(N5<>"REPORTED",U5=""),"NOT_APPLICABLE",IF(OR(AA5<Unit_Value_Review_QC!$I$6,AA5>Unit_Value_Review_QC!$I$5),"REVIEW","WITHIN_BAND")) -> WITHIN_BAND
A6: 61091000_BD_201901_IMPORT | B6: 43466 | C6: 201901 | D6: 2019 | E6: 1 | F6: 61091000 | G6: 6109 | H6: 666 | I6: BD | J6: Bangladesh | K6: IMPORT | L6: 3 | M6: 1 | N6: REPORTED | O6: 0 | P6: 0 | Q6: 31071303 | R6: 3063058 | S6: 20912727 | T6: USABLE | U6: =IF(R6>0,Q6/R6,"") -> 10.143883 | V6: =SUMIFS(fct_world_monthly!$J$2:$J$361,fct_world_monthly!$C$2:$C$361,C6,fct_world_monthly!$F$2:$F$361,F6) -> 116193459 | W6: =IF(V6>0,Q6/V6,"") -> 0.26741009 | X6: W5Q01 | Y6: EXT_HMRC_OTS_WP005_Core4_10PartnerCountries_Monthly_2019-01_to_2026-06_Raw_2026-08-26.json | Z6: =IF(U6="","",SUMIFS(Unit_Value_Review_QC!$K$10:$K$53,Unit_Value_Review_QC!$I$10:$I$53,"PARTNER|"&F6&"|"&I6)) -> 10.323148 | AA6: =IFERROR(U6/Z6,"") -> 0.98263474 | AB6: =IF(OR(N6<>"REPORTED",U6=""),"NOT_APPLICABLE",IF(OR(AA6<Unit_Value_Review_QC!$I$6,AA6>Unit_Value_Review_QC!$I$5),"REVIEW","WITHIN_BAND")) -> WITHIN_BAND
A7: 61091000_LK_201901_IMPORT | B7: 43466 | C7: 201901 | D7: 2019 | E7: 1 | F7: 61091000 | G7: 6109 | H7: 669 | I7: LK | J7: Sri Lanka | K7: IMPORT | L7: 3 | M7: 1 | N7: REPORTED | O7: 0 | P7: 0 | Q7: 2899724 | R7: 195374 | S7: 1425640 | T7: USABLE | U7: =IF(R7>0,Q7/R7,"") -> 14.841913 | V7: =SUMIFS(fct_world_monthly!$J$2:$J$361,fct_world_monthly!$C$2:$C$361,C7,fct_world_monthly!$F$2:$F$361,F7) -> 116193459 | W7: =IF(V7>0,Q7/V7,"") -> 0.024956 | X7: W5Q01 | Y7: EXT_HMRC_OTS_WP005_Core4_10PartnerCountries_Monthly_2019-01_to_2026-06_Raw_2026-08-26.json | Z7: =IF(U7="","",SUMIFS(Unit_Value_Review_QC!$K$10:$K$53,Unit_Value_Review_QC!$I$10:$I$53,"PARTNER|"&F7&"|"&I7)) -> 13.552232 | AA7: =IFERROR(U7/Z7,"") -> 1.0951638 | AB7: =IF(OR(N7<>"REPORTED",U7=""),"NOT_APPLICABLE",IF(OR(AA7<Unit_Value_Review_QC!$I$6,AA7>Unit_Value_Review_QC!$I$5),"REVIEW","WITHIN_BAND")) -> WITHIN_BAND
A8: 61091000_MM_201901_IMPORT | B8: 43466 | C8: 201901 | D8: 2019 | E8: 1 | F8: 61091000 | G8: 6109 | H8: 676 | I8: MM | J8: Myanmar | K8: IMPORT | L8: 3 | M8: 1 | N8: REPORTED | O8: 0 | P8: 0 | Q8: 130735 | R8: 8991 | S8: 72843 | T8: USABLE | U8: =IF(R8>0,Q8/R8,"") -> 14.540652 | V8: =SUMIFS(fct_world_monthly!$J$2:$J$361,fct_world_monthly!$C$2:$C$361,C8,fct_world_monthly!$F$2:$F$361,F8) -> 116193459 | W8: =IF(V8>0,Q8/V8,"") -> 0.0011251494 | X8: W5Q01 | Y8: EXT_HMRC_OTS_WP005_Core4_10PartnerCountries_Monthly_2019-01_to_2026-06_Raw_2026-08-26.json | Z8: =IF(U8="","",SUMIFS(Unit_Value_Review_QC!$K$10:$K$53,Unit_Value_Review_QC!$I$10:$I$53,"PARTNER|"&F8&"|"&I8)) -> 16.294942 | AA8: =IFERROR(U8/Z8,"") -> 0.89234142 | AB8: =IF(OR(N8<>"REPORTED",U8=""),"NOT_APPLICABLE",IF(OR(AA8<Unit_Value_Review_QC!$I$6,AA8>Unit_Value_Review_QC!$I$5),"REVIEW","WITHIN_BAND")) -> WITHIN_BAND
A9: 61091000_VN_201901_IMPORT | B9: 43466 | C9: 201901 | D9: 2019 | E9: 1 | F9: 61091000 | G9: 6109 | H9: 690 | I9: VN | J9: Vietnam | K9: IMPORT | L9: 3 | M9: 1 | N9: REPORTED | O9: 0 | P9: 0 | Q9: 2130290 | R9: 129933 | S9: 907773 | T9: USABLE | U9: =IF(R9>0,Q9/R9,"") -> 16.395296 | V9: =SUMIFS(fct_world_monthly!$J$2:$J$361,fct_world_monthly!$C$2:$C$361,C9,fct_world_monthly!$F$2:$F$361,F9) -> 116193459 | W9: =IF(V9>0,Q9/V9,"") -> 0.018333992 | X9: W5Q01 | Y9: EXT_HMRC_OTS_WP005_Core4_10PartnerCountries_Monthly_2019-01_to_2026-06_Raw_2026-08-26.json | Z9: =IF(U9="","",SUMIFS(Unit_Value_Review_QC!$K$10:$K$53,Unit_Value_Review_QC!$I$10:$I$53,"PARTNER|"&F9&"|"&I9)) -> 21.029827 | AA9: =IFERROR(U9/Z9,"") -> 0.77962106 | AB9: =IF(OR(N9<>"REPORTED",U9=""),"NOT_APPLICABLE",IF(OR(AA9<Unit_Value_Review_QC!$I$6,AA9>Unit_Value_Review_QC!$I$5),"REVIEW","WITHIN_BAND")) -> WITHIN_BAND
A10: 61091000_KH_201901_IMPORT | B10: 43466 | C10: 201901 | D10: 2019 | E10: 1 | F10: 61091000 | G10: 6109 | H10: 696 | I10: KH | J10: Cambodia | K10: IMPORT | L10: 3 | M10: 1 | N10: REPORTED | O10: 0 | P10: 0 | Q10: 1625044 | R10: 116043 | S10: 596102 | T10: USABLE | U10: =IF(R10>0,Q10/R10,"") -> 14.003809 | V10: =SUMIFS(fct_world_monthly!$J$2:$J$361,fct_world_monthly!$C$2:$C$361,C10,fct_world_monthly!$F$2:$F$361,F10) -> 116193459 | W10: =IF(V10>0,Q10/V10,"") -> 0.013985675 | X10: W5Q01 | Y10: EXT_HMRC_OTS_WP005_Core4_10PartnerCountries_Monthly_2019-01_to_2026-06_Raw_2026-08-26.json | Z10: =IF(U10="","",SUMIFS(Unit_Value_Review_QC!$K$10:$K$53,Unit_Value_Review_QC!$I$10:$I$53,"PARTNER|"&F10&"|"&I10)) -> 18.091181 | AA10: =IFERROR(U10/Z10,"") -> 0.77406824 | AB10: =IF(OR(N10<>"REPORTED",U10=""),"NOT_APPLICABLE",IF(OR(AA10<Unit_Value_Review_QC!$I$6,AA10>Unit_Value_Review_QC!$I$5),"REVIEW","WITHIN_BAND")) -> WITHIN_BAND
A11: 61091000_CN_201901_IMPORT | B11: 43466 | C11: 201901 | D11: 2019 | E11: 1 | F11: 61091000 | G11: 6109 | H11: 720 | I11: CN | J11: China | K11: IMPORT | L11: 3 | M11: 1 | N11: REPORTED | O11: 0 | P11: 0 | Q11: 7421237 | R11: 421440 | S11: 2250468 | T11: USABLE | U11: =IF(R11>0,Q11/R11,"") -> 17.609237 | V11: =SUMIFS(fct_world_monthly!$J$2:$J$361,fct_world_monthly!$C$2:$C$361,C11,fct_world_monthly!$F$2:$F$361,F11) -> 116193459 | W11: =IF(V11>0,Q11/V11,"") -> 0.063869662 | X11: W5Q01 | Y11: EXT_HMRC_OTS_WP005_Core4_10PartnerCountries_Monthly_2019-01_to_2026-06_Raw_2026-08-26.json | Z11: =IF(U11="","",SUMIFS(Unit_Value_Review_QC!$K$10:$K$53,Unit_Value_Review_QC!$I$10:$I$53,"PARTNER|"&F11&"|"&I11)) -> 18.213915 | AA11: =IFERROR(U11/Z11,"") -> 0.96680133 | AB11: =IF(OR(N11<>"REPORTED",U11=""),"NOT_APPLICABLE",IF(OR(AA11<Unit_Value_Review_QC!$I$6,AA11>Unit_Value_Review_QC!$I$5),"REVIEW","WITHIN_BAND")) -> WITHIN_BAND
A12: 61103099_TR_201901_IMPORT | B12: 43466 | C12: 201901 | D12: 2019 | E12: 1 | F12: 61103099 | G12: 6110 | H12: 52 | I12: TR | J12: Turkey | K12: IMPORT | L12: 3 | M12: 1 | N12: REPORTED | O12: 0 | P12: 0 | Q12: 9735289 | R12: 514509 | S12: 1619995 | T12: USABLE | U12: =IF(R12>0,Q12/R12,"") -> 18.921514 | V12: =SUMIFS(fct_world_monthly!$J$2:$J$361,fct_world_monthly!$C$2:$C$361,C12,fct_world_monthly!$F$2:$F$361,F12) -> 60950674 | W12: =IF(V12>0,Q12/V12,"") -> 0.15972406 | X12: W5Q01 | Y12: EXT_HMRC_OTS_WP005_Core4_10PartnerCountries_Monthly_2019-01_to_2026-06_Raw_2026-08-26.json | Z12: =IF(U12="","",SUMIFS(Unit_Value_Review_QC!$K$10:$K$53,Unit_Value_Review_QC!$I$10:$I$53,"PARTNER|"&F12&"|"&I12)) -> 19.213268 | AA12: =IFERROR(U12/Z12,"") -> 0.98481494 | AB12: =IF(OR(N12<>"REPORTED",U12=""),"NOT_APPLICABLE",IF(OR(AA12<Unit_Value_Review_QC!$I$6,AA12>Unit_Value_Review_QC!$I$5),"REVIEW","WITHIN_BAND")) -> WITHIN_BAND
A13: 61103099_MA_201901_IMPORT | B13: 43466 | C13: 201901 | D13: 2019 | E13: 1 | F13: 61103099 | G13: 6110 | H13: 204 | I13: MA | J13: Morocco | K13: IMPORT | L13: 3 | M13: 1 | N13: REPORTED | O13: 0 | P13: 0 | Q13: 425648 | R13: 21338 | S13: 63819 | T13: USABLE | U13: =IF(R13>0,Q13/R13,"") -> 19.947886 | V13: =SUMIFS(fct_world_monthly!$J$2:$J$361,fct_world_monthly!$C$2:$C$361,C13,fct_world_monthly!$F$2:$F$361,F13) -> 60950674 | W13: =IF(V13>0,Q13/V13,"") -> 0.0069834831 | X13: W5Q01 | Y13: EXT_HMRC_OTS_WP005_Core4_10PartnerCountries_Monthly_2019-01_to_2026-06_Raw_2026-08-26.json | Z13: =IF(U13="","",SUMIFS(Unit_Value_Review_QC!$K$10:$K$53,Unit_Value_Review_QC!$I$10:$I$53,"PARTNER|"&F13&"|"&I13)) -> 16.024819 | AA13: =IFERROR(U13/Z13,"") -> 1.244812 | AB13: =IF(OR(N13<>"REPORTED",U13=""),"NOT_APPLICABLE",IF(OR(AA13<Unit_Value_Review_QC!$I$6,AA13>Unit_Value_Review_QC!$I$5),"REVIEW","WITHIN_BAND")) -> WITHIN_BAND
... A612: 61103099_TR_202004_IMPORT | B612: 43922 | C612: 202004 | D612: 2020 | E612: 4 | F612: 61103099 | G612: 6110 | H612: 52 | I612: TR | J612: Turkey | K612: IMPORT | L612: 3 | M612: 1 | N612: REPORTED | O612: 0 | P612: 0 | Q612: 767299 | R612: 37826 | S612: 146605 | T612: USABLE | U612: =IF(R612>0,Q612/R612,"") -> 20.284963 | V612: =SUMIFS(fct_world_monthly!$J$2:$J$361,fct_world_monthly!$C$2:$C$361,C612,fct_world_monthly!$F$2:$F$361,F612) -> 10416097 | W612: =IF(V612>0,Q612/V612,"") -> 0.073664733 | X612: W5Q01 | Y612: EXT_HMRC_OTS_WP005_Core4_10PartnerCountries_Monthly_2019-01_to_2026-06_Raw_2026-08-26.json | Z612: =IF(U612="","",SUMIFS(Unit_Value_Review_QC!$K$10:$K$53,Unit_Value_Review_QC!$I$10:$I$53,"PARTNER|"&F612&"|"&I612)) -> 19.213268 | AA612: =IFERROR(U612/Z612,"") -> 1.0557789 | AB612: =IF(OR(N612<>"REPORTED",U612=""),"NOT_APPLICABLE",IF(OR(AA612<Unit_Value_Review_QC!$I$6,AA612>Unit_Value_Review_QC!$I$5),"REVIEW","WITHIN_BAND")) -> WITHIN_BAND
A613: 61103099_MA_202004_IMPORT | B613: 43922 | C613: 202004 | D613: 2020 | E613: 4 | F613: 61103099 | G613: 6110 | H613: 204 | I613: MA | J613: Morocco | K613: IMPORT | L613: 3 | M613: 0 | N613: NO_API_RECORD | P613: 0 | Q613: 0 | R613: 0 | S613: 0 | T613: NO_REPORTED_TRADE | U613: =IF(R613>0,Q613/R613,"") | V613: =SUMIFS(fct_world_monthly!$J$2:$J$361,fct_world_monthly!$C$2:$C$361,C613,fct_world_monthly!$F$2:$F$361,F613) -> 10416097 | W613: =IF(V613>0,Q613/V613,"") -> 0 | X613: W5Q01 | Y613: EXT_HMRC_OTS_WP005_Core4_10PartnerCountries_Monthly_2019-01_to_2026-06_Raw_2026-08-26.json | Z613: =IF(U613="","",SUMIFS(Unit_Value_Review_QC!$K$10:$K$53,Unit_Value_Review_QC!$I$10:$I$53,"PARTNER|"&F613&"|"&I613)) | AA613: =IFERROR(U613/Z613,"") | AB613: =IF(OR(N613<>"REPORTED",U613=""),"NOT_APPLICABLE",IF(OR(AA613<Unit_Value_Review_QC!$I$6,AA613>Unit_Value_Review_QC!$I$5),"REVIEW","WITHIN_BAND")) -> NOT_APPLICABLE
A614: 61103099_PK_202004_IMPORT | B614: 43922 | C614: 202004 | D614: 2020 | E614: 4 | F614: 61103099 | G614: 6110 | H614: 662 | I614: PK | J614: Pakistan | K614: IMPORT | L614: 3 | M614: 1 | N614: REPORTED | O614: 0 | P614: 0 | Q614: 261060 | R614: 17126 | S614: 53707 | T614: USABLE | U614: =IF(R614>0,Q614/R614,"") -> 15.243489 | V614: =SUMIFS(fct_world_monthly!$J$2:$J$361,fct_world_monthly!$C$2:$C$361,C614,fct_world_monthly!$F$2:$F$361,F614) -> 10416097 | W614: =IF(V614>0,Q614/V614,"") -> 0.025063131 | X614: W5Q01 | Y614: EXT_HMRC_OTS_WP005_Core4_10PartnerCountries_Monthly_2019-01_to_2026-06_Raw_2026-08-26.json | Z614: =IF(U614="","",SUMIFS(Unit_Value_Review_QC!$K$10:$K$53,Unit_Value_Review_QC!$I$10:$I$53,"PARTNER|"&F614&"|"&I614)) -> 13.240688 | AA614: =IFERROR(U614/Z614,"") -> 1.1512611 | AB614: =IF(OR(N614<>"REPORTED",U614=""),"NOT_APPLICABLE",IF(OR(AA614<Unit_Value_Review_QC!$I$6,AA614>Unit_Value_Review_QC!$I$5),"REVIEW","WITHIN_BAND")) -> WITHIN_BAND
A615: 61103099_IN_202004_IMPORT | B615: 43922 | C615: 202004 | D615: 2020 | E615: 4 | F615: 61103099 | G615: 6110 | H615: 664 | I615: IN | J615: India | K615: IMPORT | L615: 3 | M615: 1 | N615: REPORTED | O615: 0 | P615: 0 | Q615: 150405 | R615: 17414 | S615: 41324 | T615: USABLE | U615: =IF(R615>0,Q615/R615,"") -> 8.6370162 | V615: =SUMIFS(fct_world_monthly!$J$2:$J$361,fct_world_monthly!$C$2:$C$361,C615,fct_world_monthly!$F$2:$F$361,F615) -> 10416097 | W615: =IF(V615>0,Q615/V615,"") -> 0.01443967 | X615: W5Q01 | Y615: EXT_HMRC_OTS_WP005_Core4_10PartnerCountries_Monthly_2019-01_to_2026-06_Raw_2026-08-26.json | Z615: =IF(U615="","",SUMIFS(Unit_Value_Review_QC!$K$10:$K$53,Unit_Value_Review_QC!$I$10:$I$53,"PARTNER|"&F615&"|"&I615)) -> 13.033767 | AA615: =IFERROR(U615/Z615,"") -> 0.66266461 | AB615: =IF(OR(N615<>"REPORTED",U615=""),"NOT_APPLICABLE",IF(OR(AA615<Unit_Value_Review_QC!$I$6,AA615>Unit_Value_Review_QC!$I$5),"REVIEW","WITHIN_BAND")) -> WITHIN_BAND
A616: 61103099_BD_202004_IMPORT | B616: 43922 | C616: 202004 | D616: 2020 | E616: 4 | F616: 61103099 | G616: 6110 | H616: 666 | I616: BD | J616: Bangladesh | K616: IMPORT | L616: 3 | M616: 1 | N616: REPORTED | O616: 0 | P616: 0 | Q616: 2706858 | R616: 171581 | S616: 565280 | T616: USABLE | U616: =IF(R616>0,Q616/R616,"") -> 15.775978 | V616: =SUMIFS(fct_world_monthly!$J$2:$J$361,fct_world_monthly!$C$2:$C$361,C616,fct_world_monthly!$F$2:$F$361,F616) -> 10416097 | W616: =IF(V616>0,Q616/V616,"") -> 0.25987258 | X616: W5Q01 | Y616: EXT_HMRC_OTS_WP005_Core4_10PartnerCountries_Monthly_2019-01_to_2026-06_Raw_2026-08-26.json | Z616: =IF(U616="","",SUMIFS(Unit_Value_Review_QC!$K$10:$K$53,Unit_Value_Review_QC!$I$10:$I$53,"PARTNER|"&F616&"|"&I616)) -> 12.503788 | AA616: =IFERROR(U616/Z616,"") -> 1.2616958 | AB616: =IF(OR(N616<>"REPORTED",U616=""),"NOT_APPLICABLE",IF(OR(AA616<Unit_Value_Review_QC!$I$6,AA616>Unit_Value_Review_QC!$I$5),"REVIEW","WITHIN_BAND")) -> WITHIN_BAND
A617: 61103099_LK_202004_IMPORT | B617: 43922 | C617: 202004 | D617: 2020 | E617: 4 | F617: 61103099 | G617: 6110 | H617: 669 | I617: LK | J617: Sri Lanka | K617: IMPORT | L617: 3 | M617: 1 | N617: REPORTED | O617: 0 | P617: 0 | Q617: 98215 | R617: 4439 | S617: 19915 | T617: USABLE | U617: =IF(R617>0,Q617/R617,"") -> 22.125479 | V617: =SUMIFS(fct_world_monthly!$J$2:$J$361,fct_world_monthly!$C$2:$C$361,C617,fct_world_monthly!$F$2:$F$361,F617) -> 10416097 | W617: =IF(V617>0,Q617/V617,"") -> 0.0094291557 | X617: W5Q01 | Y617: EXT_HMRC_OTS_WP005_Core4_10PartnerCountries_Monthly_2019-01_to_2026-06_Raw_2026-08-26.json | Z617: =IF(U617="","",SUMIFS(Unit_Value_Review_QC!$K$10:$K$53,Unit_Value_Review_QC!$I$10:$I$53,"PARTNER|"&F617&"|"&I617)) -> 16.584044 | AA617: =IFERROR(U617/Z617,"") -> 1.3341426 | AB617: =IF(OR(N617<>"REPORTED",U617=""),"NOT_APPLICABLE",IF(OR(AA617<Unit_Value_Review_QC!$I$6,AA617>Unit_Value_Review_QC!$I$5),"REVIEW","WITHIN_BAND")) -> WITHIN_BAND
A618: 61103099_MM_202004_IMPORT | B618: 43922 | C618: 202004 | D618: 2020 | E618: 4 | F618: 61103099 | G618: 6110 | H618: 676 | I618: MM | J618: Myanmar | K618: IMPORT | L618: 3 | M618: 1 | N618: REPORTED | O618: 0 | P618: 0 | Q618: 904458 | R618: 110916 | S618: 272243 | T618: USABLE | U618: =IF(R618>0,Q618/R618,"") -> 8.1544412 | V618: =SUMIFS(fct_world_monthly!$J$2:$J$361,fct_world_monthly!$C$2:$C$361,C618,fct_world_monthly!$F$2:$F$361,F618) -> 10416097 | W618: =IF(V618>0,Q618/V618,"") -> 0.086832717 | X618: W5Q01 | Y618: EXT_HMRC_OTS_WP005_Core4_10PartnerCountries_Monthly_2019-01_to_2026-06_Raw_2026-08-26.json | Z618: =IF(U618="","",SUMIFS(Unit_Value_Review_QC!$K$10:$K$53,Unit_Value_Review_QC!$I$10:$I$53,"PARTNER|"&F618&"|"&I618)) -> 12.70545 | AA618: =IFERROR(U618/Z618,"") -> 0.64180654 | AB618: =IF(OR(N618<>"REPORTED",U618=""),"NOT_APPLICABLE",IF(OR(AA618<Unit_Value_Review_QC!$I$6,AA618>Unit_Value_Review_QC!$I$5),"REVIEW","WITHIN_BAND")) -> WITHIN_BAND
A619: 61103099_VN_202004_IMPORT | B619: 43922 | C619: 202004 | D619: 2020 | E619: 4 | F619: 61103099 | G619: 6110 | H619: 690 | I619: VN | J619: Vietnam | K619: IMPORT | L619: 3 | M619: 1 | N619: REPORTED | O619: 0 | P619: 0 | Q619: 207938 | R619: 7327 | S619: 28468 | T619: USABLE | U619: =IF(R619>0,Q619/R619,"") -> 28.379692 | V619: =SUMIFS(fct_world_monthly!$J$2:$J$361,fct_world_monthly!$C$2:$C$361,C619,fct_world_monthly!$F$2:$F$361,F619) -> 10416097 | W619: =IF(V619>0,Q619/V619,"") -> 0.01996314 | X619: W5Q01 | Y619: EXT_HMRC_OTS_WP005_Core4_10PartnerCountries_Monthly_2019-01_to_2026-06_Raw_2026-08-26.json | Z619: =IF(U619="","",SUMIFS(Unit_Value_Review_QC!$K$10:$K$53,Unit_Value_Review_QC!$I$10:$I$53,"PARTNER|"&F619&"|"&I619)) -> 23.234222 | AA619: =IFERROR(U619/Z619,"") -> 1.2214608 | AB619: =IF(OR(N619<>"REPORTED",U619=""),"NOT_APPLICABLE",IF(OR(AA619<Unit_Value_Review_QC!$I$6,AA619>Unit_Value_Review_QC!$I$5),"REVIEW","WITHIN_BAND")) -> WITHIN_BAND
A620: 61103099_KH_202004_IMPORT | B620: 43922 | C620: 202004 | D620: 2020 | E620: 4 | F620: 61103099 | G620: 6110 | H620: 696 | I620: KH | J620: Cambodia | K620: IMPORT | L620: 3 | M620: 1 | N620: REPORTED | O620: 0 | P620: 0 | Q620: 570988 | R620: 29089 | S620: 109818 | T620: USABLE | U620: =IF(R620>0,Q620/R620,"") -> 19.629001 | V620: =SUMIFS(fct_world_monthly!$J$2:$J$361,fct_world_monthly!$C$2:$C$361,C620,fct_world_monthly!$F$2:$F$361,F620) -> 10416097 | W620: =IF(V620>0,Q620/V620,"") -> 0.054817846 | X620: W5Q01 | Y620: EXT_HMRC_OTS_WP005_Core4_10PartnerCountries_Monthly_2019-01_to_2026-06_Raw_2026-08-26.json | Z620: =IF(U620="","",SUMIFS(Unit_Value_Review_QC!$K$10:$K$53,Unit_Value_Review_QC!$I$10:$I$53,"PARTNER|"&F620&"|"&I620)) -> 12.33939 | AA620: =IFERROR(U620/Z620,"") -> 1.5907594 | AB620: =IF(OR(N620<>"REPORTED",U620=""),"NOT_APPLICABLE",IF(OR(AA620<Unit_Value_Review_QC!$I$6,AA620>Unit_Value_Review_QC!$I$5),"REVIEW","WITHIN_BAND")) -> WITHIN_BAND
A621: 61103099_CN_202004_IMPORT | B621: 43922 | C621: 202004 | D621: 2020 | E621: 4 | F621: 61103099 | G621: 6110 | H621: 720 | I621: CN | J621: China | K621: IMPORT | L621: 3 | M621: 1 | N621: REPORTED | O621: 0 | P621: 0 | Q621: 1397383 | R621: 82987 | S621: 232477 | T621: USABLE | U621: =IF(R621>0,Q621/R621,"") -> 16.838577 | V621: =SUMIFS(fct_world_monthly!$J$2:$J$361,fct_world_monthly!$C$2:$C$361,C621,fct_world_monthly!$F$2:$F$361,F621) -> 10416097 | W621: =IF(V621>0,Q621/V621,"") -> 0.1341561 | X621: W5Q01 | Y621: EXT_HMRC_OTS_WP005_Core4_10PartnerCountries_Monthly_2019-01_to_2026-06_Raw_2026-08-26.json | Z621: =IF(U621="","",SUMIFS(Unit_Value_Review_QC!$K$10:$K$53,Unit_Value_Review_QC!$I$10:$I$53,"PARTNER|"&F621&"|"&I621)) -> 15.158853 | AA621: =IFERROR(U621/Z621,"") -> 1.1108082 | AB621: =IF(OR(N621<>"REPORTED",U621=""),"NOT_APPLICABLE",IF(OR(AA621<Unit_Value_Review_QC!$I$6,AA621>Unit_Value_Review_QC!$I$5),"REVIEW","WITHIN_BAND")) -> WITHIN_BAND
A622: 62044300_TR_202004_IMPORT | B622: 43922 | C622: 202004 | D622: 2020 | E622: 4 | F622: 62044300 | G622: 6204 | H622: 52 | I622: TR | J622: Turkey | K622: IMPORT | L622: 3 | M622: 1 | N622: REPORTED | O622: 0 | P622: 0 | Q622: 606218 | R622: 22721 | S622: 65702 | T622: USABLE | U622: =IF(R622>0,Q622/R622,"") -> 26.680956 | V622: =SUMIFS(fct_world_monthly!$J$2:$J$361,fct_world_monthly!$C$2:$C$361,C622,fct_world_monthly!$F$2:$F$361,F622) -> 13954909 | W622: =IF(V622>0,Q622/V622,"") -> 0.043441201 | X622: W5Q01 | Y622: EXT_HMRC_OTS_WP005_Core4_10PartnerCountries_Monthly_2019-01_to_2026-06_Raw_2026-08-26.json | Z622: =IF(U622="","",SUMIFS(Unit_Value_Review_QC!$K$10:$K$53,Unit_Value_Review_QC!$I$10:$I$53,"PARTNER|"&F622&"|"&I622)) -> 31.867133 | AA622: =IFERROR(U622/Z622,"") -> 0.83725624 | AB622: =IF(OR(N622<>"REPORTED",U622=""),"NOT_APPLICABLE",IF(OR(AA622<Unit_Value_Review_QC!$I$6,AA622>Unit_Value_Review_QC!$I$5),"REVIEW","WITHIN_BAND")) -> WITHIN_BAND
A623: 62044300_MA_202004_IMPORT | B623: 43922 | C623: 202004 | D623: 2020 | E623: 4 | F623: 62044300 | G623: 6204 | H623: 204 | I623: MA | J623: Morocco | K623: IMPORT | L623: 3 | M623: 1 | N623: REPORTED | O623: 0 | P623: 0 | Q623: 40113 | R623: 1513 | S623: 6727 | T623: USABLE | U623: =IF(R623>0,Q623/R623,"") -> 26.512227 | V623: =SUMIFS(fct_world_monthly!$J$2:$J$361,fct_world_monthly!$C$2:$C$361,C623,fct_world_monthly!$F$2:$F$361,F623) -> 13954909 | W623: =IF(V623>0,Q623/V623,"") -> 0.0028744723 | X623: W5Q01 | Y623: EXT_HMRC_OTS_WP005_Core4_10PartnerCountries_Monthly_2019-01_to_2026-06_Raw_2026-08-26.json | Z623: =IF(U623="","",SUMIFS(Unit_Value_Review_QC!$K$10:$K$53,Unit_Value_Review_QC!$I$10:$I$53,"PARTNER|"&F623&"|"&I623)) -> 19.682232 | AA623: =IFERROR(U623/Z623,"") -> 1.3470133 | AB623: =IF(OR(N623<>"REPORTED",U623=""),"NOT_APPLICABLE",IF(OR(AA623<Unit_Value_Review_QC!$I$6,AA623>Unit_Value_Review_QC!$I$5),"REVIEW","WITHIN_BAND")) -> WITHIN_BAND
A624: 62044300_PK_202004_IMPORT | B624: 43922 | C624: 202004 | D624: 2020 | E624: 4 | F624: 62044300 | G624: 6204 | H624: 662 | I624: PK | J624: Pakistan | K624: IMPORT | L624: 3 | M624: 1 | N624: REPORTED | O624: 0 | P624: 0 | Q624: 32231 | R624: 939 | S624: 7600 | T624: USABLE | U624: =IF(R624>0,Q624/R624,"") -> 34.324814 | V624: =SUMIFS(fct_world_monthly!$J$2:$J$361,fct_world_monthly!$C$2:$C$361,C624,fct_world_monthly!$F$2:$F$361,F624) -> 13954909 | W624: =IF(V624>0,Q624/V624,"") -> 0.0023096532 | X624: W5Q01 | Y624: EXT_HMRC_OTS_WP005_Core4_10PartnerCountries_Monthly_2019-01_to_2026-06_Raw_2026-08-26.json | Z624: =IF(U624="","",SUMIFS(Unit_Value_Review_QC!$K$10:$K$53,Unit_Value_Review_QC!$I$10:$I$53,"PARTNER|"&F624&"|"&I624)) -> 19.366411 | AA624: =IFERROR(U624/Z624,"") -> 1.772389 | AB624: =IF(OR(N624<>"REPORTED",U624=""),"NOT_APPLICABLE",IF(OR(AA624<Unit_Value_Review_QC!$I$6,AA624>Unit_Value_Review_QC!$I$5),"REVIEW","WITHIN_BAND")) -> WITHIN_BAND
A625: 62044300_IN_202004_IMPORT | B625: 43922 | C625: 202004 | D625: 2020 | E625: 4 | F625: 62044300 | G625: 6204 | H625: 664 | I625: IN | J625: India | K625: IMPORT | L625: 3 | M625: 1 | N625: REPORTED | O625: 0 | P625: 0 | Q625: 1254536 | R625: 50745 | S625: 220038 | T625: USABLE | U625: =IF(R625>0,Q625/R625,"") -> 24.722357 | V625: =SUMIFS(fct_world_monthly!$J$2:$J$361,fct_world_monthly!$C$2:$C$361,C625,fct_world_monthly!$F$2:$F$361,F625) -> 13954909 | W625: =IF(V625>0,Q625/V625,"") -> 0.089899261 | X625: W5Q01 | Y625: EXT_HMRC_OTS_WP005_Core4_10PartnerCountries_Monthly_2019-01_to_2026-06_Raw_2026-08-26.json | Z625: =IF(U625="","",SUMIFS(Unit_Value_Review_QC!$K$10:$K$53,Unit_Value_Review_QC!$I$10:$I$53,"PARTNER|"&F625&"|"&I625)) -> 29.827361 | AA625: =IFERROR(U625/Z625,"") -> 0.82884828 | AB625: =IF(OR(N625<>"REPORTED",U625=""),"NOT_APPLICABLE",IF(OR(AA625<Unit_Value_Review_QC!$I$6,AA625>Unit_Value_Review_QC!$I$5),"REVIEW","WITHIN_BAND")) -> WITHIN_BAND
... A632: 62052000_TR_202004_IMPORT | B632: 43922 | C632: 202004 | D632: 2020 | E632: 4 | F632: 62052000 | G632: 6205 | H632: 52 | I632: TR | J632: Turkey | K632: IMPORT | L632: 3 | M632: 1 | N632: REPORTED | O632: 0 | P632: 0 | Q632: 244355 | R632: 7688 | S632: 24809 | T632: USABLE | U632: =IF(R632>0,Q632/R632,"") -> 31.783949 | V632: =SUMIFS(fct_world_monthly!$J$2:$J$361,fct_world_monthly!$C$2:$C$361,C632,fct_world_monthly!$F$2:$F$361,F632) -> 16075495 | W632: =IF(V632>0,Q632/V632,"") -> 0.015200465 | X632: W5Q01 | Y632: EXT_HMRC_OTS_WP005_Core4_10PartnerCountries_Monthly_2019-01_to_2026-06_Raw_2026-08-26.json | Z632: =IF(U632="","",SUMIFS(Unit_Value_Review_QC!$K$10:$K$53,Unit_Value_Review_QC!$I$10:$I$53,"PARTNER|"&F632&"|"&I632)) -> 35.036767 | AA632: =IFERROR(U632/Z632,"") -> 0.90715988 | AB632: =IF(OR(N632<>"REPORTED",U632=""),"NOT_APPLICABLE",IF(OR(AA632<Unit_Value_Review_QC!$I$6,AA632>Unit_Value_Review_QC!$I$5),"REVIEW","WITHIN_BAND")) -> WITHIN_BAND
A633: 62052000_MA_202004_IMPORT | B633: 43922 | C633: 202004 | D633: 2020 | E633: 4 | F633: 62052000 | G633: 6205 | H633: 204 | I633: MA | J633: Morocco | K633: IMPORT | L633: 3 | M633: 0 | N633: NO_API_RECORD | P633: 0 | Q633: 0 | R633: 0 | S633: 0 | T633: NO_REPORTED_TRADE | U633: =IF(R633>0,Q633/R633,"") | V633: =SUMIFS(fct_world_monthly!$J$2:$J$361,fct_world_monthly!$C$2:$C$361,C633,fct_world_monthly!$F$2:$F$361,F633) -> 16075495 | W633: =IF(V633>0,Q633/V633,"") -> 0 | X633: W5Q01 | Y633: EXT_HMRC_OTS_WP005_Core4_10PartnerCountries_Monthly_2019-01_to_2026-06_Raw_2026-08-26.json | Z633: =IF(U633="","",SUMIFS(Unit_Value_Review_QC!$K$10:$K$53,Unit_Value_Review_QC!$I$10:$I$53,"PARTNER|"&F633&"|"&I633)) | AA633: =IFERROR(U633/Z633,"") | AB633: =IF(OR(N633<>"REPORTED",U633=""),"NOT_APPLICABLE",IF(OR(AA633<Unit_Value_Review_QC!$I$6,AA633>Unit_Value_Review_QC!$I$5),"REVIEW","WITHIN_BAND")) -> NOT_APPLICABLE
A634: 62052000_PK_202004_IMPORT | B634: 43922 | C634: 202004 | D634: 2020 | E634: 4 | F634: 62052000 | G634: 6205 | H634: 662 | I634: PK | J634: Pakistan | K634: IMPORT | L634: 3 | M634: 1 | N634: REPORTED | O634: 0 | P634: 0 | Q634: 27981 | R634: 2747 | S634: 10354 | T634: USABLE | U634: =IF(R634>0,Q634/R634,"") -> 10.186021 | V634: =SUMIFS(fct_world_monthly!$J$2:$J$361,fct_world_monthly!$C$2:$C$361,C634,fct_world_monthly!$F$2:$F$361,F634) -> 16075495 | W634: =IF(V634>0,Q634/V634,"") -> 0.0017405996 | X634: W5Q01 | Y634: EXT_HMRC_OTS_WP005_Core4_10PartnerCountries_Monthly_2019-01_to_2026-06_Raw_2026-08-26.json | Z634: =IF(U634="","",SUMIFS(Unit_Value_Review_QC!$K$10:$K$53,Unit_Value_Review_QC!$I$10:$I$53,"PARTNER|"&F634&"|"&I634)) -> 11.552282 | AA634: =IFERROR(U634/Z634,"") -> 0.88173236 | AB634: =IF(OR(N634<>"REPORTED",U634=""),"NOT_APPLICABLE",IF(OR(AA634<Unit_Value_Review_QC!$I$6,AA634>Unit_Value_Review_QC!$I$5),"REVIEW","WITHIN_BAND")) -> WITHIN_BAND
A635: 62052000_IN_202004_IMPORT | B635: 43922 | C635: 202004 | D635: 2020 | E635: 4 | F635: 62052000 | G635: 6205 | H635: 664 | I635: IN | J635: India | K635: IMPORT | L635: 3 | M635: 1 | N635: REPORTED | O635: 0 | P635: 0 | Q635: 2340786 | R635: 116783 | S635: 499870 | T635: USABLE | U635: =IF(R635>0,Q635/R635,"") -> 20.043893 | V635: =SUMIFS(fct_world_monthly!$J$2:$J$361,fct_world_monthly!$C$2:$C$361,C635,fct_world_monthly!$F$2:$F$361,F635) -> 16075495 | W635: =IF(V635>0,Q635/V635,"") -> 0.14561206 | X635: W5Q01 | Y635: EXT_HMRC_OTS_WP005_Core4_10PartnerCountries_Monthly_2019-01_to_2026-06_Raw_2026-08-26.json | Z635: =IF(U635="","",SUMIFS(Unit_Value_Review_QC!$K$10:$K$53,Unit_Value_Review_QC!$I$10:$I$53,"PARTNER|"&F635&"|"&I635)) -> 20.753901 | AA635: =IFERROR(U635/Z635,"") -> 0.96578919 | AB635: =IF(OR(N635<>"REPORTED",U635=""),"NOT_APPLICABLE",IF(OR(AA635<Unit_Value_Review_QC!$I$6,AA635>Unit_Value_Review_QC!$I$5),"REVIEW","WITHIN_BAND")) -> WITHIN_BAND
A636: 62052000_BD_202004_IMPORT | B636: 43922 | C636: 202004 | D636: 2020 | E636: 4 | F636: 62052000 | G636: 6205 | H636: 666 | I636: BD | J636: Bangladesh | K636: IMPORT | L636: 3 | M636: 1 | N636: REPORTED | O636: 0 | P636: 0 | Q636: 7220758 | R636: 416077 | S636: 1685440 | T636: USABLE | U636: =IF(R636>0,Q636/R636,"") -> 17.354379 | V636: =SUMIFS(fct_world_monthly!$J$2:$J$361,fct_world_monthly!$C$2:$C$361,C636,fct_world_monthly!$F$2:$F$361,F636) -> 16075495 | W636: =IF(V636>0,Q636/V636,"") -> 0.44917796 | X636: W5Q01 | Y636: EXT_HMRC_OTS_WP005_Core4_10PartnerCountries_Monthly_2019-01_to_2026-06_Raw_2026-08-26.json | Z636: =IF(U636="","",SUMIFS(Unit_Value_Review_QC!$K$10:$K$53,Unit_Value_Review_QC!$I$10:$I$53,"PARTNER|"&F636&"|"&I636)) -> 16.653215 | AA636: =IFERROR(U636/Z636,"") -> 1.0421038 | AB636: =IF(OR(N636<>"REPORTED",U636=""),"NOT_APPLICABLE",IF(OR(AA636<Unit_Value_Review_QC!$I$6,AA636>Unit_Value_Review_QC!$I$5),"REVIEW","WITHIN_BAND")) -> WITHIN_BAND
A637: 62052000_LK_202004_IMPORT | B637: 43922 | C637: 202004 | D637: 2020 | E637: 4 | F637: 62052000 | G637: 6205 | H637: 669 | I637: LK | J637: Sri Lanka | K637: IMPORT | L637: 3 | M637: 1 | N637: REPORTED | O637: 0 | P637: 0 | Q637: 74616 | R637: 2856 | S637: 12573 | T637: USABLE | U637: =IF(R637>0,Q637/R637,"") -> 26.12605 | V637: =SUMIFS(fct_world_monthly!$J$2:$J$361,fct_world_monthly!$C$2:$C$361,C637,fct_world_monthly!$F$2:$F$361,F637) -> 16075495 | W637: =IF(V637>0,Q637/V637,"") -> 0.0046415989 | X637: W5Q01 | Y637: EXT_HMRC_OTS_WP005_Core4_10PartnerCountries_Monthly_2019-01_to_2026-06_Raw_2026-08-26.json | Z637: =IF(U637="","",SUMIFS(Unit_Value_Review_QC!$K$10:$K$53,Unit_Value_Review_QC!$I$10:$I$53,"PARTNER|"&F637&"|"&I637)) -> 20.668788 | AA637: =IFERROR(U637/Z637,"") -> 1.264034 | AB637: =IF(OR(N637<>"REPORTED",U637=""),"NOT_APPLICABLE",IF(OR(AA637<Unit_Value_Review_QC!$I$6,AA637>Unit_Value_Review_QC!$I$5),"REVIEW","WITHIN_BAND")) -> WITHIN_BAND
A638: 62052000_MM_202004_IMPORT | B638: 43922 | C638: 202004 | D638: 2020 | E638: 4 | F638: 62052000 | G638: 6205 | H638: 676 | I638: MM | J638: Myanmar | K638: IMPORT | L638: 3 | M638: 1 | N638: REPORTED | O638: 0 | P638: 0 | Q638: 40912 | R638: 1606 | S638: 5111 | T638: USABLE | U638: =IF(R638>0,Q638/R638,"") -> 25.474471 | V638: =SUMIFS(fct_world_monthly!$J$2:$J$361,fct_world_monthly!$C$2:$C$361,C638,fct_world_monthly!$F$2:$F$361,F638) -> 16075495 | W638: =IF(V638>0,Q638/V638,"") -> 0.0025449916 | X638: W5Q01 | Y638: EXT_HMRC_OTS_WP005_Core4_10PartnerCountries_Monthly_2019-01_to_2026-06_Raw_2026-08-26.json | Z638: =IF(U638="","",SUMIFS(Unit_Value_Review_QC!$K$10:$K$53,Unit_Value_Review_QC!$I$10:$I$53,"PARTNER|"&F638&"|"&I638)) -> 22.71684 | AA638: =IFERROR(U638/Z638,"") -> 1.1213915 | AB638: =IF(OR(N638<>"REPORTED",U638=""),"NOT_APPLICABLE",IF(OR(AA638<Unit_Value_Review_QC!$I$6,AA638>Unit_Value_Review_QC!$I$5),"REVIEW","WITHIN_BAND")) -> WITHIN_BAND
A639: 62052000_VN_202004_IMPORT | B639: 43922 | C639: 202004 | D639: 2020 | E639: 4 | F639: 62052000 | G639: 6205 | H639: 690 | I639: VN | J639: Vietnam | K639: IMPORT | L639: 3 | M639: 1 | N639: REPORTED | O639: 0 | P639: 0 | Q639: 771026 | R639: 32091 | S639: 92249 | T639: USABLE | U639: =IF(R639>0,Q639/R639,"") -> 24.026238 | V639: =SUMIFS(fct_world_monthly!$J$2:$J$361,fct_world_monthly!$C$2:$C$361,C639,fct_world_monthly!$F$2:$F$361,F639) -> 16075495 | W639: =IF(V639>0,Q639/V639,"") -> 0.047962815 | X639: W5Q01 | Y639: EXT_HMRC_OTS_WP005_Core4_10PartnerCountries_Monthly_2019-01_to_2026-06_Raw_2026-08-26.json | Z639: =IF(U639="","",SUMIFS(Unit_Value_Review_QC!$K$10:$K$53,Unit_Value_Review_QC!$I$10:$I$53,"PARTNER|"&F639&"|"&I639)) -> 28.158454 | AA639: =IFERROR(U639/Z639,"") -> 0.85325132 | AB639: =IF(OR(N639<>"REPORTED",U639=""),"NOT_APPLICABLE",IF(OR(AA639<Unit_Value_Review_QC!$I$6,AA639>Unit_Value_Review_QC!$I$5),"REVIEW","WITHIN_BAND")) -> WITHIN_BAND
A640: 62052000_KH_202004_IMPORT | B640: 43922 | C640: 202004 | D640: 2020 | E640: 4 | F640: 62052000 | G640: 6205 | H640: 696 | I640: KH | J640: Cambodia | K640: IMPORT | L640: 3 | M640: 1 | N640: REPORTED | O640: 0 | P640: 0 | Q640: 630392 | R640: 22012 | S640: 78764 | T640: USABLE | U640: =IF(R640>0,Q640/R640,"") -> 28.638561 | V640: =SUMIFS(fct_world_monthly!$J$2:$J$361,fct_world_monthly!$C$2:$C$361,C640,fct_world_monthly!$F$2:$F$361,F640) -> 16075495 | W640: =IF(V640>0,Q640/V640,"") -> 0.039214469 | X640: W5Q01 | Y640: EXT_HMRC_OTS_WP005_Core4_10PartnerCountries_Monthly_2019-01_to_2026-06_Raw_2026-08-26.json | Z640: =IF(U640="","",SUMIFS(Unit_Value_Review_QC!$K$10:$K$53,Unit_Value_Review_QC!$I$10:$I$53,"PARTNER|"&F640&"|"&I640)) -> 25.266639 | AA640: =IFERROR(U640/Z640,"") -> 1.1334535 | AB640: =IF(OR(N640<>"REPORTED",U640=""),"NOT_APPLICABLE",IF(OR(AA640<Unit_Value_Review_QC!$I$6,AA640>Unit_Value_Review_QC!$I$5),"REVIEW","WITHIN_BAND")) -> WITHIN_BAND
A641: 62052000_CN_202004_IMPORT | B641: 43922 | C641: 202004 | D641: 2020 | E641: 4 | F641: 62052000 | G641: 6205 | H641: 720 | I641: CN | J641: China | K641: IMPORT | L641: 3 | M641: 1 | N641: REPORTED | O641: 0 | P641: 0 | Q641: 1591171 | R641: 55747 | S641: 166614 | T641: USABLE | U641: =IF(R641>0,Q641/R641,"") -> 28.54272 | V641: =SUMIFS(fct_world_monthly!$J$2:$J$361,fct_world_monthly!$C$2:$C$361,C641,fct_world_monthly!$F$2:$F$361,F641) -> 16075495 | W641: =IF(V641>0,Q641/V641,"") -> 0.098981151 | X641: W5Q01 | Y641: EXT_HMRC_OTS_WP005_Core4_10PartnerCountries_Monthly_2019-01_to_2026-06_Raw_2026-08-26.json | Z641: =IF(U641="","",SUMIFS(Unit_Value_Review_QC!$K$10:$K$53,Unit_Value_Review_QC!$I$10:$I$53,"PARTNER|"&F641&"|"&I641)) -> 23.211498 | AA641: =IFERROR(U641/Z641,"") -> 1.2296802 | AB641: =IF(OR(N641<>"REPORTED",U641=""),"NOT_APPLICABLE",IF(OR(AA641<Unit_Value_Review_QC!$I$6,AA641>Unit_Value_Review_QC!$I$5),"REVIEW","WITHIN_BAND")) -> WITHIN_BAND
A642: 61091000_TR_202005_IMPORT | B642: 43952 | C642: 202005 | D642: 2020 | E642: 5 | F642: 61091000 | G642: 6109 | H642: 52 | I642: TR | J642: Turkey | K642: IMPORT | L642: 3 | M642: 1 | N642: REPORTED | O642: 0 | P642: 0 | Q642: 4784475 | R642: 255321 | S642: 1339386 | T642: USABLE | U642: =IF(R642>0,Q642/R642,"") -> 18.739058 | V642: =SUMIFS(fct_world_monthly!$J$2:$J$361,fct_world_monthly!$C$2:$C$361,C642,fct_world_monthly!$F$2:$F$361,F642) -> 61113796 | W642: =IF(V642>0,Q642/V642,"") -> 0.07828797 | X642: W5Q01 | Y642: EXT_HMRC_OTS_WP005_Core4_10PartnerCountries_Monthly_2019-01_to_2026-06_Raw_2026-08-26.json | Z642: =IF(U642="","",SUMIFS(Unit_Value_Review_QC!$K$10:$K$53,Unit_Value_Review_QC!$I$10:$I$53,"PARTNER|"&F642&"|"&I642)) -> 20.461445 | AA642: =IFERROR(U642/Z642,"") -> 0.91582281 | AB642: =IF(OR(N642<>"REPORTED",U642=""),"NOT_APPLICABLE",IF(OR(AA642<Unit_Value_Review_QC!$I$6,AA642>Unit_Value_Review_QC!$I$5),"REVIEW","WITHIN_BAND")) -> WITHIN_BAND
