Workbook

Sheet Gate_Matrix
A2: NEXT | WP007 responsible-sourcing gates
A4: v1.0 | Final public-evidence framework | Evidence cut: 16 September 2026 | Mandatory sourcing gates; site reviews remain Pending.
A5: Pass / Conditional / Fail are project rules for additional sourcing. They are not NEXT audit ratings or a decision to terminate existing relationships.
A6: Pending means evidence is insufficient. It is not a compliance failure or approval. All applicable gates require evidence before a site can be cleared.
A7: Apply gates to the proposed supplier, site and product chain. Country context triggers due diligence; it does not establish country-wide compliance.
A8: Evidence, annotation base rates and QC are included. Myanmar remains excluded from actionable alternatives pending D008 clearance.
A10: Gate_ID | B10: Gate | C10: NEXT requirement / stated practice | D10: Evidence required for a candidate | E10: Project Pass rule | F10: Project Conditional rule | G10: Project Fail rule | H10: Application | I10: Evidence_ID
A11: RS01 | B11: Declared and approved production | C11: Suppliers provide due diligence before proposing sites. Production locations and subcontracting must be transparent and authorised. | D11: Official Site ID and location match; supplier/site relationship; proposed process; production and subcontractor approval records. | E11: Identity and proposed production chain are verified, with the required authorisations evidenced. | F11: An identified, remediable approval issue has an agreed action and decision owner. No additional production before closure. | G11: Confirmed unauthorised production remains unresolved, or the supplier refuses to disclose or regularise the production chain. | H11: All proposed sites and subcontracted processes. | I11: E01; E03
A12: RS02 | B12: Audit evidence and production clearance | C12: NEXT audits Tier 1 factories before production and uses category ratings and follow-up reviews to support improvement. | D12: Latest applicable audit, date, findings, follow-up due date, corrective-action status and current production clearance. | E12: Audit and clearance are evidenced for this site and proposed activity; no unresolved finding prevents additional sourcing. | F12: Audit identifies remediable issues with an agreed plan, owner and deadline. Expansion waits for the required closure and clearance. | G12: Verified failure of the required audit/clearance condition remains unresolved at the decision date. A historical annotation alone cannot establish this. | H12: All proposed Tier 1 sites. | I12: E01; E02; E07; E08; E09
A13: RS03 | B13: Forced labour, child labour and recruitment | C13: Prevent forced and child labour. Address wage retention, movement restrictions and exploitative recruitment, including migrant-worker fees. | D13: Worker interviews, age checks, recruitment/agency terms, fee and repayment evidence, wage records, document access and freedom of movement. | E13: Relevant risks have been investigated; no unresolved critical abuse is identified in adequate evidence, and any past remedy is verified. | F13: An evidenced issue has a credible, worker-centred remediation plan. Hold new allocation until the required remedy is verified. | G13: Confirmed ongoing critical abuse without credible remedy, refusal to remediate, or failed remediation by the agreed deadline. | H13: All sites; extend checks to agents and worker accommodation where relevant. | I13: E04; E05; E11
A14: RS04 | B14: Safe and fair working conditions | C14: Meet applicable COP requirements on safety, wages, hours, discrimination, employment security, respectful treatment and management controls. | D14: Audit findings and records for safety, pay, hours, contracts and treatment; verification of corrective actions. | E14: Evidence meets the applicable requirements and supports the proposed additional sourcing. | F14: Specific deficiencies have an agreed action plan; any expansion preconditions remain binding. | G14: Confirmed critical unsafe or abusive conditions remain unresolved, or required corrective actions are rejected or fail. | H14: All proposed sites; applicable local requirements must also be checked. | I14: E01; E10; E11
A15: RS05 | B15: Worker voice and remedy | C15: Respect freedom of association and collective bargaining. Provide accessible grievance channels and address concerns. | D15: Worker consultation; representation and grievance arrangements; complaint handling and remediation records. | E15: Evidence supports effective rights and access to remedy, including lawful alternative arrangements where relevant. | F15: A specific weakness is under a credible corrective plan; additional sourcing remains subject to resolving required safeguards. | G15: Confirmed serious suppression or retaliation remains unresolved, or the supplier refuses required corrective action. | H15: All proposed sites. A blank/No union field alone is not a failure. | I15: E01; E06; E10; E11
A16: RS06 | B16: Materials and forced-labour traceability | C16: NEXT bans XUAR cotton and describes no direct sourcing from XUAR at Tiers 1-3. Raw-material traceability is a stated focus. | D16: Product-specific material and processing chain; cotton-origin evidence where applicable; investigation of forced-labour exposure. | E16: The relevant material chain is evidenced and meets applicable sourcing restrictions and forced-labour requirements. | F16: A specific traceability deficiency has an agreed evidence/verification action; no clearance before the required evidence is obtained. | G16: Confirmed prohibited cotton/source use or forced-labour exposure remains unresolved for the proposed product chain. | H16: Check all products for forced-labour exposure. Cotton-origin checks particularly affect 61091000 and 62052000. | I16: E03; E04
A17: RS07 | B17: Remediation and evidence integrity | C17: NEXT agrees CAPs and monitors progress. It disengages where remediation is unsuccessful or willingness to improve is absent. | D17: Finding and CAP, accountable owner, agreed deadline, worker remedy, follow-up verification and reliable supporting records. | E17: Required corrective actions and remedy are verified, with any continuing monitoring in place. | F17: A credible agreed plan remains in progress and the site engages. Required closure precedes additional sourcing. | G17: Remediation fails or is refused, evidence is deliberately falsified, or current disengagement/no-production status is confirmed. | H17: Any candidate with findings or disputed records. Category 6 alone does not prove disengagement. | I17: E01; E02; E04; E05; E11
A18: RS08 | B18: Risk-specific due diligence | C18: Apply additional checks where country, process or labour risks warrant them. NEXT describes enhanced measures in Myanmar and India. | D18: Relevant country/process risk review and evidence of required extra checks; named approval of safeguards for the proposed chain. | E18: Specific risks are assessed and the applicable safeguards are evidenced. | F18: An identified safeguard gap has an agreed action plan. Expansion awaits completion of required safeguards. | G18: Confirmed material risk cannot be controlled, or the candidate refuses or fails required enhanced measures. | H18: Myanmar: excluded from actionable alternatives pending D008 clearance. RS08 enhanced measures apply. Other country-specific safeguards remain applicable. | I18: E02; E03; E04; E05; E06; E12; E13
A21: Decision rules and WP008 handover
A23: Rule | B23: Application
A24: Pending | B24: Evidence absent, unclear or not matched to the site/product. Keep the outcome Pending; do not silently convert it to Conditional or Pass.
A25: Conditional | B25: An evidence-backed, remediable issue has an agreed action, owner and deadline. This is not permission for new production.
A26: Overall outcome | B26: Any confirmed mandatory Fail excludes the candidate from new allocation. Otherwise any Pending prevents clearance; then any Conditional remains conditional. Pass requires all applicable gates to pass.
A27: Historical annotations | B27: The February 2026 annotations are review leads. They do not establish current audit status, unauthorised production or confirmed non-compliance.
A28: Unannotated sites | B28: The remaining 1,462 Site IDs have no published exception annotation. They are not deemed audited, approved or compliant.
A29: Country scenarios | B29: WP008 may compare illustrative country/product economics subject to due diligence. Myanmar is excluded from actionable reallocation pending D008 clearance; benchmark comparison is not allocation eligibility.
A30: Site allocation | B30: No site in this public-evidence review is certified for allocation. Do not derive available capacity or allocation percentages from the 16 flags or site counts.
A31: Separate origin gate | B31: Responsible-sourcing traceability is distinct from customs origin and tariff eligibility. WP008 retains WP004 origin-evidence and preference/fallback scenarios.
A32: Scope | B32: Retain all 16 exceptions. Ten are APPAREL-labelled sites in selected countries, but the label does not establish capability in any locked CN8 code.
A33: SC treatment | B33: SafetyCulture is a plausible expansion because CRR p.12 names the platform. No reviewed source explicitly maps SC in the supplier list to it. Keep all five outcomes Pending.
A36: Published audit follow-up intervals | Context only; no automatic mapping to a project outcome
A38: NEXT category | B38: Description | C38: Follow-up interval
A39: 1 | B39: Excellent | C39: 18-24 months
A40: 2 | B40: Good | C40: 12 months
A41: 3 | B41: Fair | C41: 9 months
A42: 4 | B42: Needs improvement | C42: 6 months
A43: 5 | B43: Unacceptable | C43: 6 months
A44: 6 | B44: Absolutely unacceptable | C44: Case by case; immediate action
A46: Source: E02. Follow-up intervals are NEXT-reported practice, not invented expiry dates. Check the actual site-specific audit and decision.
A49: D008 implementation and gate coverage
A50: D008: mandatory responsible-sourcing gates cannot be offset by lower costs. See Evidence E12 and docs/Research_Question_and_Scope.md.
A51: WP007 decision: Myanmar is excluded as an actionable alternative pending clearance. Public evidence cannot clear it; RS08 enhanced measures apply. Basis: D008 and the WP004 gate requirement (E04, E12, E13).
A52: WP008: Myanmar receives zero new/reallocated share while excluded. This is a project eligibility restriction, not proof that every Myanmar site fails or that existing NEXT sourcing is zero.
...

Sheet Site_Review
A2: WP003 annotation review
A4: Snapshot: February 2026 | Review: 16 September 2026 | One row per official Site ID. Outcomes concern evidence sufficiency, not a compliance verdict.
A6: Annotated sites | B6: =COUNTA(A10:A25) -> 16 | C6: Site not audited | D6: =COUNTIF(E10:E25,"site not audited") -> 11 | E6: Cannot find on SC | F6: =COUNTIF(E10:E25,"can't find on SC") -> 5 | G6: Pending reviews | H6: =COUNTIF(F10:F25,"Pending") -> 16
A7: RS01-RS02 review annotation evidence only. RS03-RS08 were considered but cannot be assessed from annotations; apply them at WP008 candidate evaluation.
A9: Site_ID | B9: Country | C9: Published product label | D9: Site name | E9: Raw annotation | F9: Review outcome | G9: Evidence gap | H9: Required next evidence | I9: Basket relevance | J9: Source_record_ID | K9: PDF page | L9: Supplier label | M9: Gate / Evidence_ID
A10: 16360 | B10: Portugal | C10: APPAREL | D10: Felpos S Paio Unipessoal Lda | E10: site not audited | F10: Pending | G10: Published unaudited annotation; timing, reason and any subsequent audit or approval are unverified. | H10: Obtain audit history, reason for annotation, current audit/follow-up evidence and production clearance. | I10: Country outside selected ten; APPAREL label only | J10: T1_2026_P08_R224 | K10: 8 | L10: Felpinter Industrias Texteis | M10: RS01; RS02; E08; E09
A11: 16580 | B11: China | C11: HOME | D11: Heng Fa Hardware | E11: site not audited | F11: Pending | G11: Published unaudited annotation; timing, reason and any subsequent audit or approval are unverified. | H11: Obtain audit history, reason for annotation, current audit/follow-up evidence and production clearance. | I11: HOME; outside garment scope | J11: T1_2026_P06_R005 | K11: 6 | L11: Rj Binnie Ltd | M11: RS01; RS02; E08; E09
A12: 21361 | B12: Taiwan | C12: HOME | D12: Gain How Printing Co Ltd | E12: site not audited | F12: Pending | G12: Published unaudited annotation; timing, reason and any subsequent audit or approval are unverified. | H12: Obtain audit history, reason for annotation, current audit/follow-up evidence and production clearance. | I12: HOME; outside garment scope | J12: T1_2026_P09_R103 | K12: 9 | L12: Royce Enterprise Co Ltd | M12: RS01; RS02; E08; E09
A13: 25555 | B13: China | C13: APPAREL | D13: Zhongshan Ronghua Leather Co Ltd | E13: site not audited | F13: Pending | G13: Published unaudited annotation; timing, reason and any subsequent audit or approval are unverified. | H13: Obtain audit history, reason for annotation, current audit/follow-up evidence and production clearance. | I13: Selected country; APPAREL label only | J13: T1_2026_P06_R028 | K13: 6 | L13: Shang Hai Newkeep Ltd Jl | M13: RS01; RS02; E08; E09
A14: 26061 | B14: China | C14: APPAREL | D14: Lucpack Limited | E14: site not audited | F14: Pending | G14: Published unaudited annotation; timing, reason and any subsequent audit or approval are unverified. | H14: Obtain audit history, reason for annotation, current audit/follow-up evidence and production clearance. | I14: Selected country; APPAREL label only | J14: T1_2026_P04_R195 | K14: 4 | L14: Monro Ltd | M14: RS01; RS02; E08; E09
A15: 26527 | B15: China | C15: APPAREL | D15: Huizhou Gao De Shoes Co Ltd | E15: site not audited | F15: Pending | G15: Published unaudited annotation; timing, reason and any subsequent audit or approval are unverified. | H15: Obtain audit history, reason for annotation, current audit/follow-up evidence and production clearance. | I15: Selected country; APPAREL label only | J15: T1_2026_P04_R010 | K15: 4 | L15: Grand Step (Hk) Ltd | M15: RS01; RS02; E08; E09
A16: 28834 | B16: China | C16: APPAREL | D16: Haining Aolundannu Garments Co Ltd | E16: can't find on SC | F16: Pending | G16: SC is undefined in the published list; audit-system absence and compliance status are unverified. | H16: Obtain authoritative SC definition and Site ID/system match, then current audit, findings and production clearance. | I16: Selected country; APPAREL label only | J16: T1_2026_P06_R059 | K16: 6 | L16: Sinoproud Import Export Corp | M16: RS01; RS02; E07; E08; E09
A17: 28898 | B17: China | C17: HOME | D17: Suzhou Eslite Textiles Corporation Ltd | E17: can't find on SC | F17: Pending | G17: SC is undefined in the published list; audit-system absence and compliance status are unverified. | H17: Obtain authoritative SC definition and Site ID/system match, then current audit, findings and production clearance. | I17: HOME; outside garment scope | J17: T1_2026_P06_R087 | K17: 6 | L17: Teng Jin Limited Wsl | M17: RS01; RS02; E07; E08; E09
A18: 29016 | B18: China | C18: APPAREL | D18: Chartered Company Limited | E18: can't find on SC | F18: Pending | G18: SC is undefined in the published list; audit-system absence and compliance status are unverified. | H18: Obtain authoritative SC definition and Site ID/system match, then current audit, findings and production clearance. | I18: Selected country; APPAREL label only | J18: T1_2026_P04_R082 | K18: 4 | L18: Inter-City Watch Company Ltd | M18: RS01; RS02; E07; E08; E09
A19: 29073 | B19: China | C19: APPAREL | D19: Dongguan Zhongxin Knitting Fashion Co Ltd | E19: can't find on SC | F19: Pending | G19: SC is undefined in the published list; audit-system absence and compliance status are unverified. | H19: Obtain authoritative SC definition and Site ID/system match, then current audit, findings and production clearance. | I19: Selected country; APPAREL label only | J19: T1_2026_P05_R037 | K19: 5 | L19: Nsl (Shanghai) | M19: RS01; RS02; E07; E08; E09
A20: 29322 | B20: Great Britain | C20: HOME | D20: The Downland Bedding Company Ltd | E20: site not audited | F20: Pending | G20: Published unaudited annotation; timing, reason and any subsequent audit or approval are unverified. | H20: Obtain audit history, reason for annotation, current audit/follow-up evidence and production clearance. | I20: HOME; outside garment scope | J20: T1_2026_P06_R238 | K20: 6 | L20: The Downland Bedding Company Ltd | M20: RS01; RS02; E08; E09
A21: 29910 | B21: Egypt | C21: APPAREL | D21: Sahinler Egypt 2 | E21: can't find on SC | F21: Pending | G21: SC is undefined in the published list; audit-system absence and compliance status are unverified. | H21: Obtain authoritative SC definition and Site ID/system match, then current audit, findings and production clearance. | I21: Country outside selected ten; APPAREL label only | J21: T1_2026_P06_R206 | K21: 6 | L21: Nsl (Turkey) | M21: RS01; RS02; E07; E08; E09
... A25: 30751 | B25: India | C25: APPAREL | D25: Kut & Kraft | E25: site not audited | F25: Pending | G25: Published unaudited annotation; timing, reason and any subsequent audit or approval are unverified. | H25: Obtain audit history, reason for annotation, current audit/follow-up evidence and production clearance. | I25: Selected country; APPAREL label only | J25: T1_2026_P07_R120 | K25: 7 | L25: Kut & Kraft | M25: RS01; RS02; E08; E09
A27: Source: E08-E09. A later disposition needs dated evidence and a recorded rationale; resolving an annotation alone does not clear all responsible-sourcing gates.

Sheet Evidence
A2: Evidence register
A4: Review date: 16 September 2026 | Archived documents anchor the historical evidence. Live policy links were checked on this date.
A5: MS page numbers are printed page + 1 in the PDF viewer. CRR printed pages match PDF pages for the cited sections.
A7: Evidence_ID | B7: Source_ID | C7: Document / filename | D7: Page or section | E7: Finding | F7: Evidence basis | G7: Limits / treatment | H7: Official URL / source
A8: E01 | B8: NXT_CRR_2026 | C8: NEXT_CRR_2026.pdf | D8: Printed/PDF pp.10-11 | E8: COP compliance is a contractual condition. Suppliers provide due diligence before proposing sites; Tier 1 audits precede production. CAPs and continuous improvement govern issues. | F8: NEXT disclosure | G8: Group reporting scope differs from WP003 NEXT-brand snapshot. It provides policy context, not clearance of any named site. | H8: https://www.nextplc.co.uk/~/media/Files/N/next-plc-v4/documents/corporate-responsibility/corporate-responsibility-report-2026.pdf
A9: E02 | B9: NXT_CRR_2026 | C9: NEXT_CRR_2026.pdf | D9: Printed/PDF pp.11-12 | E9: SafetyCulture was introduced in 2025. Audit categories run from 1 to 6; category 6 requires immediate action and case-specific follow-up. Myanmar factories receive enhanced monitoring. | F9: NEXT disclosure | G9: 2,708 audits are audit events, not unique WP003 sites. The 48 category-6 disengagements cannot be matched to the 16 annotations. | H9: https://www.nextplc.co.uk/~/media/Files/N/next-plc-v4/documents/corporate-responsibility/corporate-responsibility-report-2026.pdf
A10: E03 | B10: NXT_MS_2026 | C10: NEXT_Modern_Slavery_Statement_2026.pdf | D10: Printed p.7 / PDF p.8 | E10: Unauthorised subcontracting requires investigation and remediation. NEXT bans XUAR cotton and reports no direct Tier 1-3 sourcing from XUAR. Country/process risks guide due diligence. | F10: NEXT disclosure | G10: 32 subcontracting cases are reported without Site IDs. Do not attribute them to named sites or infer cotton origin from manufacturing country. | H10: https://www.nextplc.co.uk/corporate-responsibility/modern-slavery-transparency-statement
A11: E04 | B11: NXT_MS_2026 | C11: NEXT_Modern_Slavery_Statement_2026.pdf | D11: Printed p.8 / PDF p.9 | E11: 42 modern-slavery-risk cases: 9 remediated, 12 under agreed remediation and 21 disengaged. Myanmar measures include unannounced audits every eight weeks. | F11: NEXT disclosure | G11: These are reported cases, not a failure rate for WP003. The statement does not identify the relevant Site IDs. | H11: https://www.nextplc.co.uk/corporate-responsibility/modern-slavery-transparency-statement
A12: E05 | B12: NXT_MS_2026 | C12: NEXT_Modern_Slavery_Statement_2026.pdf | D12: Printed pp.9-10 / PDF pp.10-11 | E12: Examples cover child labour, movement restrictions in India and migrant recruitment fees in Turkey. Outcomes include disengagement, verified remedy and ongoing corrective plans. | F12: NEXT disclosure | G12: No match to the 16 annotated Site IDs is evidenced. Country examples trigger investigation, not country-wide failure. | H12: https://www.nextplc.co.uk/corporate-responsibility/modern-slavery-transparency-statement
A13: E06 | B13: NXT_CRR_2026 | C13: NEXT_CRR_2026.pdf | D13: Printed/PDF p.13 | E13: Worker voice includes grievance access and remedy. Freedom-of-association issues in Turkey require engagement. Different countries use different grievance arrangements. | F13: NEXT disclosure | G13: A No/blank trade-union or committee field does not establish suppression of rights or absence of every grievance route. | H13: https://www.nextplc.co.uk/~/media/Files/N/next-plc-v4/documents/corporate-responsibility/corporate-responsibility-report-2026.pdf
A14: E07 | B14: NXT_CRR_2026; NXT_SUP_T1_2026 | C14: CRR and February 2026 Tier 1 list | D14: CRR p.12; supplier PDF pp.4-6 | E14: CRR names SafetyCulture as the audit platform. The supplier list uses SC without defining it. | F14: Inference: plausible, unconfirmed | G14: No explicit acronym-to-platform mapping found in reviewed sources. Preserve SC verbatim; all five outcomes remain Pending. | H14: https://www.nextplc.co.uk/~/media/Files/N/next-plc-v4/documents/corporate-responsibility/corporate-responsibility-report-2026.pdf
A15: E08 | B15: NXT_SUP_T1_2026 | C15: NEXT_Tier1_Supplier_List_2026(1).pdf | D15: PDF pp.4-9; row-specific pages in Site_Review | E15: Verified all 16 raw annotations against source rows: 11 site not audited and 5 cannot-find-on-SC annotations, each on a distinct official Site ID. | F15: Direct published annotations | G15: Historical snapshot. An annotation does not show when production occurred, why an audit was absent or what happened later. | H15: https://www.nextplc.co.uk/~/media/Files/N/next-plc-v4/Tier%201%20-2%20-%203%20lists/PLC%20LIST%20FEB%202026%20-%20TIER1.pdf
A16: E09 | B16: Derived: NXT_SUP_T1_2026 | C16: NEXT_WP003_Tier1_Supplier_Footprint_2026(2).xlsx | D16: raw_tier1_relationships; site_master | E16: 1,478 Site IDs; 16 flags; 12 APPAREL and 4 HOME. Ten APPAREL-labelled exceptions fall in selected countries: 9 China, 1 India. | F16: Reconciled WP003 extraction | G16: APPAREL is a coarse label and can include non-garment products. Flags are not available capacity, procurement value or confirmed audit failures. | H16: Governed WP003 workbook
A17: E10 | B17: NXT_COP_PRINCIPLES_2024 | C17: Code_of_Practice_Principle_Standards_August_2024.pdf | D17: Cover; PDF pp.2-4 | E17: August 2024 issue lists ten standards, including Management Systems. Compliance and corrective action are conditions of the supplier relationship. | F17: Official linked policy | G17: Use the dated PDF: the web summary and MS statement list nine headings. Detailed supplier-portal policies were not accessible in this review. | H17: https://www.nextplc.co.uk/~/media/Files/N/Next-PLC-V2/documents/corporate-responsibility/Code_of_Practice_Principle_Standards_August_2024.pdf
A18: E11 | B18: NXT_COP_AUDIT_2025 | C18: _SUPPLIER Auditing Standards JUNE 2025.pdf | D18: Cover; sections 1, 2, 9 and 10 (PDF pp.2-3, 26-27) | E18: June 2025 cover governs version identification. Requirements include recruitment-fee controls, freedom of association, credible grievance channels and reliable records. | F18: Official linked policy | G18: Document search title says June 2024 but cover says June 2025. Finding severity is not automatic project clearance or disengagement. | H18: https://www.nextplc.co.uk/~/media/Files/N/next-plc-v4/corporate-responsibility/_SUPPLIER%20Auditing%20Standards%20JUNE%202025.pdf
... A20: E13 | B20: WP004 responsible-sourcing prerequisite | C20: NEXT_WP004_Category_Tariff_Lock.xlsx | D20: Tariff_Matrix!K22:K25; Origin_Rules!F4:I4 | E20: WP004 requires the separate D008 responsible-sourcing gate before recommending Myanmar and explicitly requires a mandatory responsible-sourcing decision. | F20: Direct workbook inspection | G20: WP004 establishes the gate requirement. Exclusion from actionable reallocation pending clearance is the WP007 project decision, recorded through D020. | H20: WP004 workbook

Sheet QC_Checks
A2: WP007 quality checks
A4: Checks recalculate against the included WP003 reference and current workbook rows. Counts cover the fixed 16-record review and eight-gate framework.
A5: QC is a terminal check: no decision, annotation rate or outcome is calculated from these results.
A7: Check_ID | B7: Check | C7: Expected | D7: Actual | E7: Exceptions | F7: Result | L7: Allowed outcomes
A8: QC001 | B8: Annotations reconcile to WP003 | C8: =SUM(WP003_Reference!$E$8:$E$1485) -> 16 | D8: =SUM(C16:C31) -> 16 | E8: =ABS(C8-D8)+ABS(COUNTA(Site_Review!$A$10:$A$25)-C8) -> 0 | F8: =IF(E8=0,"PASS","FAIL") -> PASS | L8: Pending
A9: QC002 | B9: Site IDs distinct and source-matched | C9: =SUM(WP003_Reference!$E$8:$E$1485) -> 16 | D9: =SUM(G16:G31) -> 16 | E9: =ABS(C9-D9)+ABS(COUNTA(Site_Review!$A$10:$A$25)-C9) -> 0 | F9: =IF(E9=0,"PASS","FAIL") -> PASS | L9: Pass
A10: QC003 | B10: Country and product match WP003 | C10: =SUM(WP003_Reference!$E$8:$E$1485) -> 16 | D10: =SUM(H16:H31) -> 16 | E10: =ABS(C10-D10)+ABS(COUNTA(Site_Review!$A$10:$A$25)-C10) -> 0 | F10: =IF(E10=0,"PASS","FAIL") -> PASS | L10: Conditional
A11: QC004 | B11: Outcomes within allowed domain | C11: =SUM(WP003_Reference!$E$8:$E$1485) -> 16 | D11: =SUM(F16:F31) -> 16 | E11: =ABS(C11-D11)+ABS(COUNTA(Site_Review!$A$10:$A$25)-C11) -> 0 | F11: =IF(E11=0,"PASS","FAIL") -> PASS | L11: Fail
A12: QC005 | B12: Evidence and gate references resolve | C12: 0 | D12: =SUM(D36:D59) -> 0 | E12: =D12 -> 0 | F12: =IF(E12=0,"PASS","FAIL") -> PASS
A15: Site_ID | B15: Source_ID matches | C15: Annotation matches | D15: Country matches | E15: Product matches | F15: Valid outcome | G15: Distinct ID | H15: Country + product
A16: =Site_Review!A10 -> 16360 | B16: =COUNTIF(WP003_Reference!$A$8:$A$1485,A16) -> 1 | C16: =IF(Site_Review!E10="",0,COUNTIFS(WP003_Reference!$A$8:$A$1485,A16,WP003_Reference!$D$8:$D$1485,Site_Review!E10)) -> 1 | D16: =COUNTIFS(WP003_Reference!$A$8:$A$1485,A16,WP003_Reference!$B$8:$B$1485,Site_Review!B10) -> 1 | E16: =COUNTIFS(WP003_Reference!$A$8:$A$1485,A16,WP003_Reference!$C$8:$C$1485,Site_Review!C10) -> 1 | F16: =COUNTIF($L$8:$L$11,Site_Review!F10) -> 1 | G16: =IF(AND(A16<>"",B16=1,COUNTIF(Site_Review!$A$10:$A$25,A16)=1),1,0) -> 1 | H16: =IF(AND(D16=1,E16=1),1,0) -> 1
A17: =Site_Review!A11 -> 16580 | B17: =COUNTIF(WP003_Reference!$A$8:$A$1485,A17) -> 1 | C17: =IF(Site_Review!E11="",0,COUNTIFS(WP003_Reference!$A$8:$A$1485,A17,WP003_Reference!$D$8:$D$1485,Site_Review!E11)) -> 1 | D17: =COUNTIFS(WP003_Reference!$A$8:$A$1485,A17,WP003_Reference!$B$8:$B$1485,Site_Review!B11) -> 1 | E17: =COUNTIFS(WP003_Reference!$A$8:$A$1485,A17,WP003_Reference!$C$8:$C$1485,Site_Review!C11) -> 1 | F17: =COUNTIF($L$8:$L$11,Site_Review!F11) -> 1 | G17: =IF(AND(A17<>"",B17=1,COUNTIF(Site_Review!$A$10:$A$25,A17)=1),1,0) -> 1 | H17: =IF(AND(D17=1,E17=1),1,0) -> 1
A18: =Site_Review!A12 -> 21361 | B18: =COUNTIF(WP003_Reference!$A$8:$A$1485,A18) -> 1 | C18: =IF(Site_Review!E12="",0,COUNTIFS(WP003_Reference!$A$8:$A$1485,A18,WP003_Reference!$D$8:$D$1485,Site_Review!E12)) -> 1 | D18: =COUNTIFS(WP003_Reference!$A$8:$A$1485,A18,WP003_Reference!$B$8:$B$1485,Site_Review!B12) -> 1 | E18: =COUNTIFS(WP003_Reference!$A$8:$A$1485,A18,WP003_Reference!$C$8:$C$1485,Site_Review!C12) -> 1 | F18: =COUNTIF($L$8:$L$11,Site_Review!F12) -> 1 | G18: =IF(AND(A18<>"",B18=1,COUNTIF(Site_Review!$A$10:$A$25,A18)=1),1,0) -> 1 | H18: =IF(AND(D18=1,E18=1),1,0) -> 1
A19: =Site_Review!A13 -> 25555 | B19: =COUNTIF(WP003_Reference!$A$8:$A$1485,A19) -> 1 | C19: =IF(Site_Review!E13="",0,COUNTIFS(WP003_Reference!$A$8:$A$1485,A19,WP003_Reference!$D$8:$D$1485,Site_Review!E13)) -> 1 | D19: =COUNTIFS(WP003_Reference!$A$8:$A$1485,A19,WP003_Reference!$B$8:$B$1485,Site_Review!B13) -> 1 | E19: =COUNTIFS(WP003_Reference!$A$8:$A$1485,A19,WP003_Reference!$C$8:$C$1485,Site_Review!C13) -> 1 | F19: =COUNTIF($L$8:$L$11,Site_Review!F13) -> 1 | G19: =IF(AND(A19<>"",B19=1,COUNTIF(Site_Review!$A$10:$A$25,A19)=1),1,0) -> 1 | H19: =IF(AND(D19=1,E19=1),1,0) -> 1
A20: =Site_Review!A14 -> 26061 | B20: =COUNTIF(WP003_Reference!$A$8:$A$1485,A20) -> 1 | C20: =IF(Site_Review!E14="",0,COUNTIFS(WP003_Reference!$A$8:$A$1485,A20,WP003_Reference!$D$8:$D$1485,Site_Review!E14)) -> 1 | D20: =COUNTIFS(WP003_Reference!$A$8:$A$1485,A20,WP003_Reference!$B$8:$B$1485,Site_Review!B14) -> 1 | E20: =COUNTIFS(WP003_Reference!$A$8:$A$1485,A20,WP003_Reference!$C$8:$C$1485,Site_Review!C14) -> 1 | F20: =COUNTIF($L$8:$L$11,Site_Review!F14) -> 1 | G20: =IF(AND(A20<>"",B20=1,COUNTIF(Site_Review!$A$10:$A$25,A20)=1),1,0) -> 1 | H20: =IF(AND(D20=1,E20=1),1,0) -> 1
A21: =Site_Review!A15 -> 26527 | B21: =COUNTIF(WP003_Reference!$A$8:$A$1485,A21) -> 1 | C21: =IF(Site_Review!E15="",0,COUNTIFS(WP003_Reference!$A$8:$A$1485,A21,WP003_Reference!$D$8:$D$1485,Site_Review!E15)) -> 1 | D21: =COUNTIFS(WP003_Reference!$A$8:$A$1485,A21,WP003_Reference!$B$8:$B$1485,Site_Review!B15) -> 1 | E21: =COUNTIFS(WP003_Reference!$A$8:$A$1485,A21,WP003_Reference!$C$8:$C$1485,Site_Review!C15) -> 1 | F21: =COUNTIF($L$8:$L$11,Site_Review!F15) -> 1 | G21: =IF(AND(A21<>"",B21=1,COUNTIF(Site_Review!$A$10:$A$25,A21)=1),1,0) -> 1 | H21: =IF(AND(D21=1,E21=1),1,0) -> 1
A22: =Site_Review!A16 -> 28834 | B22: =COUNTIF(WP003_Reference!$A$8:$A$1485,A22) -> 1 | C22: =IF(Site_Review!E16="",0,COUNTIFS(WP003_Reference!$A$8:$A$1485,A22,WP003_Reference!$D$8:$D$1485,Site_Review!E16)) -> 1 | D22: =COUNTIFS(WP003_Reference!$A$8:$A$1485,A22,WP003_Reference!$B$8:$B$1485,Site_Review!B16) -> 1 | E22: =COUNTIFS(WP003_Reference!$A$8:$A$1485,A22,WP003_Reference!$C$8:$C$1485,Site_Review!C16) -> 1 | F22: =COUNTIF($L$8:$L$11,Site_Review!F16) -> 1 | G22: =IF(AND(A22<>"",B22=1,COUNTIF(Site_Review!$A$10:$A$25,A22)=1),1,0) -> 1 | H22: =IF(AND(D22=1,E22=1),1,0) -> 1
A23: =Site_Review!A17 -> 28898 | B23: =COUNTIF(WP003_Reference!$A$8:$A$1485,A23) -> 1 | C23: =IF(Site_Review!E17="",0,COUNTIFS(WP003_Reference!$A$8:$A$1485,A23,WP003_Reference!$D$8:$D$1485,Site_Review!E17)) -> 1 | D23: =COUNTIFS(WP003_Reference!$A$8:$A$1485,A23,WP003_Reference!$B$8:$B$1485,Site_Review!B17) -> 1 | E23: =COUNTIFS(WP003_Reference!$A$8:$A$1485,A23,WP003_Reference!$C$8:$C$1485,Site_Review!C17) -> 1 | F23: =COUNTIF($L$8:$L$11,Site_Review!F17) -> 1 | G23: =IF(AND(A23<>"",B23=1,COUNTIF(Site_Review!$A$10:$A$25,A23)=1),1,0) -> 1 | H23: =IF(AND(D23=1,E23=1),1,0) -> 1
A24: =Site_Review!A18 -> 29016 | B24: =COUNTIF(WP003_Reference!$A$8:$A$1485,A24) -> 1 | C24: =IF(Site_Review!E18="",0,COUNTIFS(WP003_Reference!$A$8:$A$1485,A24,WP003_Reference!$D$8:$D$1485,Site_Review!E18)) -> 1 | D24: =COUNTIFS(WP003_Reference!$A$8:$A$1485,A24,WP003_Reference!$B$8:$B$1485,Site_Review!B18) -> 1 | E24: =COUNTIFS(WP003_Reference!$A$8:$A$1485,A24,WP003_Reference!$C$8:$C$1485,Site_Review!C18) -> 1 | F24: =COUNTIF($L$8:$L$11,Site_Review!F18) -> 1 | G24: =IF(AND(A24<>"",B24=1,COUNTIF(Site_Review!$A$10:$A$25,A24)=1),1,0) -> 1 | H24: =IF(AND(D24=1,E24=1),1,0) -> 1
A25: =Site_Review!A19 -> 29073 | B25: =COUNTIF(WP003_Reference!$A$8:$A$1485,A25) -> 1 | C25: =IF(Site_Review!E19="",0,COUNTIFS(WP003_Reference!$A$8:$A$1485,A25,WP003_Reference!$D$8:$D$1485,Site_Review!E19)) -> 1 | D25: =COUNTIFS(WP003_Reference!$A$8:$A$1485,A25,WP003_Reference!$B$8:$B$1485,Site_Review!B19) -> 1 | E25: =COUNTIFS(WP003_Reference!$A$8:$A$1485,A25,WP003_Reference!$C$8:$C$1485,Site_Review!C19) -> 1 | F25: =COUNTIF($L$8:$L$11,Site_Review!F19) -> 1 | G25: =IF(AND(A25<>"",B25=1,COUNTIF(Site_Review!$A$10:$A$25,A25)=1),1,0) -> 1 | H25: =IF(AND(D25=1,E25=1),1,0) -> 1
A26: =Site_Review!A20 -> 29322 | B26: =COUNTIF(WP003_Reference!$A$8:$A$1485,A26) -> 1 | C26: =IF(Site_Review!E20="",0,COUNTIFS(WP003_Reference!$A$8:$A$1485,A26,WP003_Reference!$D$8:$D$1485,Site_Review!E20)) -> 1 | D26: =COUNTIFS(WP003_Reference!$A$8:$A$1485,A26,WP003_Reference!$B$8:$B$1485,Site_Review!B20) -> 1 | E26: =COUNTIFS(WP003_Reference!$A$8:$A$1485,A26,WP003_Reference!$C$8:$C$1485,Site_Review!C20) -> 1 | F26: =COUNTIF($L$8:$L$11,Site_Review!F20) -> 1 | G26: =IF(AND(A26<>"",B26=1,COUNTIF(Site_Review!$A$10:$A$25,A26)=1),1,0) -> 1 | H26: =IF(AND(D26=1,E26=1),1,0) -> 1
A27: =Site_Review!A21 -> 29910 | B27: =COUNTIF(WP003_Reference!$A$8:$A$1485,A27) -> 1 | C27: =IF(Site_Review!E21="",0,COUNTIFS(WP003_Reference!$A$8:$A$1485,A27,WP003_Reference!$D$8:$D$1485,Site_Review!E21)) -> 1 | D27: =COUNTIFS(WP003_Reference!$A$8:$A$1485,A27,WP003_Reference!$B$8:$B$1485,Site_Review!B21) -> 1 | E27: =COUNTIFS(WP003_Reference!$A$8:$A$1485,A27,WP003_Reference!$C$8:$C$1485,Site_Review!C21) -> 1 | F27: =COUNTIF($L$8:$L$11,Site_Review!F21) -> 1 | G27: =IF(AND(A27<>"",B27=1,COUNTIF(Site_Review!$A$10:$A$25,A27)=1),1,0) -> 1 | H27: =IF(AND(D27=1,E27=1),1,0) -> 1
... A31: =Site_Review!A25 -> 30751 | B31: =COUNTIF(WP003_Reference!$A$8:$A$1485,A31) -> 1 | C31: =IF(Site_Review!E25="",0,COUNTIFS(WP003_Reference!$A$8:$A$1485,A31,WP003_Reference!$D$8:$D$1485,Site_Review!E25)) -> 1 | D31: =COUNTIFS(WP003_Reference!$A$8:$A$1485,A31,WP003_Reference!$B$8:$B$1485,Site_Review!B25) -> 1 | E31: =COUNTIFS(WP003_Reference!$A$8:$A$1485,A31,WP003_Reference!$C$8:$C$1485,Site_Review!C25) -> 1 | F31: =COUNTIF($L$8:$L$11,Site_Review!F25) -> 1 | G31: =IF(AND(A31<>"",B31=1,COUNTIF(Site_Review!$A$10:$A$25,A31)=1),1,0) -> 1 | H31: =IF(AND(D31=1,E31=1),1,0) -> 1
A35: Sheet | B35: Reference cell | C35: Current references | D35: Unresolved / invalid | E35: Token 1 | F35: Token 2 | G35: Token 3 | H35: Token 4 | I35: Token 5 | J35: Token 6 | K35: Token 7 | L35: Token 8 | M35: Token 1 issues | N35: Token 2 issues | O35: Token 3 issues | P35: Token 4 issues | Q35: Token 5 issues | R35: Token 6 issues | S35: Token 7 issues | T35: Token 8 issues
A36: Gate_Matrix | B36: I11 | C36: =Gate_Matrix!I11 -> E01; E03 | D36: =SUM(M36:T36)+IF(OR(C36="",LEN(C36)-LEN(SUBSTITUTE(C36,";",""))+1>8),1,0) -> 0 | E36: =TRIM(MID(SUBSTITUTE(C36,";",REPT(" ",30)),1,30)) -> E01 | F36: =TRIM(MID(SUBSTITUTE(C36,";",REPT(" ",30)),31,30)) -> E03 | G36: =TRIM(MID(SUBSTITUTE(C36,";",REPT(" ",30)),61,30)) | H36: =TRIM(MID(SUBSTITUTE(C36,";",REPT(" ",30)),91,30)) | I36: =TRIM(MID(SUBSTITUTE(C36,";",REPT(" ",30)),121,30)) | J36: =TRIM(MID(SUBSTITUTE(C36,";",REPT(" ",30)),151,30)) | K36: =TRIM(MID(SUBSTITUTE(C36,";",REPT(" ",30)),181,30)) | L36: =TRIM(MID(SUBSTITUTE(C36,";",REPT(" ",30)),211,30)) | M36: =IF(E36="",0,IF(COUNTIF(Evidence!$A$8:$A$20,E36)+COUNTIF(Gate_Matrix!$A$11:$A$18,E36)=1,0,1)) -> 0 | N36: =IF(F36="",0,IF(COUNTIF(Evidence!$A$8:$A$20,F36)+COUNTIF(Gate_Matrix!$A$11:$A$18,F36)=1,0,1)) -> 0 | O36: =IF(G36="",0,IF(COUNTIF(Evidence!$A$8:$A$20,G36)+COUNTIF(Gate_Matrix!$A$11:$A$18,G36)=1,0,1)) -> 0 | P36: =IF(H36="",0,IF(COUNTIF(Evidence!$A$8:$A$20,H36)+COUNTIF(Gate_Matrix!$A$11:$A$18,H36)=1,0,1)) -> 0 | Q36: =IF(I36="",0,IF(COUNTIF(Evidence!$A$8:$A$20,I36)+COUNTIF(Gate_Matrix!$A$11:$A$18,I36)=1,0,1)) -> 0 | R36: =IF(J36="",0,IF(COUNTIF(Evidence!$A$8:$A$20,J36)+COUNTIF(Gate_Matrix!$A$11:$A$18,J36)=1,0,1)) -> 0 | S36: =IF(K36="",0,IF(COUNTIF(Evidence!$A$8:$A$20,K36)+COUNTIF(Gate_Matrix!$A$11:$A$18,K36)=1,0,1)) -> 0 | T36: =IF(L36="",0,IF(COUNTIF(Evidence!$A$8:$A$20,L36)+COUNTIF(Gate_Matrix!$A$11:$A$18,L36)=1,0,1)) -> 0
A37: Gate_Matrix | B37: I12 | C37: =Gate_Matrix!I12 -> E01; E02; E07; E08; E09 | D37: =SUM(M37:T37)+IF(OR(C37="",LEN(C37)-LEN(SUBSTITUTE(C37,";",""))+1>8),1,0) -> 0 | E37: =TRIM(MID(SUBSTITUTE(C37,";",REPT(" ",30)),1,30)) -> E01 | F37: =TRIM(MID(SUBSTITUTE(C37,";",REPT(" ",30)),31,30)) -> E02 | G37: =TRIM(MID(SUBSTITUTE(C37,";",REPT(" ",30)),61,30)) -> E07 | H37: =TRIM(MID(SUBSTITUTE(C37,";",REPT(" ",30)),91,30)) -> E08 | I37: =TRIM(MID(SUBSTITUTE(C37,";",REPT(" ",30)),121,30)) -> E09 | J37: =TRIM(MID(SUBSTITUTE(C37,";",REPT(" ",30)),151,30)) | K37: =TRIM(MID(SUBSTITUTE(C37,";",REPT(" ",30)),181,30)) | L37: =TRIM(MID(SUBSTITUTE(C37,";",REPT(" ",30)),211,30)) | M37: =IF(E37="",0,IF(COUNTIF(Evidence!$A$8:$A$20,E37)+COUNTIF(Gate_Matrix!$A$11:$A$18,E37)=1,0,1)) -> 0 | N37: =IF(F37="",0,IF(COUNTIF(Evidence!$A$8:$A$20,F37)+COUNTIF(Gate_Matrix!$A$11:$A$18,F37)=1,0,1)) -> 0 | O37: =IF(G37="",0,IF(COUNTIF(Evidence!$A$8:$A$20,G37)+COUNTIF(Gate_Matrix!$A$11:$A$18,G37)=1,0,1)) -> 0 | P37: =IF(H37="",0,IF(COUNTIF(Evidence!$A$8:$A$20,H37)+COUNTIF(Gate_Matrix!$A$11:$A$18,H37)=1,0,1)) -> 0 | Q37: =IF(I37="",0,IF(COUNTIF(Evidence!$A$8:$A$20,I37)+COUNTIF(Gate_Matrix!$A$11:$A$18,I37)=1,0,1)) -> 0 | R37: =IF(J37="",0,IF(COUNTIF(Evidence!$A$8:$A$20,J37)+COUNTIF(Gate_Matrix!$A$11:$A$18,J37)=1,0,1)) -> 0 | S37: =IF(K37="",0,IF(COUNTIF(Evidence!$A$8:$A$20,K37)+COUNTIF(Gate_Matrix!$A$11:$A$18,K37)=1,0,1)) -> 0 | T37: =IF(L37="",0,IF(COUNTIF(Evidence!$A$8:$A$20,L37)+COUNTIF(Gate_Matrix!$A$11:$A$18,L37)=1,0,1)) -> 0
A38: Gate_Matrix | B38: I13 | C38: =Gate_Matrix!I13 -> E04; E05; E11 | D38: =SUM(M38:T38)+IF(OR(C38="",LEN(C38)-LEN(SUBSTITUTE(C38,";",""))+1>8),1,0) -> 0 | E38: =TRIM(MID(SUBSTITUTE(C38,";",REPT(" ",30)),1,30)) -> E04 | F38: =TRIM(MID(SUBSTITUTE(C38,";",REPT(" ",30)),31,30)) -> E05 | G38: =TRIM(MID(SUBSTITUTE(C38,";",REPT(" ",30)),61,30)) -> E11 | H38: =TRIM(MID(SUBSTITUTE(C38,";",REPT(" ",30)),91,30)) | I38: =TRIM(MID(SUBSTITUTE(C38,";",REPT(" ",30)),121,30)) | J38: =TRIM(MID(SUBSTITUTE(C38,";",REPT(" ",30)),151,30)) | K38: =TRIM(MID(SUBSTITUTE(C38,";",REPT(" ",30)),181,30)) | L38: =TRIM(MID(SUBSTITUTE(C38,";",REPT(" ",30)),211,30)) | M38: =IF(E38="",0,IF(COUNTIF(Evidence!$A$8:$A$20,E38)+COUNTIF(Gate_Matrix!$A$11:$A$18,E38)=1,0,1)) -> 0 | N38: =IF(F38="",0,IF(COUNTIF(Evidence!$A$8:$A$20,F38)+COUNTIF(Gate_Matrix!$A$11:$A$18,F38)=1,0,1)) -> 0 | O38: =IF(G38="",0,IF(COUNTIF(Evidence!$A$8:$A$20,G38)+COUNTIF(Gate_Matrix!$A$11:$A$18,G38)=1,0,1)) -> 0 | P38: =IF(H38="",0,IF(COUNTIF(Evidence!$A$8:$A$20,H38)+COUNTIF(Gate_Matrix!$A$11:$A$18,H38)=1,0,1)) -> 0 | Q38: =IF(I38="",0,IF(COUNTIF(Evidence!$A$8:$A$20,I38)+COUNTIF(Gate_Matrix!$A$11:$A$18,I38)=1,0,1)) -> 0 | R38: =IF(J38="",0,IF(COUNTIF(Evidence!$A$8:$A$20,J38)+COUNTIF(Gate_Matrix!$A$11:$A$18,J38)=1,0,1)) -> 0 | S38: =IF(K38="",0,IF(COUNTIF(Evidence!$A$8:$A$20,K38)+COUNTIF(Gate_Matrix!$A$11:$A$18,K38)=1,0,1)) -> 0 | T38: =IF(L38="",0,IF(COUNTIF(Evidence!$A$8:$A$20,L38)+COUNTIF(Gate_Matrix!$A$11:$A$18,L38)=1,0,1)) -> 0
A39: Gate_Matrix | B39: I14 | C39: =Gate_Matrix!I14 -> E01; E10; E11 | D39: =SUM(M39:T39)+IF(OR(C39="",LEN(C39)-LEN(SUBSTITUTE(C39,";",""))+1>8),1,0) -> 0 | E39: =TRIM(MID(SUBSTITUTE(C39,";",REPT(" ",30)),1,30)) -> E01 | F39: =TRIM(MID(SUBSTITUTE(C39,";",REPT(" ",30)),31,30)) -> E10 | G39: =TRIM(MID(SUBSTITUTE(C39,";",REPT(" ",30)),61,30)) -> E11 | H39: =TRIM(MID(SUBSTITUTE(C39,";",REPT(" ",30)),91,30)) | I39: =TRIM(MID(SUBSTITUTE(C39,";",REPT(" ",30)),121,30)) | J39: =TRIM(MID(SUBSTITUTE(C39,";",REPT(" ",30)),151,30)) | K39: =TRIM(MID(SUBSTITUTE(C39,";",REPT(" ",30)),181,30)) | L39: =TRIM(MID(SUBSTITUTE(C39,";",REPT(" ",30)),211,30)) | M39: =IF(E39="",0,IF(COUNTIF(Evidence!$A$8:$A$20,E39)+COUNTIF(Gate_Matrix!$A$11:$A$18,E39)=1,0,1)) -> 0 | N39: =IF(F39="",0,IF(COUNTIF(Evidence!$A$8:$A$20,F39)+COUNTIF(Gate_Matrix!$A$11:$A$18,F39)=1,0,1)) -> 0 | O39: =IF(G39="",0,IF(COUNTIF(Evidence!$A$8:$A$20,G39)+COUNTIF(Gate_Matrix!$A$11:$A$18,G39)=1,0,1)) -> 0 | P39: =IF(H39="",0,IF(COUNTIF(Evidence!$A$8:$A$20,H39)+COUNTIF(Gate_Matrix!$A$11:$A$18,H39)=1,0,1)) -> 0 | Q39: =IF(I39="",0,IF(COUNTIF(Evidence!$A$8:$A$20,I39)+COUNTIF(Gate_Matrix!$A$11:$A$18,I39)=1,0,1)) -> 0 | R39: =IF(J39="",0,IF(COUNTIF(Evidence!$A$8:$A$20,J39)+COUNTIF(Gate_Matrix!$A$11:$A$18,J39)=1,0,1)) -> 0 | S39: =IF(K39="",0,IF(COUNTIF(Evidence!$A$8:$A$20,K39)+COUNTIF(Gate_Matrix!$A$11:$A$18,K39)=1,0,1)) -> 0 | T39: =IF(L39="",0,IF(COUNTIF(Evidence!$A$8:$A$20,L39)+COUNTIF(Gate_Matrix!$A$11:$A$18,L39)=1,0,1)) -> 0
A40: Gate_Matrix | B40: I15 | C40: =Gate_Matrix!I15 -> E01; E06; E10; E11 | D40: =SUM(M40:T40)+IF(OR(C40="",LEN(C40)-LEN(SUBSTITUTE(C40,";",""))+1>8),1,0) -> 0 | E40: =TRIM(MID(SUBSTITUTE(C40,";",REPT(" ",30)),1,30)) -> E01 | F40: =TRIM(MID(SUBSTITUTE(C40,";",REPT(" ",30)),31,30)) -> E06 | G40: =TRIM(MID(SUBSTITUTE(C40,";",REPT(" ",30)),61,30)) -> E10 | H40: =TRIM(MID(SUBSTITUTE(C40,";",REPT(" ",30)),91,30)) -> E11 | I40: =TRIM(MID(SUBSTITUTE(C40,";",REPT(" ",30)),121,30)) | J40: =TRIM(MID(SUBSTITUTE(C40,";",REPT(" ",30)),151,30)) | K40: =TRIM(MID(SUBSTITUTE(C40,";",REPT(" ",30)),181,30)) | L40: =TRIM(MID(SUBSTITUTE(C40,";",REPT(" ",30)),211,30)) | M40: =IF(E40="",0,IF(COUNTIF(Evidence!$A$8:$A$20,E40)+COUNTIF(Gate_Matrix!$A$11:$A$18,E40)=1,0,1)) -> 0 | N40: =IF(F40="",0,IF(COUNTIF(Evidence!$A$8:$A$20,F40)+COUNTIF(Gate_Matrix!$A$11:$A$18,F40)=1,0,1)) -> 0 | O40: =IF(G40="",0,IF(COUNTIF(Evidence!$A$8:$A$20,G40)+COUNTIF(Gate_Matrix!$A$11:$A$18,G40)=1,0,1)) -> 0 | P40: =IF(H40="",0,IF(COUNTIF(Evidence!$A$8:$A$20,H40)+COUNTIF(Gate_Matrix!$A$11:$A$18,H40)=1,0,1)) -> 0 | Q40: =IF(I40="",0,IF(COUNTIF(Evidence!$A$8:$A$20,I40)+COUNTIF(Gate_Matrix!$A$11:$A$18,I40)=1,0,1)) -> 0 | R40: =IF(J40="",0,IF(COUNTIF(Evidence!$A$8:$A$20,J40)+COUNTIF(Gate_Matrix!$A$11:$A$18,J40)=1,0,1)) -> 0 | S40: =IF(K40="",0,IF(COUNTIF(Evidence!$A$8:$A$20,K40)+COUNTIF(Gate_Matrix!$A$11:$A$18,K40)=1,0,1)) -> 0 | T40: =IF(L40="",0,IF(COUNTIF(Evidence!$A$8:$A$20,L40)+COUNTIF(Gate_Matrix!$A$11:$A$18,L40)=1,0,1)) -> 0
A41: Gate_Matrix | B41: I16 | C41: =Gate_Matrix!I16 -> E03; E04 | D41: =SUM(M41:T41)+IF(OR(C41="",LEN(C41)-LEN(SUBSTITUTE(C41,";",""))+1>8),1,0) -> 0 | E41: =TRIM(MID(SUBSTITUTE(C41,";",REPT(" ",30)),1,30)) -> E03 | F41: =TRIM(MID(SUBSTITUTE(C41,";",REPT(" ",30)),31,30)) -> E04 | G41: =TRIM(MID(SUBSTITUTE(C41,";",REPT(" ",30)),61,30)) | H41: =TRIM(MID(SUBSTITUTE(C41,";",REPT(" ",30)),91,30)) | I41: =TRIM(MID(SUBSTITUTE(C41,";",REPT(" ",30)),121,30)) | J41: =TRIM(MID(SUBSTITUTE(C41,";",REPT(" ",30)),151,30)) | K41: =TRIM(MID(SUBSTITUTE(C41,";",REPT(" ",30)),181,30)) | L41: =TRIM(MID(SUBSTITUTE(C41,";",REPT(" ",30)),211,30)) | M41: =IF(E41="",0,IF(COUNTIF(Evidence!$A$8:$A$20,E41)+COUNTIF(Gate_Matrix!$A$11:$A$18,E41)=1,0,1)) -> 0 | N41: =IF(F41="",0,IF(COUNTIF(Evidence!$A$8:$A$20,F41)+COUNTIF(Gate_Matrix!$A$11:$A$18,F41)=1,0,1)) -> 0 | O41: =IF(G41="",0,IF(COUNTIF(Evidence!$A$8:$A$20,G41)+COUNTIF(Gate_Matrix!$A$11:$A$18,G41)=1,0,1)) -> 0 | P41: =IF(H41="",0,IF(COUNTIF(Evidence!$A$8:$A$20,H41)+COUNTIF(Gate_Matrix!$A$11:$A$18,H41)=1,0,1)) -> 0 | Q41: =IF(I41="",0,IF(COUNTIF(Evidence!$A$8:$A$20,I41)+COUNTIF(Gate_Matrix!$A$11:$A$18,I41)=1,0,1)) -> 0 | R41: =IF(J41="",0,IF(COUNTIF(Evidence!$A$8:$A$20,J41)+COUNTIF(Gate_Matrix!$A$11:$A$18,J41)=1,0,1)) -> 0 | S41: =IF(K41="",0,IF(COUNTIF(Evidence!$A$8:$A$20,K41)+COUNTIF(Gate_Matrix!$A$11:$A$18,K41)=1,0,1)) -> 0 | T41: =IF(L41="",0,IF(COUNTIF(Evidence!$A$8:$A$20,L41)+COUNTIF(Gate_Matrix!$A$11:$A$18,L41)=1,0,1)) -> 0
A42: Gate_Matrix | B42: I17 | C42: =Gate_Matrix!I17 -> E01; E02; E04; E05; E11 | D42: =SUM(M42:T42)+IF(OR(C42="",LEN(C42)-LEN(SUBSTITUTE(C42,";",""))+1>8),1,0) -> 0 | E42: =TRIM(MID(SUBSTITUTE(C42,";",REPT(" ",30)),1,30)) -> E01 | F42: =TRIM(MID(SUBSTITUTE(C42,";",REPT(" ",30)),31,30)) -> E02 | G42: =TRIM(MID(SUBSTITUTE(C42,";",REPT(" ",30)),61,30)) -> E04 | H42: =TRIM(MID(SUBSTITUTE(C42,";",REPT(" ",30)),91,30)) -> E05 | I42: =TRIM(MID(SUBSTITUTE(C42,";",REPT(" ",30)),121,30)) -> E11 | J42: =TRIM(MID(SUBSTITUTE(C42,";",REPT(" ",30)),151,30)) | K42: =TRIM(MID(SUBSTITUTE(C42,";",REPT(" ",30)),181,30)) | L42: =TRIM(MID(SUBSTITUTE(C42,";",REPT(" ",30)),211,30)) | M42: =IF(E42="",0,IF(COUNTIF(Evidence!$A$8:$A$20,E42)+COUNTIF(Gate_Matrix!$A$11:$A$18,E42)=1,0,1)) -> 0 | N42: =IF(F42="",0,IF(COUNTIF(Evidence!$A$8:$A$20,F42)+COUNTIF(Gate_Matrix!$A$11:$A$18,F42)=1,0,1)) -> 0 | O42: =IF(G42="",0,IF(COUNTIF(Evidence!$A$8:$A$20,G42)+COUNTIF(Gate_Matrix!$A$11:$A$18,G42)=1,0,1)) -> 0 | P42: =IF(H42="",0,IF(COUNTIF(Evidence!$A$8:$A$20,H42)+COUNTIF(Gate_Matrix!$A$11:$A$18,H42)=1,0,1)) -> 0 | Q42: =IF(I42="",0,IF(COUNTIF(Evidence!$A$8:$A$20,I42)+COUNTIF(Gate_Matrix!$A$11:$A$18,I42)=1,0,1)) -> 0 | R42: =IF(J42="",0,IF(COUNTIF(Evidence!$A$8:$A$20,J42)+COUNTIF(Gate_Matrix!$A$11:$A$18,J42)=1,0,1)) -> 0 | S42: =IF(K42="",0,IF(COUNTIF(Evidence!$A$8:$A$20,K42)+COUNTIF(Gate_Matrix!$A$11:$A$18,K42)=1,0,1)) -> 0 | T42: =IF(L42="",0,IF(COUNTIF(Evidence!$A$8:$A$20,L42)+COUNTIF(Gate_Matrix!$A$11:$A$18,L42)=1,0,1)) -> 0
A43: Gate_Matrix | B43: I18 | C43: =Gate_Matrix!I18 -> E02; E03; E04; E05; E06; E12; E13 | D43: =SUM(M43:T43)+IF(OR(C43="",LEN(C43)-LEN(SUBSTITUTE(C43,";",""))+1>8),1,0) -> 0 | E43: =TRIM(MID(SUBSTITUTE(C43,";",REPT(" ",30)),1,30)) -> E02 | F43: =TRIM(MID(SUBSTITUTE(C43,";",REPT(" ",30)),31,30)) -> E03 | G43: =TRIM(MID(SUBSTITUTE(C43,";",REPT(" ",30)),61,30)) -> E04 | H43: =TRIM(MID(SUBSTITUTE(C43,";",REPT(" ",30)),91,30)) -> E05 | I43: =TRIM(MID(SUBSTITUTE(C43,";",REPT(" ",30)),121,30)) -> E06 | J43: =TRIM(MID(SUBSTITUTE(C43,";",REPT(" ",30)),151,30)) -> E12 | K43: =TRIM(MID(SUBSTITUTE(C43,";",REPT(" ",30)),181,30)) -> E13 | L43: =TRIM(MID(SUBSTITUTE(C43,";",REPT(" ",30)),211,30)) | M43: =IF(E43="",0,IF(COUNTIF(Evidence!$A$8:$A$20,E43)+COUNTIF(Gate_Matrix!$A$11:$A$18,E43)=1,0,1)) -> 0 | N43: =IF(F43="",0,IF(COUNTIF(Evidence!$A$8:$A$20,F43)+COUNTIF(Gate_Matrix!$A$11:$A$18,F43)=1,0,1)) -> 0 | O43: =IF(G43="",0,IF(COUNTIF(Evidence!$A$8:$A$20,G43)+COUNTIF(Gate_Matrix!$A$11:$A$18,G43)=1,0,1)) -> 0 | P43: =IF(H43="",0,IF(COUNTIF(Evidence!$A$8:$A$20,H43)+COUNTIF(Gate_Matrix!$A$11:$A$18,H43)=1,0,1)) -> 0 | Q43: =IF(I43="",0,IF(COUNTIF(Evidence!$A$8:$A$20,I43)+COUNTIF(Gate_Matrix!$A$11:$A$18,I43)=1,0,1)) -> 0 | R43: =IF(J43="",0,IF(COUNTIF(Evidence!$A$8:$A$20,J43)+COUNTIF(Gate_Matrix!$A$11:$A$18,J43)=1,0,1)) -> 0 | S43: =IF(K43="",0,IF(COUNTIF(Evidence!$A$8:$A$20,K43)+COUNTIF(Gate_Matrix!$A$11:$A$18,K43)=1,0,1)) -> 0 | T43: =IF(L43="",0,IF(COUNTIF(Evidence!$A$8:$A$20,L43)+COUNTIF(Gate_Matrix!$A$11:$A$18,L43)=1,0,1)) -> 0
A44: Site_Review | B44: M10 | C44: =Site_Review!M10 -> RS01; RS02; E08; E09 | D44: =SUM(M44:T44)+IF(OR(C44="",LEN(C44)-LEN(SUBSTITUTE(C44,";",""))+1>8),1,0) -> 0 | E44: =TRIM(MID(SUBSTITUTE(C44,";",REPT(" ",30)),1,30)) -> RS01 | F44: =TRIM(MID(SUBSTITUTE(C44,";",REPT(" ",30)),31,30)) -> RS02 | G44: =TRIM(MID(SUBSTITUTE(C44,";",REPT(" ",30)),61,30)) -> E08 | H44: =TRIM(MID(SUBSTITUTE(C44,";",REPT(" ",30)),91,30)) -> E09 | I44: =TRIM(MID(SUBSTITUTE(C44,";",REPT(" ",30)),121,30)) | J44: =TRIM(MID(SUBSTITUTE(C44,";",REPT(" ",30)),151,30)) | K44: =TRIM(MID(SUBSTITUTE(C44,";",REPT(" ",30)),181,30)) | L44: =TRIM(MID(SUBSTITUTE(C44,";",REPT(" ",30)),211,30)) | M44: =IF(E44="",0,IF(COUNTIF(Evidence!$A$8:$A$20,E44)+COUNTIF(Gate_Matrix!$A$11:$A$18,E44)=1,0,1)) -> 0 | N44: =IF(F44="",0,IF(COUNTIF(Evidence!$A$8:$A$20,F44)+COUNTIF(Gate_Matrix!$A$11:$A$18,F44)=1,0,1)) -> 0 | O44: =IF(G44="",0,IF(COUNTIF(Evidence!$A$8:$A$20,G44)+COUNTIF(Gate_Matrix!$A$11:$A$18,G44)=1,0,1)) -> 0 | P44: =IF(H44="",0,IF(COUNTIF(Evidence!$A$8:$A$20,H44)+COUNTIF(Gate_Matrix!$A$11:$A$18,H44)=1,0,1)) -> 0 | Q44: =IF(I44="",0,IF(COUNTIF(Evidence!$A$8:$A$20,I44)+COUNTIF(Gate_Matrix!$A$11:$A$18,I44)=1,0,1)) -> 0 | R44: =IF(J44="",0,IF(COUNTIF(Evidence!$A$8:$A$20,J44)+COUNTIF(Gate_Matrix!$A$11:$A$18,J44)=1,0,1)) -> 0 | S44: =IF(K44="",0,IF(COUNTIF(Evidence!$A$8:$A$20,K44)+COUNTIF(Gate_Matrix!$A$11:$A$18,K44)=1,0,1)) -> 0 | T44: =IF(L44="",0,IF(COUNTIF(Evidence!$A$8:$A$20,L44)+COUNTIF(Gate_Matrix!$A$11:$A$18,L44)=1,0,1)) -> 0
A45: Site_Review | B45: M11 | C45: =Site_Review!M11 -> RS01; RS02; E08; E09 | D45: =SUM(M45:T45)+IF(OR(C45="",LEN(C45)-LEN(SUBSTITUTE(C45,";",""))+1>8),1,0) -> 0 | E45: =TRIM(MID(SUBSTITUTE(C45,";",REPT(" ",30)),1,30)) -> RS01 | F45: =TRIM(MID(SUBSTITUTE(C45,";",REPT(" ",30)),31,30)) -> RS02 | G45: =TRIM(MID(SUBSTITUTE(C45,";",REPT(" ",30)),61,30)) -> E08 | H45: =TRIM(MID(SUBSTITUTE(C45,";",REPT(" ",30)),91,30)) -> E09 | I45: =TRIM(MID(SUBSTITUTE(C45,";",REPT(" ",30)),121,30)) | J45: =TRIM(MID(SUBSTITUTE(C45,";",REPT(" ",30)),151,30)) | K45: =TRIM(MID(SUBSTITUTE(C45,";",REPT(" ",30)),181,30)) | L45: =TRIM(MID(SUBSTITUTE(C45,";",REPT(" ",30)),211,30)) | M45: =IF(E45="",0,IF(COUNTIF(Evidence!$A$8:$A$20,E45)+COUNTIF(Gate_Matrix!$A$11:$A$18,E45)=1,0,1)) -> 0 | N45: =IF(F45="",0,IF(COUNTIF(Evidence!$A$8:$A$20,F45)+COUNTIF(Gate_Matrix!$A$11:$A$18,F45)=1,0,1)) -> 0 | O45: =IF(G45="",0,IF(COUNTIF(Evidence!$A$8:$A$20,G45)+COUNTIF(Gate_Matrix!$A$11:$A$18,G45)=1,0,1)) -> 0 | P45: =IF(H45="",0,IF(COUNTIF(Evidence!$A$8:$A$20,H45)+COUNTIF(Gate_Matrix!$A$11:$A$18,H45)=1,0,1)) -> 0 | Q45: =IF(I45="",0,IF(COUNTIF(Evidence!$A$8:$A$20,I45)+COUNTIF(Gate_Matrix!$A$11:$A$18,I45)=1,0,1)) -> 0 | R45: =IF(J45="",0,IF(COUNTIF(Evidence!$A$8:$A$20,J45)+COUNTIF(Gate_Matrix!$A$11:$A$18,J45)=1,0,1)) -> 0 | S45: =IF(K45="",0,IF(COUNTIF(Evidence!$A$8:$A$20,K45)+COUNTIF(Gate_Matrix!$A$11:$A$18,K45)=1,0,1)) -> 0 | T45: =IF(L45="",0,IF(COUNTIF(Evidence!$A$8:$A$20,L45)+COUNTIF(Gate_Matrix!$A$11:$A$18,L45)=1,0,1)) -> 0
A46: Site_Review | B46: M12 | C46: =Site_Review!M12 -> RS01; RS02; E08; E09 | D46: =SUM(M46:T46)+IF(OR(C46="",LEN(C46)-LEN(SUBSTITUTE(C46,";",""))+1>8),1,0) -> 0 | E46: =TRIM(MID(SUBSTITUTE(C46,";",REPT(" ",30)),1,30)) -> RS01 | F46: =TRIM(MID(SUBSTITUTE(C46,";",REPT(" ",30)),31,30)) -> RS02 | G46: =TRIM(MID(SUBSTITUTE(C46,";",REPT(" ",30)),61,30)) -> E08 | H46: =TRIM(MID(SUBSTITUTE(C46,";",REPT(" ",30)),91,30)) -> E09 | I46: =TRIM(MID(SUBSTITUTE(C46,";",REPT(" ",30)),121,30)) | J46: =TRIM(MID(SUBSTITUTE(C46,";",REPT(" ",30)),151,30)) | K46: =TRIM(MID(SUBSTITUTE(C46,";",REPT(" ",30)),181,30)) | L46: =TRIM(MID(SUBSTITUTE(C46,";",REPT(" ",30)),211,30)) | M46: =IF(E46="",0,IF(COUNTIF(Evidence!$A$8:$A$20,E46)+COUNTIF(Gate_Matrix!$A$11:$A$18,E46)=1,0,1)) -> 0 | N46: =IF(F46="",0,IF(COUNTIF(Evidence!$A$8:$A$20,F46)+COUNTIF(Gate_Matrix!$A$11:$A$18,F46)=1,0,1)) -> 0 | O46: =IF(G46="",0,IF(COUNTIF(Evidence!$A$8:$A$20,G46)+COUNTIF(Gate_Matrix!$A$11:$A$18,G46)=1,0,1)) -> 0 | P46: =IF(H46="",0,IF(COUNTIF(Evidence!$A$8:$A$20,H46)+COUNTIF(Gate_Matrix!$A$11:$A$18,H46)=1,0,1)) -> 0 | Q46: =IF(I46="",0,IF(COUNTIF(Evidence!$A$8:$A$20,I46)+COUNTIF(Gate_Matrix!$A$11:$A$18,I46)=1,0,1)) -> 0 | R46: =IF(J46="",0,IF(COUNTIF(Evidence!$A$8:$A$20,J46)+COUNTIF(Gate_Matrix!$A$11:$A$18,J46)=1,0,1)) -> 0 | S46: =IF(K46="",0,IF(COUNTIF(Evidence!$A$8:$A$20,K46)+COUNTIF(Gate_Matrix!$A$11:$A$18,K46)=1,0,1)) -> 0 | T46: =IF(L46="",0,IF(COUNTIF(Evidence!$A$8:$A$20,L46)+COUNTIF(Gate_Matrix!$A$11:$A$18,L46)=1,0,1)) -> 0
A47: Site_Review | B47: M13 | C47: =Site_Review!M13 -> RS01; RS02; E08; E09 | D47: =SUM(M47:T47)+IF(OR(C47="",LEN(C47)-LEN(SUBSTITUTE(C47,";",""))+1>8),1,0) -> 0 | E47: =TRIM(MID(SUBSTITUTE(C47,";",REPT(" ",30)),1,30)) -> RS01 | F47: =TRIM(MID(SUBSTITUTE(C47,";",REPT(" ",30)),31,30)) -> RS02 | G47: =TRIM(MID(SUBSTITUTE(C47,";",REPT(" ",30)),61,30)) -> E08 | H47: =TRIM(MID(SUBSTITUTE(C47,";",REPT(" ",30)),91,30)) -> E09 | I47: =TRIM(MID(SUBSTITUTE(C47,";",REPT(" ",30)),121,30)) | J47: =TRIM(MID(SUBSTITUTE(C47,";",REPT(" ",30)),151,30)) | K47: =TRIM(MID(SUBSTITUTE(C47,";",REPT(" ",30)),181,30)) | L47: =TRIM(MID(SUBSTITUTE(C47,";",REPT(" ",30)),211,30)) | M47: =IF(E47="",0,IF(COUNTIF(Evidence!$A$8:$A$20,E47)+COUNTIF(Gate_Matrix!$A$11:$A$18,E47)=1,0,1)) -> 0 | N47: =IF(F47="",0,IF(COUNTIF(Evidence!$A$8:$A$20,F47)+COUNTIF(Gate_Matrix!$A$11:$A$18,F47)=1,0,1)) -> 0 | O47: =IF(G47="",0,IF(COUNTIF(Evidence!$A$8:$A$20,G47)+COUNTIF(Gate_Matrix!$A$11:$A$18,G47)=1,0,1)) -> 0 | P47: =IF(H47="",0,IF(COUNTIF(Evidence!$A$8:$A$20,H47)+COUNTIF(Gate_Matrix!$A$11:$A$18,H47)=1,0,1)) -> 0 | Q47: =IF(I47="",0,IF(COUNTIF(Evidence!$A$8:$A$20,I47)+COUNTIF(Gate_Matrix!$A$11:$A$18,I47)=1,0,1)) -> 0 | R47: =IF(J47="",0,IF(COUNTIF(Evidence!$A$8:$A$20,J47)+COUNTIF(Gate_Matrix!$A$11:$A$18,J47)=1,0,1)) -> 0 | S47: =IF(K47="",0,IF(COUNTIF(Evidence!$A$8:$A$20,K47)+COUNTIF(Gate_Matrix!$A$11:$A$18,K47)=1,0,1)) -> 0 | T47: =IF(L47="",0,IF(COUNTIF(Evidence!$A$8:$A$20,L47)+COUNTIF(Gate_Matrix!$A$11:$A$18,L47)=1,0,1)) -> 0
A48: Site_Review | B48: M14 | C48: =Site_Review!M14 -> RS01; RS02; E08; E09 | D48: =SUM(M48:T48)+IF(OR(C48="",LEN(C48)-LEN(SUBSTITUTE(C48,";",""))+1>8),1,0) -> 0 | E48: =TRIM(MID(SUBSTITUTE(C48,";",REPT(" ",30)),1,30)) -> RS01 | F48: =TRIM(MID(SUBSTITUTE(C48,";",REPT(" ",30)),31,30)) -> RS02 | G48: =TRIM(MID(SUBSTITUTE(C48,";",REPT(" ",30)),61,30)) -> E08 | H48: =TRIM(MID(SUBSTITUTE(C48,";",REPT(" ",30)),91,30)) -> E09 | I48: =TRIM(MID(SUBSTITUTE(C48,";",REPT(" ",30)),121,30)) | J48: =TRIM(MID(SUBSTITUTE(C48,";",REPT(" ",30)),151,30)) | K48: =TRIM(MID(SUBSTITUTE(C48,";",REPT(" ",30)),181,30)) | L48: =TRIM(MID(SUBSTITUTE(C48,";",REPT(" ",30)),211,30)) | M48: =IF(E48="",0,IF(COUNTIF(Evidence!$A$8:$A$20,E48)+COUNTIF(Gate_Matrix!$A$11:$A$18,E48)=1,0,1)) -> 0 | N48: =IF(F48="",0,IF(COUNTIF(Evidence!$A$8:$A$20,F48)+COUNTIF(Gate_Matrix!$A$11:$A$18,F48)=1,0,1)) -> 0 | O48: =IF(G48="",0,IF(COUNTIF(Evidence!$A$8:$A$20,G48)+COUNTIF(Gate_Matrix!$A$11:$A$18,G48)=1,0,1)) -> 0 | P48: =IF(H48="",0,IF(COUNTIF(Evidence!$A$8:$A$20,H48)+COUNTIF(Gate_Matrix!$A$11:$A$18,H48)=1,0,1)) -> 0 | Q48: =IF(I48="",0,IF(COUNTIF(Evidence!$A$8:$A$20,I48)+COUNTIF(Gate_Matrix!$A$11:$A$18,I48)=1,0,1)) -> 0 | R48: =IF(J48="",0,IF(COUNTIF(Evidence!$A$8:$A$20,J48)+COUNTIF(Gate_Matrix!$A$11:$A$18,J48)=1,0,1)) -> 0 | S48: =IF(K48="",0,IF(COUNTIF(Evidence!$A$8:$A$20,K48)+COUNTIF(Gate_Matrix!$A$11:$A$18,K48)=1,0,1)) -> 0 | T48: =IF(L48="",0,IF(COUNTIF(Evidence!$A$8:$A$20,L48)+COUNTIF(Gate_Matrix!$A$11:$A$18,L48)=1,0,1)) -> 0
A49: Site_Review | B49: M15 | C49: =Site_Review!M15 -> RS01; RS02; E08; E09 | D49: =SUM(M49:T49)+IF(OR(C49="",LEN(C49)-LEN(SUBSTITUTE(C49,";",""))+1>8),1,0) -> 0 | E49: =TRIM(MID(SUBSTITUTE(C49,";",REPT(" ",30)),1,30)) -> RS01 | F49: =TRIM(MID(SUBSTITUTE(C49,";",REPT(" ",30)),31,30)) -> RS02 | G49: =TRIM(MID(SUBSTITUTE(C49,";",REPT(" ",30)),61,30)) -> E08 | H49: =TRIM(MID(SUBSTITUTE(C49,";",REPT(" ",30)),91,30)) -> E09 | I49: =TRIM(MID(SUBSTITUTE(C49,";",REPT(" ",30)),121,30)) | J49: =TRIM(MID(SUBSTITUTE(C49,";",REPT(" ",30)),151,30)) | K49: =TRIM(MID(SUBSTITUTE(C49,";",REPT(" ",30)),181,30)) | L49: =TRIM(MID(SUBSTITUTE(C49,";",REPT(" ",30)),211,30)) | M49: =IF(E49="",0,IF(COUNTIF(Evidence!$A$8:$A$20,E49)+COUNTIF(Gate_Matrix!$A$11:$A$18,E49)=1,0,1)) -> 0 | N49: =IF(F49="",0,IF(COUNTIF(Evidence!$A$8:$A$20,F49)+COUNTIF(Gate_Matrix!$A$11:$A$18,F49)=1,0,1)) -> 0 | O49: =IF(G49="",0,IF(COUNTIF(Evidence!$A$8:$A$20,G49)+COUNTIF(Gate_Matrix!$A$11:$A$18,G49)=1,0,1)) -> 0 | P49: =IF(H49="",0,IF(COUNTIF(Evidence!$A$8:$A$20,H49)+COUNTIF(Gate_Matrix!$A$11:$A$18,H49)=1,0,1)) -> 0 | Q49: =IF(I49="",0,IF(COUNTIF(Evidence!$A$8:$A$20,I49)+COUNTIF(Gate_Matrix!$A$11:$A$18,I49)=1,0,1)) -> 0 | R49: =IF(J49="",0,IF(COUNTIF(Evidence!$A$8:$A$20,J49)+COUNTIF(Gate_Matrix!$A$11:$A$18,J49)=1,0,1)) -> 0 | S49: =IF(K49="",0,IF(COUNTIF(Evidence!$A$8:$A$20,K49)+COUNTIF(Gate_Matrix!$A$11:$A$18,K49)=1,0,1)) -> 0 | T49: =IF(L49="",0,IF(COUNTIF(Evidence!$A$8:$A$20,L49)+COUNTIF(Gate_Matrix!$A$11:$A$18,L49)=1,0,1)) -> 0
A50: Site_Review | B50: M16 | C50: =Site_Review!M16 -> RS01; RS02; E07; E08; E09 | D50: =SUM(M50:T50)+IF(OR(C50="",LEN(C50)-LEN(SUBSTITUTE(C50,";",""))+1>8),1,0) -> 0 | E50: =TRIM(MID(SUBSTITUTE(C50,";",REPT(" ",30)),1,30)) -> RS01 | F50: =TRIM(MID(SUBSTITUTE(C50,";",REPT(" ",30)),31,30)) -> RS02 | G50: =TRIM(MID(SUBSTITUTE(C50,";",REPT(" ",30)),61,30)) -> E07 | H50: =TRIM(MID(SUBSTITUTE(C50,";",REPT(" ",30)),91,30)) -> E08 | I50: =TRIM(MID(SUBSTITUTE(C50,";",REPT(" ",30)),121,30)) -> E09 | J50: =TRIM(MID(SUBSTITUTE(C50,";",REPT(" ",30)),151,30)) | K50: =TRIM(MID(SUBSTITUTE(C50,";",REPT(" ",30)),181,30)) | L50: =TRIM(MID(SUBSTITUTE(C50,";",REPT(" ",30)),211,30)) | M50: =IF(E50="",0,IF(COUNTIF(Evidence!$A$8:$A$20,E50)+COUNTIF(Gate_Matrix!$A$11:$A$18,E50)=1,0,1)) -> 0 | N50: =IF(F50="",0,IF(COUNTIF(Evidence!$A$8:$A$20,F50)+COUNTIF(Gate_Matrix!$A$11:$A$18,F50)=1,0,1)) -> 0 | O50: =IF(G50="",0,IF(COUNTIF(Evidence!$A$8:$A$20,G50)+COUNTIF(Gate_Matrix!$A$11:$A$18,G50)=1,0,1)) -> 0 | P50: =IF(H50="",0,IF(COUNTIF(Evidence!$A$8:$A$20,H50)+COUNTIF(Gate_Matrix!$A$11:$A$18,H50)=1,0,1)) -> 0 | Q50: =IF(I50="",0,IF(COUNTIF(Evidence!$A$8:$A$20,I50)+COUNTIF(Gate_Matrix!$A$11:$A$18,I50)=1,0,1)) -> 0 | R50: =IF(J50="",0,IF(COUNTIF(Evidence!$A$8:$A$20,J50)+COUNTIF(Gate_Matrix!$A$11:$A$18,J50)=1,0,1)) -> 0 | S50: =IF(K50="",0,IF(COUNTIF(Evidence!$A$8:$A$20,K50)+COUNTIF(Gate_Matrix!$A$11:$A$18,K50)=1,0,1)) -> 0 | T50: =IF(L50="",0,IF(COUNTIF(Evidence!$A$8:$A$20,L50)+COUNTIF(Gate_Matrix!$A$11:$A$18,L50)=1,0,1)) -> 0
A51: Site_Review | B51: M17 | C51: =Site_Review!M17 -> RS01; RS02; E07; E08; E09 | D51: =SUM(M51:T51)+IF(OR(C51="",LEN(C51)-LEN(SUBSTITUTE(C51,";",""))+1>8),1,0) -> 0 | E51: =TRIM(MID(SUBSTITUTE(C51,";",REPT(" ",30)),1,30)) -> RS01 | F51: =TRIM(MID(SUBSTITUTE(C51,";",REPT(" ",30)),31,30)) -> RS02 | G51: =TRIM(MID(SUBSTITUTE(C51,";",REPT(" ",30)),61,30)) -> E07 | H51: =TRIM(MID(SUBSTITUTE(C51,";",REPT(" ",30)),91,30)) -> E08 | I51: =TRIM(MID(SUBSTITUTE(C51,";",REPT(" ",30)),121,30)) -> E09 | J51: =TRIM(MID(SUBSTITUTE(C51,";",REPT(" ",30)),151,30)) | K51: =TRIM(MID(SUBSTITUTE(C51,";",REPT(" ",30)),181,30)) | L51: =TRIM(MID(SUBSTITUTE(C51,";",REPT(" ",30)),211,30)) | M51: =IF(E51="",0,IF(COUNTIF(Evidence!$A$8:$A$20,E51)+COUNTIF(Gate_Matrix!$A$11:$A$18,E51)=1,0,1)) -> 0 | N51: =IF(F51="",0,IF(COUNTIF(Evidence!$A$8:$A$20,F51)+COUNTIF(Gate_Matrix!$A$11:$A$18,F51)=1,0,1)) -> 0 | O51: =IF(G51="",0,IF(COUNTIF(Evidence!$A$8:$A$20,G51)+COUNTIF(Gate_Matrix!$A$11:$A$18,G51)=1,0,1)) -> 0 | P51: =IF(H51="",0,IF(COUNTIF(Evidence!$A$8:$A$20,H51)+COUNTIF(Gate_Matrix!$A$11:$A$18,H51)=1,0,1)) -> 0 | Q51: =IF(I51="",0,IF(COUNTIF(Evidence!$A$8:$A$20,I51)+COUNTIF(Gate_Matrix!$A$11:$A$18,I51)=1,0,1)) -> 0 | R51: =IF(J51="",0,IF(COUNTIF(Evidence!$A$8:$A$20,J51)+COUNTIF(Gate_Matrix!$A$11:$A$18,J51)=1,0,1)) -> 0 | S51: =IF(K51="",0,IF(COUNTIF(Evidence!$A$8:$A$20,K51)+COUNTIF(Gate_Matrix!$A$11:$A$18,K51)=1,0,1)) -> 0 | T51: =IF(L51="",0,IF(COUNTIF(Evidence!$A$8:$A$20,L51)+COUNTIF(Gate_Matrix!$A$11:$A$18,L51)=1,0,1)) -> 0
...

Sheet WP003_Reference
A2: WP003 reference snapshot
A4: Source: NEXT_WP003_Tier1_Supplier_Footprint_2026(2).xlsx / site_master. Relevant fields copied unchanged; February 2026 snapshot.
A5: One row per official Site ID. These source inputs support annotation rates and QC; the original WP003 workbook remains the governed source.
A7: Site_ID | B7: Country | C7: Product_label | D7: Audit_annotation_raw | E7: Review_flag | F7: Source_record_IDs | G7: Source_ID
A8: 80 | B8: Lithuania | C8: HOME | E8: 0 | F8: T1_2026_P08_R112 | G8: NXT_SUP_T1_2026
A9: 102 | B9: Italy | C9: APPAREL | E9: 0 | F9: T1_2026_P08_R104 | G9: NXT_SUP_T1_2026
A10: 196 | B10: China | C10: APPAREL | E10: 0 | F10: T1_2026_P06_R123 | G10: NXT_SUP_T1_2026
A11: 208 | B11: Turkey | C11: APPAREL | E11: 0 | F11: T1_2026_P09_R179 | G11: NXT_SUP_T1_2026
A12: 212 | B12: India | C12: APPAREL | E12: 0 | F12: T1_2026_P07_R010 | G12: NXT_SUP_T1_2026
A13: 288 | B13: Vietnam | C13: APPAREL | E13: 0 | F13: T1_2026_P10_R011 | G13: NXT_SUP_T1_2026
A14: 355 | B14: United Arab Emirates | C14: APPAREL | E14: 0 | F14: T1_2026_P09_R239 | G14: NXT_SUP_T1_2026
A15: 377 | B15: India | C15: APPAREL | E15: 0 | F15: T1_2026_P07_R136 | G15: NXT_SUP_T1_2026
A16: 527 | B16: Mauritius | C16: APPAREL | E16: 0 | F16: T1_2026_P08_R114 | G16: NXT_SUP_T1_2026
A17: 537 | B17: Thailand | C17: APPAREL | E17: 0 | F17: T1_2026_P09_R106 | G17: NXT_SUP_T1_2026
